Workbook

Sheet dataset
A1: repository | B1: architecture smell | C1: element (package/class) | D1: designite label | E1: repo's link | F1: metrics link | G1: human label
A2: javaparser | B2: God Component | C2: com.github.javaparser.symbolsolver | D2: 1 | E2: link | F2: link | G2: =VLOOKUP(C2,_GC!$D$2:$K$41,8,0) -> 1
A3: byte-buddy | B3: God Component | C3: net.bytebuddy.dynamic.scaffold.inline | D3: 1 | E3: link | F3: link | G3: =VLOOKUP(C3,_GC!$D$2:$K$41,8,0) -> 1
A4: gson | B4: God Component | C4: com.google.gson | D4: 1 | E4: link | F4: link | G4: =VLOOKUP(C4,_GC!$D$2:$K$41,8,0) -> 1
A5: zxing | B5: God Component | C5: com.google.zxing.oned | D5: 1 | E5: link | F5: link | G5: =VLOOKUP(C5,_GC!$D$2:$K$41,8,0) -> 1
A6: gson | B6: God Component | C6: com.google.gson.internal.bind | D6: 1 | E6: link | F6: link | G6: =VLOOKUP(C6,_GC!$D$2:$K$41,8,0) -> 1
A7: javaparser | B7: God Component | C7: com.github.javaparser.metamodel | D7: 1 | E7: link | F7: link | G7: =VLOOKUP(C7,_GC!$D$2:$K$41,8,0) -> 1
A8: gson | B8: God Component | C8: com.google.gson.internal | D8: 1 | E8: link | F8: link | G8: =VLOOKUP(C8,_GC!$D$2:$K$41,8,0) -> 1
A9: byte-buddy | B9: God Component | C9: net.bytebuddy.implementation.bytecode | D9: 1 | E9: link | F9: link | G9: =VLOOKUP(C9,_GC!$D$2:$K$41,8,0) -> 1
A10: jsoup | B10: God Component | C10: org.jsoup.helper | D10: 1 | E10: link | F10: link | G10: =VLOOKUP(C10,_GC!$D$2:$K$41,8,0) -> 1
A11: byte-buddy | B11: God Component | C11: net.bytebuddy.description.modifier | D11: 1 | E11: link | F11: link | G11: =VLOOKUP(C11,_GC!$D$2:$K$41,8,0) -> 1
A12: commons-io | B12: God Component | C12: org.apache.commons.io.function | D12: 1 | E12: link | F12: link | G12: =VLOOKUP(C12,_GC!$D$2:$K$41,8,0) -> 1
A13: zxing | B13: God Component | C13: com.google.zxing.client.result | D13: 1 | E13: link | F13: link | G13: =VLOOKUP(C13,_GC!$D$2:$K$41,8,0) -> 1
... A41: javaparser | B41: God Component | C41: issue1945.main | D41: 0 | E41: link | F41: link | G41: =VLOOKUP(C41,_GC!$D$2:$K$41,8,0) -> 0
A42: jitwatch | B42: Unstable Dependency | C42: org.adoptopenjdk.jitwatch.model.assembly | D42: 1 | E42: link | F42: link | G42: =VLOOKUP(C42,_UD!$D$2:$K$41,8,0) -> 0
A43: jitwatch | B43: Unstable Dependency | C43: org.adoptopenjdk.jitwatch.ui.compilationchooser | D43: 1 | E43: link | F43: link | G43: =VLOOKUP(C43,_UD!$D$2:$K$41,8,0) -> 1
A44: zxing | B44: Unstable Dependency | C44: com.google.zxing.aztec | D44: 1 | E44: link | F44: link | G44: =VLOOKUP(C44,_UD!$D$2:$K$41,8,0) -> 1
A45: jitwatch | B45: Unstable Dependency | C45: org.adoptopenjdk.jitwatch.report | D45: 1 | E45: link | F45: link | G45: =VLOOKUP(C45,_UD!$D$2:$K$41,8,0) -> 1
A46: jitwatch | B46: Unstable Dependency | C46: org.adoptopenjdk.jitwatch.process.runtime | D46: 1 | E46: link | F46: link | G46: =VLOOKUP(C46,_UD!$D$2:$K$41,8,0) -> 0
A47: jitwatch | B47: Unstable Dependency | C47: org.adoptopenjdk.jitwatch.ui.stage | D47: 1 | E47: link | F47: link | G47: =VLOOKUP(C47,_UD!$D$2:$K$41,8,0) -> 1
A48: zxing | B48: Unstable Dependency | C48: com.google.zxing.client.android.history | D48: 1 | E48: link | F48: link | G48: =VLOOKUP(C48,_UD!$D$2:$K$41,8,0) -> 1
A49: jitwatch | B49: Unstable Dependency | C49: org.adoptopenjdk.jitwatch.ui.parserchooser | D49: 1 | E49: link | F49: link | G49: =VLOOKUP(C49,_UD!$D$2:$K$41,8,0) -> 0
A50: jitwatch | B50: Unstable Dependency | C50: org.adoptopenjdk.jitwatch.toplist | D50: 1 | E50: link | F50: link | G50: =VLOOKUP(C50,_UD!$D$2:$K$41,8,0) -> 0
A51: jitwatch | B51: Unstable Dependency | C51: org.adoptopenjdk.jitwatch.process.javap | D51: 1 | E51: link | F51: link | G51: =VLOOKUP(C51,_UD!$D$2:$K$41,8,0) -> 0
A52: jitwatch | B52: Unstable Dependency | C52: org.adoptopenjdk.jitwatch.ui.triview.source | D52: 1 | E52: link | F52: link | G52: =VLOOKUP(C52,_UD!$D$2:$K$41,8,0) -> 0
A53: zxing | B53: Unstable Dependency | C53: com.google.zxing.oned.rss.expanded.decoders | D53: 1 | E53: link | F53: link | G53: =VLOOKUP(C53,_UD!$D$2:$K$41,8,0) -> 1
... A81: zxing | B81: Unstable Dependency | C81: com.google.zxing.client.android.book | D81: 0 | E81: link | F81: link | G81: =VLOOKUP(C81,_UD!$D$2:$K$41,8,0) -> 0
A82: commons-io | B82: Insufficient Modularization | C82: org.apache.commons.io.CloseableURLConnection | D82: 1 | E82: link | F82: link | G82: =VLOOKUP(C82,_IM!$D$2:$K$41,8,0) -> 0
A83: javaparser | B83: Insufficient Modularization | C83: com.github.javaparser.ast.modules.ModuleOpensDirective | D83: 1 | E83: link | F83: link | G83: =VLOOKUP(C83,_IM!$D$2:$K$41,8,0) -> 0
A84: javaparser | B84: Insufficient Modularization | C84: com.github.javaparser.ast.body.ConstructorDeclaration | D84: 1 | E84: link | F84: link | G84: =VLOOKUP(C84,_IM!$D$2:$K$41,8,0) -> 1
A85: javaparser | B85: Insufficient Modularization | C85: com.github.javaparser.symbolsolver.resolution.typeinference.BoundSet | D85: 1 | E85: link | F85: link | G85: =VLOOKUP(C85,_IM!$D$2:$K$41,8,0) -> 1
A86: javaparser | B86: Insufficient Modularization | C86: com.github.javaparser.ast.visitor.HashCodeVisitor | D86: 1 | E86: link | F86: link | G86: =VLOOKUP(C86,_IM!$D$2:$K$41,8,0) -> 1
A87: javaparser | B87: Insufficient Modularization | C87: com.github.javaparser.resolution.logic.MethodResolutionLogic | D87: 1 | E87: link | F87: link | G87: =VLOOKUP(C87,_IM!$D$2:$K$41,8,0) -> 0
A88: javaparser | B88: Insufficient Modularization | C88: com.github.javaparser.symbolsolver.javassistmodel.JavassistMethodDeclaration | D88: 1 | E88: link | F88: link | G88: =VLOOKUP(C88,_IM!$D$2:$K$41,8,0) -> 0
A89: javaparser | B89: Insufficient Modularization | C89: com.github.javaparser.symbolsolver.javaparsermodel.declarations.JavaParserClassDeclaration | D89: 1 | E89: link | F89: link | G89: =VLOOKUP(C89,_IM!$D$2:$K$41,8,0) -> 1
A90: javaparser | B90: Insufficient Modularization | C90: com.github.javaparser.ast.type.PrimitiveType | D90: 1 | E90: link | F90: link | G90: =VLOOKUP(C90,_IM!$D$2:$K$41,8,0) -> 1
A91: commons-lang | B91: Insufficient Modularization | C91: org.apache.commons.lang3.mutable.MutableFloat | D91: 1 | E91: link | F91: link | G91: =VLOOKUP(C91,_IM!$D$2:$K$41,8,0) -> 1
A92: jitwatch | B92: Insufficient Modularization | C92: org.adoptopenjdk.jitwatch.demo.MakeHotSpotLog | D92: 1 | E92: link | F92: link | G92: =VLOOKUP(C92,_IM!$D$2:$K$41,8,0) -> 0
A93: jitwatch | B93: Insufficient Modularization | C93: org.adoptopenjdk.jitwatch.util.StringUtil | D93: 1 | E93: link | F93: link | G93: =VLOOKUP(C93,_IM!$D$2:$K$41,8,0) -> 1
... A121: commons-io | B121: Insufficient Modularization | C121: org.apache.commons.io.output.ProxyOutputStream | D121: 0 | E121: link | F121: link | G121: =VLOOKUP(C121,_IM!$D$2:$K$41,8,0) -> 0
...

Sheet _GC
A1: id | B1: project | C1: smell | D1: package | E1: repo_link | F1: metrics_link | G1: group | H1: vote 1 | I1: vote 2 | J1: vote 3 | K1: label
A2: 1 | B2: javaparser | C2: God Component | D2: com.github.javaparser.symbolsolver | E2: link | F2: link | G2: 1 | H2: =VLOOKUP(D2,G1P1!$D$2:$E$11,2,0) -> yes | I2: =VLOOKUP(D2,G1P2!$D$2:$E$11,2,0) -> yes | J2: =VLOOKUP(D2,G1P3!$D$2:$E$11,2,0) -> no | K2: =IF(COUNTIF(H2:J2,"yes")>=2,1,0) -> 1
A3: 2 | B3: jitwatch | C3: God Component | D3: org.adoptopenjdk.jitwatch.ui.parserchooser | E3: link | F3: link | G3: 1 | H3: =VLOOKUP(D3,G1P1!$D$2:$E$11,2,0) -> no | I3: =VLOOKUP(D3,G1P2!$D$2:$E$11,2,0) -> no | J3: =VLOOKUP(D3,G1P3!$D$2:$E$11,2,0) -> no | K3: =IF(COUNTIF(H3:J3,"yes")>=2,1,0) -> 0
A4: 3 | B4: jsoup | C4: God Component | D4: org.jsoup.helper | E4: link | F4: link | G4: 1 | H4: =VLOOKUP(D4,G1P1!$D$2:$E$11,2,0) -> no | I4: =VLOOKUP(D4,G1P2!$D$2:$E$11,2,0) -> yes | J4: =VLOOKUP(D4,G1P3!$D$2:$E$11,2,0) -> yes | K4: =IF(COUNTIF(H4:J4,"yes")>=2,1,0) -> 1
A5: 4 | B5: zxing | C5: God Component | D5: com.google.zxing.multi.qrcode.detector | E5: link | F5: link | G5: 1 | H5: =VLOOKUP(D5,G1P1!$D$2:$E$11,2,0) -> no | I5: =VLOOKUP(D5,G1P2!$D$2:$E$11,2,0) -> no | J5: =VLOOKUP(D5,G1P3!$D$2:$E$11,2,0) -> no | K5: =IF(COUNTIF(H5:J5,"yes")>=2,1,0) -> 0
A6: 5 | B6: gson | C6: God Component | D6: com.google.gson.internal | E6: link | F6: link | G6: 1 | H6: =VLOOKUP(D6,G1P1!$D$2:$E$11,2,0) -> yes | I6: =VLOOKUP(D6,G1P2!$D$2:$E$11,2,0) -> yes | J6: =VLOOKUP(D6,G1P3!$D$2:$E$11,2,0) -> no | K6: =IF(COUNTIF(H6:J6,"yes")>=2,1,0) -> 1
A7: 6 | B7: zxing | C7: God Component | D7: com.google.zxing.oned | E7: link | F7: link | G7: 1 | H7: =VLOOKUP(D7,G1P1!$D$2:$E$11,2,0) -> yes | I7: =VLOOKUP(D7,G1P2!$D$2:$E$11,2,0) -> yes | J7: =VLOOKUP(D7,G1P3!$D$2:$E$11,2,0) -> no | K7: =IF(COUNTIF(H7:J7,"yes")>=2,1,0) -> 1
A8: 7 | B8: byte-buddy | C8: God Component | D8: net.bytebuddy.description.modifier | E8: link | F8: link | G8: 1 | H8: =VLOOKUP(D8,G1P1!$D$2:$E$11,2,0) -> yes | I8: =VLOOKUP(D8,G1P2!$D$2:$E$11,2,0) -> yes | J8: =VLOOKUP(D8,G1P3!$D$2:$E$11,2,0) -> yes | K8: =IF(COUNTIF(H8:J8,"yes")>=2,1,0) -> 1
A9: 8 | B9: zxing | C9: God Component | D9: com.google.zxing.common | E9: link | F9: link | G9: 1 | H9: =VLOOKUP(D9,G1P1!$D$2:$E$11,2,0) -> yes | I9: =VLOOKUP(D9,G1P2!$D$2:$E$11,2,0) -> yes | J9: =VLOOKUP(D9,G1P3!$D$2:$E$11,2,0) -> yes | K9: =IF(COUNTIF(H9:J9,"yes")>=2,1,0) -> 1
A10: 9 | B10: javaparser | C10: God Component | D10: com.github.javaparser.metamodel | E10: link | F10: link | G10: 1 | H10: =VLOOKUP(D10,G1P1!$D$2:$E$11,2,0) -> yes | I10: =VLOOKUP(D10,G1P2!$D$2:$E$11,2,0) -> yes | J10: =VLOOKUP(D10,G1P3!$D$2:$E$11,2,0) -> yes | K10: =IF(COUNTIF(H10:J10,"yes")>=2,1,0) -> 1
A11: 10 | B11: javaparser | C11: God Component | D11: issue1945.interfaces | E11: link | F11: link | G11: 1 | H11: =VLOOKUP(D11,G1P1!$D$2:$E$11,2,0) -> no | I11: =VLOOKUP(D11,G1P2!$D$2:$E$11,2,0) -> no | J11: =VLOOKUP(D11,G1P3!$D$2:$E$11,2,0) -> no | K11: =IF(COUNTIF(H11:J11,"yes")>=2,1,0) -> 0
A12: 11 | B12: zxing | C12: God Component | D12: com.google.zxing.aztec.decoder | E12: link | F12: link | G12: 2 | H12: =VLOOKUP(D12,G2P1!$D$2:$E$11,2,0) -> no | I12: =VLOOKUP(D12,G2P2!$D$2:$E$11,2,0) -> no | J12: no | K12: =IF(COUNTIF(H12:J12,"yes")>=2,1,0) -> 0
A13: 12 | B13: javaparser | C13: God Component | D13: com.github.javaparser.generator.core.utils | E13: link | F13: link | G13: 2 | H13: =VLOOKUP(D13,G2P1!$D$2:$E$11,2,0) -> no | I13: =VLOOKUP(D13,G2P2!$D$2:$E$11,2,0) -> no | J13: no | K13: =IF(COUNTIF(H13:J13,"yes")>=2,1,0) -> 0
A14: 13 | B14: javaparser | C14: God Component | D14: com.github.javaparser.symbolsolver.javassistmodel | E14: link | F14: link | G14: 2 | H14: =VLOOKUP(D14,G2P1!$D$2:$E$11,2,0) -> yes | I14: =VLOOKUP(D14,G2P2!$D$2:$E$11,2,0) -> no | J14: no | K14: =IF(COUNTIF(H14:J14,"yes")>=2,1,0) -> 0
A15: 14 | B15: byte-buddy | C15: God Component | D15: net.bytebuddy.implementation.bytecode | E15: link | F15: link | G15: 2 | H15: =VLOOKUP(D15,G2P1!$D$2:$E$11,2,0) -> yes | I15: =VLOOKUP(D15,G2P2!$D$2:$E$11,2,0) -> yes | J15: no | K15: =IF(COUNTIF(H15:J15,"yes")>=2,1,0) -> 1
A16: 15 | B16: javaparser | C16: God Component | D16: issue1945.main | E16: link | F16: link | G16: 2 | H16: =VLOOKUP(D16,G2P1!$D$2:$E$11,2,0) -> no | I16: =VLOOKUP(D16,G2P2!$D$2:$E$11,2,0) -> no | J16: no | K16: =IF(COUNTIF(H16:J16,"yes")>=2,1,0) -> 0
A17: 16 | B17: javaparser | C17: God Component | D17: another | E17: link | F17: link | G17: 2 | H17: =VLOOKUP(D17,G2P1!$D$2:$E$11,2,0) -> no | I17: =VLOOKUP(D17,G2P2!$D$2:$E$11,2,0) -> no | J17: no | K17: =IF(COUNTIF(H17:J17,"yes")>=2,1,0) -> 0
A18: 17 | B18: gson | C18: God Component | D18: com.google.gson.internal.bind | E18: link | F18: link | G18: 2 | H18: =VLOOKUP(D18,G2P1!$D$2:$E$11,2,0) -> yes | I18: =VLOOKUP(D18,G2P2!$D$2:$E$11,2,0) -> yes | J18: no | K18: =IF(COUNTIF(H18:J18,"yes")>=2,1,0) -> 1
A19: 18 | B19: commons-io | C19: God Component | D19: org.apache.commons.io.function | E19: link | F19: link | G19: 2 | H19: =VLOOKUP(D19,G2P1!$D$2:$E$11,2,0) -> yes | I19: =VLOOKUP(D19,G2P2!$D$2:$E$11,2,0) -> yes | J19: no | K19: =IF(COUNTIF(H19:J19,"yes")>=2,1,0) -> 1
A20: 19 | B20: commons-lang | C20: God Component | D20: org.apache.commons.lang3.mutable | E20: link | F20: link | G20: 2 | H20: =VLOOKUP(D20,G2P1!$D$2:$E$11,2,0) -> yes | I20: =VLOOKUP(D20,G2P2!$D$2:$E$11,2,0) -> no | J20: no | K20: =IF(COUNTIF(H20:J20,"yes")>=2,1,0) -> 0
A21: 20 | B21: commons-io | C21: God Component | D21: org.apache.commons.io.output | E21: link | F21: link | G21: 2 | H21: =VLOOKUP(D21,G2P1!$D$2:$E$11,2,0) -> yes | I21: =VLOOKUP(D21,G2P2!$D$2:$E$11,2,0) -> yes | J21: no | K21: =IF(COUNTIF(H21:J21,"yes")>=2,1,0) -> 1
A22: 21 | B22: byte-buddy | C22: God Component | D22: net.bytebuddy.dynamic.scaffold.inline | E22: link | F22: link | G22: 3 | H22: =VLOOKUP(D22,G3P1!$D$2:$E$11,2,0) -> yes | I22: =VLOOKUP(D22,G3P2!$D$2:$E$11,2,0) -> yes | J22: =VLOOKUP(D22,G3P3!$D$2:$E$11,2,0) -> yes | K22: =IF(COUNTIF(H22:J22,"yes")>=2,1,0) -> 1
A23: 22 | B23: javaparser | C23: God Component | D23: com.github.javaparser.resolution.declarations | E23: link | F23: link | G23: 3 | H23: =VLOOKUP(D23,G3P1!$D$2:$E$11,2,0) -> no | I23: =VLOOKUP(D23,G3P2!$D$2:$E$11,2,0) -> yes | J23: =VLOOKUP(D23,G3P3!$D$2:$E$11,2,0) -> yes | K23: =IF(COUNTIF(H23:J23,"yes")>=2,1,0) -> 1
A24: 23 | B24: gson | C24: God Component | D24: com.google.gson | E24: link | F24: link | G24: 3 | H24: =VLOOKUP(D24,G3P1!$D$2:$E$11,2,0) -> yes | I24: =VLOOKUP(D24,G3P2!$D$2:$E$11,2,0) -> yes | J24: =VLOOKUP(D24,G3P3!$D$2:$E$11,2,0) -> yes | K24: =IF(COUNTIF(H24:J24,"yes")>=2,1,0) -> 1
A25: 24 | B25: zxing | C25: God Component | D25: com.google.zxing.client.result | E25: link | F25: link | G25: 3 | H25: =VLOOKUP(D25,G3P1!$D$2:$E$11,2,0) -> yes | I25: =VLOOKUP(D25,G3P2!$D$2:$E$11,2,0) -> yes | J25: =VLOOKUP(D25,G3P3!$D$2:$E$11,2,0) -> yes | K25: =IF(COUNTIF(H25:J25,"yes")>=2,1,0) -> 1
A26: 25 | B26: jsoup | C26: God Component | D26: org.jsoup.safety | E26: link | F26: link | G26: 3 | H26: =VLOOKUP(D26,G3P1!$D$2:$E$11,2,0) -> yes | I26: =VLOOKUP(D26,G3P2!$D$2:$E$11,2,0) -> no | J26: =VLOOKUP(D26,G3P3!$D$2:$E$11,2,0) -> no | K26: =IF(COUNTIF(H26:J26,"yes")>=2,1,0) -> 0
A27: 26 | B27: javaparser | C27: God Component | D27: com.github.javaparser.symbolsolver.javaparsermodel.contexts | E27: link | F27: link | G27: 3 | H27: =VLOOKUP(D27,G3P1!$D$2:$E$11,2,0) -> no | I27: =VLOOKUP(D27,G3P2!$D$2:$E$11,2,0) -> yes | J27: =VLOOKUP(D27,G3P3!$D$2:$E$11,2,0) -> yes | K27: =IF(COUNTIF(H27:J27,"yes")>=2,1,0) -> 1
A28: 27 | B28: byte-buddy | C28: God Component | D28: net.bytebuddy.implementation.bytecode.assign.primitive | E28: link | F28: link | G28: 3 | H28: =VLOOKUP(D28,G3P1!$D$2:$E$11,2,0) -> yes | I28: =VLOOKUP(D28,G3P2!$D$2:$E$11,2,0) -> no | J28: =VLOOKUP(D28,G3P3!$D$2:$E$11,2,0) -> no | K28: =IF(COUNTIF(H28:J28,"yes")>=2,1,0) -> 0
A29: 28 | B29: javaparser | C29: God Component | D29: com.github.javaparser.symbolsolver.resolution | E29: link | F29: link | G29: 3 | H29: =VLOOKUP(D29,G3P1!$D$2:$E$11,2,0) -> no | I29: =VLOOKUP(D29,G3P2!$D$2:$E$11,2,0) -> no | J29: =VLOOKUP(D29,G3P3!$D$2:$E$11,2,0) -> no | K29: =IF(COUNTIF(H29:J29,"yes")>=2,1,0) -> 0
A30: 29 | B30: javaparser | C30: God Component | D30: com.github.javaparser.symbolsolver.declarations.common | E30: link | F30: link | G30: 3 | H30: =VLOOKUP(D30,G3P1!$D$2:$E$11,2,0) -> no | I30: =VLOOKUP(D30,G3P2!$D$2:$E$11,2,0) -> no | J30: =VLOOKUP(D30,G3P3!$D$2:$E$11,2,0) -> no | K30: =IF(COUNTIF(H30:J30,"yes")>=2,1,0) -> 0
A31: 30 | B31: javaparser | C31: God Component | D31: box | E31: link | F31: link | G31: 3 | H31: =VLOOKUP(D31,G3P1!$D$2:$E$11,2,0) -> yes | I31: =VLOOKUP(D31,G3P2!$D$2:$E$11,2,0) -> no | J31: =VLOOKUP(D31,G3P3!$D$2:$E$11,2,0) -> no | K31: =IF(COUNTIF(H31:J31,"yes")>=2,1,0) -> 0
A32: 31 | B32: commons-io | C32: God Component | D32: org.apache.commons.io.monitor | E32: link | F32: link | G32: 4 | H32: =VLOOKUP(D32,G4P1!$D$2:$E$11,2,0) -> no | I32: =VLOOKUP(D32,G4P2!$D$2:$E$11,2,0) -> no | J32: no | K32: =IF(COUNTIF(H32:J32,"yes")>=2,1,0) -> 0
A33: 32 | B33: commons-lang | C33: God Component | D33: org.apache.commons.lang3.tuple | E33: link | F33: link | G33: 4 | H33: =VLOOKUP(D33,G4P1!$D$2:$E$11,2,0) -> no | I33: =VLOOKUP(D33,G4P2!$D$2:$E$11,2,0) -> no | J33: no | K33: =IF(COUNTIF(H33:J33,"yes")>=2,1,0) -> 0
A34: 33 | B34: javaparser | C34: God Component | D34: com.github.javaparser.symbolsolver.reflectionmodel | E34: link | F34: link | G34: 4 | H34: =VLOOKUP(D34,G4P1!$D$2:$E$11,2,0) -> yes | I34: =VLOOKUP(D34,G4P2!$D$2:$E$11,2,0) -> yes | J34: no | K34: =IF(COUNTIF(H34:J34,"yes")>=2,1,0) -> 1
A35: 34 | B35: javaparser | C35: God Component | D35: com.github.javaparser.resolution.promotion | E35: link | F35: link | G35: 4 | H35: =VLOOKUP(D35,G4P1!$D$2:$E$11,2,0) -> no | I35: =VLOOKUP(D35,G4P2!$D$2:$E$11,2,0) -> no | J35: no | K35: =IF(COUNTIF(H35:J35,"yes")>=2,1,0) -> 0
A36: 35 | B36: jitwatch | C36: God Component | D36: org.adoptopenjdk.jitwatch.inline | E36: link | F36: link | G36: 4 | H36: =VLOOKUP(D36,G4P1!$D$2:$E$11,2,0) -> no | I36: =VLOOKUP(D36,G4P2!$D$2:$E$11,2,0) -> no | J36: no | K36: =IF(COUNTIF(H36:J36,"yes")>=2,1,0) -> 0
A37: 36 | B37: jitwatch | C37: God Component | D37: org.adoptopenjdk.jitwatch.ui.nmethod.compilerthread | E37: link | F37: link | G37: 4 | H37: =VLOOKUP(D37,G4P1!$D$2:$E$11,2,0) -> no | I37: =VLOOKUP(D37,G4P2!$D$2:$E$11,2,0) -> no | J37: no | K37: =IF(COUNTIF(H37:J37,"yes")>=2,1,0) -> 0
A38: 37 | B38: google-java-format | C38: God Component | D38: com.google.googlejavaformat | E38: link | F38: link | G38: 4 | H38: =VLOOKUP(D38,G4P1!$D$2:$E$11,2,0) -> yes | I38: =VLOOKUP(D38,G4P2!$D$2:$E$11,2,0) -> yes | J38: no | K38: =IF(COUNTIF(H38:J38,"yes")>=2,1,0) -> 1
A39: 38 | B39: google-java-format | C39: God Component | D39: com.google.googlejavaformat.java.javadoc | E39: link | F39: link | G39: 4 | H39: =VLOOKUP(D39,G4P1!$D$2:$E$11,2,0) -> no | I39: =VLOOKUP(D39,G4P2!$D$2:$E$11,2,0) -> no | J39: no | K39: =IF(COUNTIF(H39:J39,"yes")>=2,1,0) -> 0
A40: 39 | B40: zxing | C40: God Component | D40: com.google.zxing | E40: link | F40: link | G40: 4 | H40: =VLOOKUP(D40,G4P1!$D$2:$E$11,2,0) -> yes | I40: =VLOOKUP(D40,G4P2!$D$2:$E$11,2,0) -> yes | J40: no | K40: =IF(COUNTIF(H40:J40,"yes")>=2,1,0) -> 1
...

Sheet _UD
A1: id | B1: project | C1: smell | D1: package | E1: repo_link | F1: metrics_link | G1: group | H1: vote 1 | I1: vote 2 | J1: vote 3 | K1: label
A2: 1 | B2: jitwatch | C2: Unstable Dependency | D2: org.adoptopenjdk.jitwatch.toplist | E2: link | F2: link | G2: 1 | H2: =VLOOKUP(D2,G1P1!$D$12:$E$21,2,0) -> yes | I2: =VLOOKUP(D2,G1P2!$D$12:$E$21,2,0) -> no | J2: =VLOOKUP(D2,G1P3!$D$12:$E$21,2,0) -> no | K2: =IF(COUNTIF(H2:J2,"yes")>=2,1,0) -> 0
A3: 2 | B3: byte-buddy | C3: Unstable Dependency | D3: org.gradle.work | E3: link | F3: link | G3: 1 | H3: =VLOOKUP(D3,G1P1!$D$12:$E$21,2,0) -> yes | I3: =VLOOKUP(D3,G1P2!$D$12:$E$21,2,0) -> yes | J3: =VLOOKUP(D3,G1P3!$D$12:$E$21,2,0) -> no | K3: =IF(COUNTIF(H3:J3,"yes")>=2,1,0) -> 1
A4: 3 | B4: jitwatch | C4: Unstable Dependency | D4: org.adoptopenjdk.jitwatch.ui.triview.source | E4: link | F4: link | G4: 1 | H4: =VLOOKUP(D4,G1P1!$D$12:$E$21,2,0) -> yes | I4: =VLOOKUP(D4,G1P2!$D$12:$E$21,2,0) -> no | J4: =VLOOKUP(D4,G1P3!$D$12:$E$21,2,0) -> no | K4: =IF(COUNTIF(H4:J4,"yes")>=2,1,0) -> 0
A5: 4 | B5: jitwatch | C5: Unstable Dependency | D5: org.adoptopenjdk.jitwatch.model.assembly | E5: link | F5: link | G5: 1 | H5: =VLOOKUP(D5,G1P1!$D$12:$E$21,2,0) -> yes | I5: =VLOOKUP(D5,G1P2!$D$12:$E$21,2,0) -> no | J5: =VLOOKUP(D5,G1P3!$D$12:$E$21,2,0) -> no | K5: =IF(COUNTIF(H5:J5,"yes")>=2,1,0) -> 0
A6: 5 | B6: jitwatch | C6: Unstable Dependency | D6: org.adoptopenjdk.jitwatch.process.javap | E6: link | F6: link | G6: 1 | H6: =VLOOKUP(D6,G1P1!$D$12:$E$21,2,0) -> yes | I6: =VLOOKUP(D6,G1P2!$D$12:$E$21,2,0) -> no | J6: =VLOOKUP(D6,G1P3!$D$12:$E$21,2,0) -> no | K6: =IF(COUNTIF(H6:J6,"yes")>=2,1,0) -> 0
A7: 6 | B7: zxing | C7: Unstable Dependency | D7: com.google.zxing.aztec.detector | E7: link | F7: link | G7: 1 | H7: =VLOOKUP(D7,G1P1!$D$12:$E$21,2,0) -> yes | I7: =VLOOKUP(D7,G1P2!$D$12:$E$21,2,0) -> no | J7: =VLOOKUP(D7,G1P3!$D$12:$E$21,2,0) -> no | K7: =IF(COUNTIF(H7:J7,"yes")>=2,1,0) -> 0
A8: 7 | B8: jitwatch | C8: Unstable Dependency | D8: org.adoptopenjdk.jitwatch.ui.nmethod.compilerthread | E8: link | F8: link | G8: 1 | H8: =VLOOKUP(D8,G1P1!$D$12:$E$21,2,0) -> yes | I8: =VLOOKUP(D8,G1P2!$D$12:$E$21,2,0) -> no | J8: =VLOOKUP(D8,G1P3!$D$12:$E$21,2,0) -> no | K8: =IF(COUNTIF(H8:J8,"yes")>=2,1,0) -> 0
A9: 8 | B9: zxing | C9: Unstable Dependency | D9: com.google.zxing.client.android.history | E9: link | F9: link | G9: 1 | H9: =VLOOKUP(D9,G1P1!$D$12:$E$21,2,0) -> yes | I9: =VLOOKUP(D9,G1P2!$D$12:$E$21,2,0) -> yes | J9: =VLOOKUP(D9,G1P3!$D$12:$E$21,2,0) -> no | K9: =IF(COUNTIF(H9:J9,"yes")>=2,1,0) -> 1
A10: 9 | B10: byte-buddy | C10: Unstable Dependency | D10: org.gradle.api.file | E10: link | F10: link | G10: 1 | H10: =VLOOKUP(D10,G1P1!$D$12:$E$21,2,0) -> yes | I10: =VLOOKUP(D10,G1P2!$D$12:$E$21,2,0) -> no | J10: =VLOOKUP(D10,G1P3!$D$12:$E$21,2,0) -> no | K10: =IF(COUNTIF(H10:J10,"yes")>=2,1,0) -> 0
A11: 10 | B11: jitwatch | C11: Unstable Dependency | D11: org.adoptopenjdk.jitwatch.process.runtime | E11: link | F11: link | G11: 1 | H11: =VLOOKUP(D11,G1P1!$D$12:$E$21,2,0) -> yes | I11: =VLOOKUP(D11,G1P2!$D$12:$E$21,2,0) -> no | J11: =VLOOKUP(D11,G1P3!$D$12:$E$21,2,0) -> no | K11: =IF(COUNTIF(H11:J11,"yes")>=2,1,0) -> 0
A12: 11 | B12: zxing | C12: Unstable Dependency | D12: com.google.zxing.aztec | E12: link | F12: link | G12: 2 | H12: =VLOOKUP(D12,G2P1!$D$12:$E$21,2,0) -> yes | I12: =VLOOKUP(D12,G2P2!$D$12:$E$21,2,0) -> yes | J12: no | K12: =IF(COUNTIF(H12:J12,"yes")>=2,1,0) -> 1
A13: 12 | B13: jitwatch | C13: Unstable Dependency | D13: org.adoptopenjdk.jitwatch.ui.resize | E13: link | F13: link | G13: 2 | H13: =VLOOKUP(D13,G2P1!$D$12:$E$21,2,0) -> no | I13: =VLOOKUP(D13,G2P2!$D$12:$E$21,2,0) -> no | J13: no | K13: =IF(COUNTIF(H13:J13,"yes")>=2,1,0) -> 0
A14: 13 | B14: jitwatch | C14: Unstable Dependency | D14: org.adoptopenjdk.jitwatch.ui.report.cell | E14: link | F14: link | G14: 2 | H14: =VLOOKUP(D14,G2P1!$D$12:$E$21,2,0) -> no | I14: =VLOOKUP(D14,G2P2!$D$12:$E$21,2,0) -> no | J14: no | K14: =IF(COUNTIF(H14:J14,"yes")>=2,1,0) -> 0
A15: 14 | B15: jitwatch | C15: Unstable Dependency | D15: org.adoptopenjdk.jitwatch.histo | E15: link | F15: link | G15: 2 | H15: =VLOOKUP(D15,G2P1!$D$12:$E$21,2,0) -> no | I15: =VLOOKUP(D15,G2P2!$D$12:$E$21,2,0) -> no | J15: no | K15: =IF(COUNTIF(H15:J15,"yes")>=2,1,0) -> 0
A16: 15 | B16: javaparser | C16: Unstable Dependency | D16: com.packageName | E16: link | F16: link | G16: 2 | H16: =VLOOKUP(D16,G2P1!$D$12:$E$21,2,0) -> no | I16: =VLOOKUP(D16,G2P2!$D$12:$E$21,2,0) -> no | J16: no | K16: =IF(COUNTIF(H16:J16,"yes")>=2,1,0) -> 0
A17: 16 | B17: zxing | C17: Unstable Dependency | D17: com.google.zxing.pdf417.detector | E17: link | F17: link | G17: 2 | H17: =VLOOKUP(D17,G2P1!$D$12:$E$21,2,0) -> no | I17: =VLOOKUP(D17,G2P2!$D$12:$E$21,2,0) -> no | J17: no | K17: =IF(COUNTIF(H17:J17,"yes")>=2,1,0) -> 0
A18: 17 | B18: commons-io | C18: Unstable Dependency | D18: org.apache.commons.io.file.spi | E18: link | F18: link | G18: 2 | H18: =VLOOKUP(D18,G2P1!$D$12:$E$21,2,0) -> no | I18: =VLOOKUP(D18,G2P2!$D$12:$E$21,2,0) -> no | J18: no | K18: =IF(COUNTIF(H18:J18,"yes")>=2,1,0) -> 0
A19: 18 | B19: zxing | C19: Unstable Dependency | D19: com.google.zxing.oned.rss.expanded.decoders | E19: link | F19: link | G19: 2 | H19: =VLOOKUP(D19,G2P1!$D$12:$E$21,2,0) -> no | I19: =VLOOKUP(D19,G2P2!$D$12:$E$21,2,0) -> yes | J19: yes | K19: =IF(COUNTIF(H19:J19,"yes")>=2,1,0) -> 1
A20: 19 | B20: jitwatch | C20: Unstable Dependency | D20: org.adoptopenjdk.jitwatch.ui.parserchooser | E20: link | F20: link | G20: 2 | H20: =VLOOKUP(D20,G2P1!$D$12:$E$21,2,0) -> no | I20: =VLOOKUP(D20,G2P2!$D$12:$E$21,2,0) -> no | J20: no | K20: =IF(COUNTIF(H20:J20,"yes")>=2,1,0) -> 0
A21: 20 | B21: javaparser | C21: Unstable Dependency | D21: com.github.javaparser.storage | E21: link | F21: link | G21: 2 | H21: =VLOOKUP(D21,G2P1!$D$12:$E$21,2,0) -> no | I21: =VLOOKUP(D21,G2P2!$D$12:$E$21,2,0) -> no | J21: no | K21: =IF(COUNTIF(H21:J21,"yes")>=2,1,0) -> 0
A22: 21 | B22: jitwatch | C22: Unstable Dependency | D22: org.adoptopenjdk.jitwatch.chain | E22: link | F22: link | G22: 3 | H22: =VLOOKUP(D22,G3P1!$D$12:$E$21,2,0) -> yes | I22: =VLOOKUP(D22,G3P2!$D$12:$E$21,2,0) -> no | J22: =VLOOKUP(D22,G3P3!$D$12:$E$21,2,0) -> no | K22: =IF(COUNTIF(H22:J22,"yes")>=2,1,0) -> 0
A23: 22 | B23: javaparser | C23: Unstable Dependency | D23: aPackage | E23: link | F23: link | G23: 3 | H23: =VLOOKUP(D23,G3P1!$D$12:$E$21,2,0) -> yes | I23: =VLOOKUP(D23,G3P2!$D$12:$E$21,2,0) -> no | J23: =VLOOKUP(D23,G3P3!$D$12:$E$21,2,0) -> no | K23: =IF(COUNTIF(H23:J23,"yes")>=2,1,0) -> 0
A24: 23 | B24: javaparser | C24: Unstable Dependency | D24: issue1945.main | E24: link | F24: link | G24: 3 | H24: =VLOOKUP(D24,G3P1!$D$12:$E$21,2,0) -> no | I24: =VLOOKUP(D24,G3P2!$D$12:$E$21,2,0) -> no | J24: =VLOOKUP(D24,G3P3!$D$12:$E$21,2,0) -> no | K24: =IF(COUNTIF(H24:J24,"yes")>=2,1,0) -> 0
A25: 24 | B25: jitwatch | C25: Unstable Dependency | D25: org.adoptopenjdk.jitwatch.parser.j9 | E25: link | F25: link | G25: 3 | H25: =VLOOKUP(D25,G3P1!$D$12:$E$21,2,0) -> no | I25: =VLOOKUP(D25,G3P2!$D$12:$E$21,2,0) -> no | J25: =VLOOKUP(D25,G3P3!$D$12:$E$21,2,0) -> no | K25: =IF(COUNTIF(H25:J25,"yes")>=2,1,0) -> 0
A26: 25 | B26: zxing | C26: Unstable Dependency | D26: com.google.zxing.oned.rss | E26: link | F26: link | G26: 3 | H26: =VLOOKUP(D26,G3P1!$D$12:$E$21,2,0) -> no | I26: =VLOOKUP(D26,G3P2!$D$12:$E$21,2,0) -> no | J26: =VLOOKUP(D26,G3P3!$D$12:$E$21,2,0) -> no | K26: =IF(COUNTIF(H26:J26,"yes")>=2,1,0) -> 0
A27: 26 | B27: jitwatch | C27: Unstable Dependency | D27: org.adoptopenjdk.jitwatch.report | E27: link | F27: link | G27: 3 | H27: =VLOOKUP(D27,G3P1!$D$12:$E$21,2,0) -> yes | I27: =VLOOKUP(D27,G3P2!$D$12:$E$21,2,0) -> yes | J27: =VLOOKUP(D27,G3P3!$D$12:$E$21,2,0) -> yes | K27: =IF(COUNTIF(H27:J27,"yes")>=2,1,0) -> 1
A28: 27 | B28: byte-buddy | C28: Unstable Dependency | D28: net.bytebuddy.benchmark.specimen | E28: link | F28: link | G28: 3 | H28: =VLOOKUP(D28,G3P1!$D$12:$E$21,2,0) -> yes | I28: =VLOOKUP(D28,G3P2!$D$12:$E$21,2,0) -> no | J28: =VLOOKUP(D28,G3P3!$D$12:$E$21,2,0) -> no | K28: =IF(COUNTIF(H28:J28,"yes")>=2,1,0) -> 0
A29: 28 | B29: jitwatch | C29: Unstable Dependency | D29: org.adoptopenjdk.jitwatch.hotthrow | E29: link | F29: link | G29: 3 | H29: =VLOOKUP(D29,G3P1!$D$12:$E$21,2,0) -> yes | I29: =VLOOKUP(D29,G3P2!$D$12:$E$21,2,0) -> no | J29: =VLOOKUP(D29,G3P3!$D$12:$E$21,2,0) -> no | K29: =IF(COUNTIF(H29:J29,"yes")>=2,1,0) -> 0
A30: 29 | B30: jitwatch | C30: Unstable Dependency | D30: org.adoptopenjdk.jitwatch.ui.compilationchooser | E30: link | F30: link | G30: 3 | H30: =VLOOKUP(D30,G3P1!$D$12:$E$21,2,0) -> yes | I30: =VLOOKUP(D30,G3P2!$D$12:$E$21,2,0) -> yes | J30: =VLOOKUP(D30,G3P3!$D$12:$E$21,2,0) -> yes | K30: =IF(COUNTIF(H30:J30,"yes")>=2,1,0) -> 1
A31: 30 | B31: zxing | C31: Unstable Dependency | D31: com.google.zxing.client.android.camera | E31: link | F31: link | G31: 3 | H31: =VLOOKUP(D31,G3P1!$D$12:$E$21,2,0) -> yes | I31: =VLOOKUP(D31,G3P2!$D$12:$E$21,2,0) -> no | J31: =VLOOKUP(D31,G3P3!$D$12:$E$21,2,0) -> no | K31: =IF(COUNTIF(H31:J31,"yes")>=2,1,0) -> 0
A32: 31 | B32: zxing | C32: Unstable Dependency | D32: com.google.zxing.integration.android | E32: link | F32: link | G32: 4 | H32: =VLOOKUP(D32,G4P1!$D$12:$E$21,2,0) -> no | I32: =VLOOKUP(D32,G4P2!$D$12:$E$21,2,0) -> no | J32: no | K32: =IF(COUNTIF(H32:J32,"yes")>=2,1,0) -> 0
A33: 32 | B33: zxing | C33: Unstable Dependency | D33: com.google.zxing.client.android.book | E33: link | F33: link | G33: 4 | H33: =VLOOKUP(D33,G4P1!$D$12:$E$21,2,0) -> no | I33: =VLOOKUP(D33,G4P2!$D$12:$E$21,2,0) -> no | J33: no | K33: =IF(COUNTIF(H33:J33,"yes")>=2,1,0) -> 0
A34: 33 | B34: zxing | C34: Unstable Dependency | D34: com.google.zxing.client.android.clipboard | E34: link | F34: link | G34: 4 | H34: =VLOOKUP(D34,G4P1!$D$12:$E$21,2,0) -> no | I34: =VLOOKUP(D34,G4P2!$D$12:$E$21,2,0) -> no | J34: no | K34: =IF(COUNTIF(H34:J34,"yes")>=2,1,0) -> 0
A35: 34 | B35: gson | C35: Unstable Dependency | D35: com.google.gson.internal.bind.util | E35: link | F35: link | G35: 4 | H35: =VLOOKUP(D35,G4P1!$D$12:$E$21,2,0) -> no | I35: =VLOOKUP(D35,G4P2!$D$12:$E$21,2,0) -> no | J35: no | K35: =IF(COUNTIF(H35:J35,"yes")>=2,1,0) -> 0
A36: 35 | B36: commons-lang | C36: Unstable Dependency | D36: org.apache.commons.lang3.event | E36: link | F36: link | G36: 4 | H36: no | I36: =VLOOKUP(D36,G4P2!$D$12:$E$21,2,0) -> no | J36: no | K36: =IF(COUNTIF(H36:J36,"yes")>=2,1,0) -> 0
A37: 36 | B37: zxing | C37: Unstable Dependency | D37: com.google.zxing.maxicode.decoder | E37: link | F37: link | G37: 4 | H37: =VLOOKUP(D37,G4P1!$D$12:$E$21,2,0) -> no | I37: =VLOOKUP(D37,G4P2!$D$12:$E$21,2,0) -> no | J37: no | K37: =IF(COUNTIF(H37:J37,"yes")>=2,1,0) -> 0
A38: 37 | B38: jitwatch | C38: Unstable Dependency | D38: org.adoptopenjdk.jitwatch.parser.zing | E38: link | F38: link | G38: 4 | H38: =VLOOKUP(D38,G4P1!$D$12:$E$21,2,0) -> no | I38: =VLOOKUP(D38,G4P2!$D$12:$E$21,2,0) -> no | J38: no | K38: =IF(COUNTIF(H38:J38,"yes")>=2,1,0) -> 0
A39: 38 | B39: gson | C39: Unstable Dependency | D39: com.google.gson.protobuf | E39: link | F39: link | G39: 4 | H39: =VLOOKUP(D39,G4P1!$D$12:$E$21,2,0) -> no | I39: =VLOOKUP(D39,G4P2!$D$12:$E$21,2,0) -> no | J39: no | K39: =IF(COUNTIF(H39:J39,"yes")>=2,1,0) -> 0
A40: 39 | B40: jitwatch | C40: Unstable Dependency | D40: org.adoptopenjdk.jitwatch.ui.stage | E40: link | F40: link | G40: 4 | H40: =VLOOKUP(D40,G4P1!$D$12:$E$21,2,0) -> yes | I40: =VLOOKUP(D40,G4P2!$D$12:$E$21,2,0) -> yes | J40: no | K40: =IF(COUNTIF(H40:J40,"yes")>=2,1,0) -> 1
...

Sheet _IM
A1: id | B1: project | C1: smell | D1: class | E1: repo_link | F1: metrics_link | G1: group | H1: vote 1 | I1: vote 2 | J1: vote 3 | K1: label
A2: 1 | B2: javaparser | C2: Insufficient Modularization | D2: com.github.javaparser.symbolsolver.javassistmodel.JavassistMethodDeclaration | E2: link | F2: link | G2: 1 | H2: =VLOOKUP(D2,G1P1!$D$22:$E$31,2,0) -> no | I2: =VLOOKUP(D2,G1P2!$D$22:$E$31,2,0) -> no | J2: =VLOOKUP(D2,G1P3!$D$22:$E$31,2,0) -> no | K2: =IF(COUNTIF(H2:J2,"yes")>=2,1,0) -> 0
A3: 2 | B3: javaparser | C3: Insufficient Modularization | D3: com.github.javaparser.ast.type.PrimitiveType | E3: link | F3: link | G3: 1 | H3: =VLOOKUP(D3,G1P1!$D$22:$E$31,2,0) -> yes | I3: =VLOOKUP(D3,G1P2!$D$22:$E$31,2,0) -> no | J3: =VLOOKUP(D3,G1P3!$D$22:$E$31,2,0) -> yes | K3: =IF(COUNTIF(H3:J3,"yes")>=2,1,0) -> 1
A4: 3 | B4: javaparser | C4: Insufficient Modularization | D4: com.github.javaparser.Range | E4: link | F4: link | G4: 1 | H4: =VLOOKUP(D4,G1P1!$D$22:$E$31,2,0) -> yes | I4: =VLOOKUP(D4,G1P2!$D$22:$E$31,2,0) -> yes | J4: =VLOOKUP(D4,G1P3!$D$22:$E$31,2,0) -> no | K4: =IF(COUNTIF(H4:J4,"yes")>=2,1,0) -> 1
A5: 4 | B5: zxing | C5: Insufficient Modularization | D5: com.google.zxing.common.BitMatrix | E5: link | F5: link | G5: 1 | H5: =VLOOKUP(D5,G1P1!$D$22:$E$31,2,0) -> yes | I5: =VLOOKUP(D5,G1P2!$D$22:$E$31,2,0) -> yes | J5: =VLOOKUP(D5,G1P3!$D$22:$E$31,2,0) -> yes | K5: =IF(COUNTIF(H5:J5,"yes")>=2,1,0) -> 1
A6: 5 | B6: javaparser | C6: Insufficient Modularization | D6: com.github.javaparser.symbolsolver.resolution.typeinference.BoundSet | E6: link | F6: link | G6: 1 | H6: =VLOOKUP(D6,G1P1!$D$22:$E$31,2,0) -> yes | I6: =VLOOKUP(D6,G1P2!$D$22:$E$31,2,0) -> yes | J6: =VLOOKUP(D6,G1P3!$D$22:$E$31,2,0) -> yes | K6: =IF(COUNTIF(H6:J6,"yes")>=2,1,0) -> 1
A7: 6 | B7: zxing | C7: Insufficient Modularization | D7: com.google.zxing.EncodeHintType | E7: link | F7: link | G7: 1 | H7: =VLOOKUP(D7,G1P1!$D$22:$E$31,2,0) -> no | I7: =VLOOKUP(D7,G1P2!$D$22:$E$31,2,0) -> no | J7: =VLOOKUP(D7,G1P3!$D$22:$E$31,2,0) -> no | K7: =IF(COUNTIF(H7:J7,"yes")>=2,1,0) -> 0
A8: 7 | B8: jitwatch | C8: Insufficient Modularization | D8: org.adoptopenjdk.jitwatch.util.StringUtil | E8: link | F8: link | G8: 1 | H8: =VLOOKUP(D8,G1P1!$D$22:$E$31,2,0) -> yes | I8: =VLOOKUP(D8,G1P2!$D$22:$E$31,2,0) -> yes | J8: =VLOOKUP(D8,G1P3!$D$22:$E$31,2,0) -> yes | K8: =IF(COUNTIF(H8:J8,"yes")>=2,1,0) -> 1
A9: 8 | B9: byte-buddy | C9: Insufficient Modularization | D9: net.bytebuddy.dynamic.TypeResolutionStrategy | E9: link | F9: link | G9: 1 | H9: =VLOOKUP(D9,G1P1!$D$22:$E$31,2,0) -> no | I9: =VLOOKUP(D9,G1P2!$D$22:$E$31,2,0) -> yes | J9: =VLOOKUP(D9,G1P3!$D$22:$E$31,2,0) -> no | K9: =IF(COUNTIF(H9:J9,"yes")>=2,1,0) -> 0
A10: 9 | B10: jimfs | C10: Insufficient Modularization | D10: com.google.common.jimfs.RegularFile | E10: link | F10: link | G10: 1 | H10: =VLOOKUP(D10,G1P1!$D$22:$E$31,2,0) -> yes | I10: =VLOOKUP(D10,G1P2!$D$22:$E$31,2,0) -> no | J10: =VLOOKUP(D10,G1P3!$D$22:$E$31,2,0) -> yes | K10: =IF(COUNTIF(H10:J10,"yes")>=2,1,0) -> 1
A11: 10 | B11: javaparser | C11: Insufficient Modularization | D11: com.github.javaparser.ast.modules.ModuleOpensDirective | E11: link | F11: link | G11: 1 | H11: =VLOOKUP(D11,G1P1!$D$22:$E$31,2,0) -> no | I11: =VLOOKUP(D11,G1P2!$D$22:$E$31,2,0) -> no | J11: =VLOOKUP(D11,G1P3!$D$22:$E$31,2,0) -> no | K11: =IF(COUNTIF(H11:J11,"yes")>=2,1,0) -> 0
A12: 11 | B12: byte-buddy | C12: Insufficient Modularization | D12: net.bytebuddy.implementation.attribute.AnnotationValueFilter | E12: link | F12: link | G12: 2 | H12: =VLOOKUP(D12,G2P1!$D$22:$E$31,2,0) -> no | I12: =VLOOKUP(D12,G2P2!$D$22:$E$31,2,0) -> yes | J12: no | K12: =IF(COUNTIF(H12:J12,"yes")>=2,1,0) -> 0
A13: 12 | B13: zxing | C13: Insufficient Modularization | D13: com.google.zxing.datamatrix.decoder.DataBlock | E13: link | F13: link | G13: 2 | H13: =VLOOKUP(D13,G2P1!$D$22:$E$31,2,0) -> no | I13: =VLOOKUP(D13,G2P2!$D$22:$E$31,2,0) -> no | J13: no | K13: =IF(COUNTIF(H13:J13,"yes")>=2,1,0) -> 0
A14: 13 | B14: javaparser | C14: Insufficient Modularization | D14: com.github.javaparser.javasymbolsolver.javassist.symbols.main.jar.InterfaceUserOwnJar | E14: link | F14: link | G14: 2 | H14: =VLOOKUP(D14,G2P1!$D$22:$E$31,2,0) -> no | I14: =VLOOKUP(D14,G2P2!$D$22:$E$31,2,0) -> no | J14: no | K14: =IF(COUNTIF(H14:J14,"yes")>=2,1,0) -> 0
A15: 14 | B15: commons-lang | C15: Insufficient Modularization | D15: org.apache.commons.lang3.exception.CloneFailedException | E15: link | F15: link | G15: 2 | H15: =VLOOKUP(D15,G2P1!$D$22:$E$31,2,0) -> no | I15: =VLOOKUP(D15,G2P2!$D$22:$E$31,2,0) -> no | J15: no | K15: =IF(COUNTIF(H15:J15,"yes")>=2,1,0) -> 0
A16: 15 | B16: javaparser | C16: Insufficient Modularization | D16: com.github.javaparser.symbolsolver.javaparsermodel.declarations.JavaParserClassDeclaration | E16: link | F16: link | G16: 2 | H16: =VLOOKUP(D16,G2P1!$D$22:$E$31,2,0) -> yes | I16: =VLOOKUP(D16,G2P2!$D$22:$E$31,2,0) -> no | J16: yes | K16: =IF(COUNTIF(H16:J16,"yes")>=2,1,0) -> 1
A17: 16 | B17: javaparser | C17: Insufficient Modularization | D17: com.github.javaparser.ast.visitor.HashCodeVisitor | E17: link | F17: link | G17: 2 | H17: =VLOOKUP(D17,G2P1!$D$22:$E$31,2,0) -> yes | I17: =VLOOKUP(D17,G2P2!$D$22:$E$31,2,0) -> yes | J17: no | K17: =IF(COUNTIF(H17:J17,"yes")>=2,1,0) -> 1
A18: 17 | B18: jitwatch | C18: Insufficient Modularization | D18: org.adoptopenjdk.jitwatch.parser.zing.ZingLine | E18: link | F18: link | G18: 2 | H18: =VLOOKUP(D18,G2P1!$D$22:$E$31,2,0) -> no | I18: =VLOOKUP(D18,G2P2!$D$22:$E$31,2,0) -> no | J18: no | K18: =IF(COUNTIF(H18:J18,"yes")>=2,1,0) -> 0
A19: 18 | B19: jsoup | C19: Insufficient Modularization | D19: org.jsoup.helper.RequestDispatch | E19: link | F19: link | G19: 2 | H19: =VLOOKUP(D19,G2P1!$D$22:$E$31,2,0) -> no | I19: =VLOOKUP(D19,G2P2!$D$22:$E$31,2,0) -> no | J19: no | K19: =IF(COUNTIF(H19:J19,"yes")>=2,1,0) -> 0
A20: 19 | B20: jitwatch | C20: Insufficient Modularization | D20: org.adoptopenjdk.jitwatch.parser.ParserFactory | E20: link | F20: link | G20: 2 | H20: =VLOOKUP(D20,G2P1!$D$22:$E$31,2,0) -> no | I20: =VLOOKUP(D20,G2P2!$D$22:$E$31,2,0) -> no | J20: no | K20: =IF(COUNTIF(H20:J20,"yes")>=2,1,0) -> 0
A21: 20 | B21: commons-lang | C21: Insufficient Modularization | D21: org.apache.commons.lang3.mutable.MutableFloat | E21: link | F21: link | G21: 2 | H21: =VLOOKUP(D21,G2P1!$D$22:$E$31,2,0) -> yes | I21: =VLOOKUP(D21,G2P2!$D$22:$E$31,2,0) -> no | J21: yes | K21: =IF(COUNTIF(H21:J21,"yes")>=2,1,0) -> 1
A22: 21 | B22: byte-buddy | C22: Insufficient Modularization | D22: net.bytebuddy.utility.privilege.GetSystemPropertyAction | E22: link | F22: link | G22: 3 | H22: =VLOOKUP(D22,G3P1!$D$22:$E$31,2,0) -> yes | I22: =VLOOKUP(D22,G3P2!$D$22:$E$31,2,0) -> no | J22: =VLOOKUP(D22,G3P3!$D$22:$E$31,2,0) -> no | K22: =IF(COUNTIF(H22:J22,"yes")>=2,1,0) -> 0
A23: 22 | B23: jsoup | C23: Insufficient Modularization | D23: org.jsoup.helper.CookieUtil | E23: link | F23: link | G23: 3 | H23: =VLOOKUP(D23,G3P1!$D$22:$E$31,2,0) -> yes | I23: =VLOOKUP(D23,G3P2!$D$22:$E$31,2,0) -> no | J23: =VLOOKUP(D23,G3P3!$D$22:$E$31,2,0) -> yes | K23: =IF(COUNTIF(H23:J23,"yes")>=2,1,0) -> 1
A24: 23 | B24: commons-lang | C24: Insufficient Modularization | D24: org.apache.commons.lang3.time.FastDateFormat | E24: link | F24: link | G24: 3 | H24: =VLOOKUP(D24,G3P1!$D$22:$E$31,2,0) -> yes | I24: =VLOOKUP(D24,G3P2!$D$22:$E$31,2,0) -> yes | J24: =VLOOKUP(D24,G3P3!$D$22:$E$31,2,0) -> no | K24: =IF(COUNTIF(H24:J24,"yes")>=2,1,0) -> 1
A25: 24 | B25: byte-buddy | C25: Insufficient Modularization | D25: net.bytebuddy.description.modifier.Ownership | E25: link | F25: link | G25: 3 | H25: =VLOOKUP(D25,G3P1!$D$22:$E$31,2,0) -> no | I25: =VLOOKUP(D25,G3P2!$D$22:$E$31,2,0) -> no | J25: =VLOOKUP(D25,G3P3!$D$22:$E$31,2,0) -> yes | K25: =IF(COUNTIF(H25:J25,"yes")>=2,1,0) -> 0
A26: 25 | B26: javaparser | C26: Insufficient Modularization | D26: org.tensorflow.op.Ops | E26: link | F26: link | G26: 3 | H26: =VLOOKUP(D26,G3P1!$D$22:$E$31,2,0) -> yes | I26: =VLOOKUP(D26,G3P2!$D$22:$E$31,2,0) -> yes | J26: =VLOOKUP(D26,G3P3!$D$22:$E$31,2,0) -> no | K26: =IF(COUNTIF(H26:J26,"yes")>=2,1,0) -> 1
A27: 26 | B27: jitwatch | C27: Insufficient Modularization | D27: org.adoptopenjdk.jitwatch.ui.nmethod.NMethodInfo | E27: link | F27: link | G27: 3 | H27: =VLOOKUP(D27,G3P1!$D$22:$E$31,2,0) -> no | I27: =VLOOKUP(D27,G3P2!$D$22:$E$31,2,0) -> no | J27: =VLOOKUP(D27,G3P3!$D$22:$E$31,2,0) -> no | K27: =IF(COUNTIF(H27:J27,"yes")>=2,1,0) -> 0
A28: 27 | B28: zxing | C28: Insufficient Modularization | D28: com.google.zxing.common.reedsolomon.ReedSolomonEncoder | E28: link | F28: link | G28: 3 | H28: =VLOOKUP(D28,G3P1!$D$22:$E$31,2,0) -> no | I28: =VLOOKUP(D28,G3P2!$D$22:$E$31,2,0) -> no | J28: =VLOOKUP(D28,G3P3!$D$22:$E$31,2,0) -> no | K28: =IF(COUNTIF(H28:J28,"yes")>=2,1,0) -> 0
A29: 28 | B29: commons-io | C29: Insufficient Modularization | D29: org.apache.commons.io.output.ProxyOutputStream | E29: link | F29: link | G29: 3 | H29: =VLOOKUP(D29,G3P1!$D$22:$E$31,2,0) -> yes | I29: =VLOOKUP(D29,G3P2!$D$22:$E$31,2,0) -> no | J29: =VLOOKUP(D29,G3P3!$D$22:$E$31,2,0) -> no | K29: =IF(COUNTIF(H29:J29,"yes")>=2,1,0) -> 0
A30: 29 | B30: javaparser | C30: Insufficient Modularization | D30: com.github.javaparser.metamodel.TypeParameterMetaModel | E30: link | F30: link | G30: 3 | H30: =VLOOKUP(D30,G3P1!$D$22:$E$31,2,0) -> no | I30: =VLOOKUP(D30,G3P2!$D$22:$E$31,2,0) -> no | J30: =VLOOKUP(D30,G3P3!$D$22:$E$31,2,0) -> no | K30: =IF(COUNTIF(H30:J30,"yes")>=2,1,0) -> 0
A31: 30 | B31: commons-lang | C31: Insufficient Modularization | D31: org.apache.commons.lang3.Validate | E31: link | F31: link | G31: 3 | H31: =VLOOKUP(D31,G3P1!$D$22:$E$31,2,0) -> yes | I31: =VLOOKUP(D31,G3P2!$D$22:$E$31,2,0) -> yes | J31: =VLOOKUP(D31,G3P3!$D$22:$E$31,2,0) -> yes | K31: =IF(COUNTIF(H31:J31,"yes")>=2,1,0) -> 1
A32: 31 | B32: javaparser | C32: Insufficient Modularization | D32: com.github.javaparser.ast.visitor.VoidVisitor | E32: link | F32: link | G32: 4 | H32: =VLOOKUP(D32,G4P1!$D$22:$E$31,2,0) -> yes | I32: =VLOOKUP(D32,G4P2!$D$22:$E$31,2,0) -> no | J32: no | K32: =IF(COUNTIF(H32:J32,"yes")>=2,1,0) -> 0
A33: 32 | B33: javaparser | C33: Insufficient Modularization | D33: com.github.javaparser.ast.body.ConstructorDeclaration | E33: link | F33: link | G33: 4 | H33: =VLOOKUP(D33,G4P1!$D$22:$E$31,2,0) -> yes | I33: =VLOOKUP(D33,G4P2!$D$22:$E$31,2,0) -> yes | J33: no | K33: =IF(COUNTIF(H33:J33,"yes")>=2,1,0) -> 1
A34: 33 | B34: commons-io | C34: Insufficient Modularization | D34: org.apache.commons.io.CloseableURLConnection | E34: link | F34: link | G34: 4 | H34: =VLOOKUP(D34,G4P1!$D$22:$E$31,2,0) -> yes | I34: =VLOOKUP(D34,G4P2!$D$22:$E$31,2,0) -> no | J34: no | K34: =IF(COUNTIF(H34:J34,"yes")>=2,1,0) -> 0
A35: 34 | B35: jitwatch | C35: Insufficient Modularization | D35: org.adoptopenjdk.jitwatch.demo.MakeHotSpotLog | E35: link | F35: link | G35: 4 | H35: =VLOOKUP(D35,G4P1!$D$22:$E$31,2,0) -> yes | I35: =VLOOKUP(D35,G4P2!$D$22:$E$31,2,0) -> no | J35: no | K35: =IF(COUNTIF(H35:J35,"yes")>=2,1,0) -> 0
A36: 35 | B36: javaparser | C36: Insufficient Modularization | D36: com.github.javaparser.resolution.logic.MethodResolutionLogic | E36: link | F36: link | G36: 4 | H36: =VLOOKUP(D36,G4P1!$D$22:$E$31,2,0) -> yes | I36: =VLOOKUP(D36,G4P2!$D$22:$E$31,2,0) -> no | J36: no | K36: =IF(COUNTIF(H36:J36,"yes")>=2,1,0) -> 0
A37: 36 | B37: javaparser | C37: Insufficient Modularization | D37: com.github.javaparser.symbolsolver.javaparsermodel.contexts.ArrayAccessExprContext | E37: link | F37: link | G37: 4 | H37: =VLOOKUP(D37,G4P1!$D$22:$E$31,2,0) -> no | I37: =VLOOKUP(D37,G4P2!$D$22:$E$31,2,0) -> no | J37: no | K37: =IF(COUNTIF(H37:J37,"yes")>=2,1,0) -> 0
A38: 37 | B38: zxing | C38: Insufficient Modularization | D38: com.google.zxing.pdf417.decoder.DetectionResultColumn | E38: link | F38: link | G38: 4 | H38: =VLOOKUP(D38,G4P1!$D$22:$E$31,2,0) -> no | I38: =VLOOKUP(D38,G4P2!$D$22:$E$31,2,0) -> no | J38: no | K38: =IF(COUNTIF(H38:J38,"yes")>=2,1,0) -> 0
A39: 38 | B39: zxing | C39: Insufficient Modularization | D39: com.google.zxing.qrcode.decoder.ErrorCorrectionLevel | E39: link | F39: link | G39: 4 | H39: =VLOOKUP(D39,G4P1!$D$22:$E$31,2,0) -> no | I39: =VLOOKUP(D39,G4P2!$D$22:$E$31,2,0) -> no | J39: no | K39: =IF(COUNTIF(H39:J39,"yes")>=2,1,0) -> 0
A40: 39 | B40: jitwatch | C40: Insufficient Modularization | D40: org.adoptopenjdk.jitwatch.ui.report.ReportStageType | E40: link | F40: link | G40: 4 | H40: =VLOOKUP(D40,G4P1!$D$22:$E$31,2,0) -> no | I40: =VLOOKUP(D40,G4P2!$D$22:$E$31,2,0) -> no | J40: no | K40: =IF(COUNTIF(H40:J40,"yes")>=2,1,0) -> 0
...

Sheet _HM
A1: id | B1: project | C1: smell | D1: class | E1: repo_link | F1: metrics_link | G1: group | H1: vote 1 | I1: vote 2 | J1: vote 3 | K1: label
A2: 1 | B2: javaparser | C2: Hub-like Modularization | D2: com.github.javaparser.symbolsolver.resolution.typeinference.bounds.SubtypeOfBound | E2: link | F2: link | G2: 1 | H2: =VLOOKUP(D2,G1P1!$D$32:$E$41,2,0) -> no | I2: =VLOOKUP(D2,G1P2!$D$32:$E$41,2,0) -> no | J2: =VLOOKUP(D2,G1P3!$D$32:$E$41,2,0) -> no | K2: =IF(COUNTIF(H2:J2,"yes")>=2,1,0) -> 0
A3: 2 | B3: javaparser | C3: Hub-like Modularization | D3: com.github.javaparser.metamodel.BaseNodeMetaModel | E3: link | F3: link | G3: 1 | H3: =VLOOKUP(D3,G1P1!$D$32:$E$41,2,0) -> no | I3: =VLOOKUP(D3,G1P2!$D$32:$E$41,2,0) -> no | J3: =VLOOKUP(D3,G1P3!$D$32:$E$41,2,0) -> no | K3: =IF(COUNTIF(H3:J3,"yes")>=2,1,0) -> 0
A4: 3 | B4: byte-buddy | C4: Hub-like Modularization | D4: net.bytebuddy.ByteBuddy | E4: link | F4: link | G4: 1 | H4: =VLOOKUP(D4,G1P1!$D$32:$E$41,2,0) -> yes | I4: =VLOOKUP(D4,G1P2!$D$32:$E$41,2,0) -> yes | J4: =VLOOKUP(D4,G1P3!$D$32:$E$41,2,0) -> yes | K4: =IF(COUNTIF(H4:J4,"yes")>=2,1,0) -> 1
A5: 4 | B5: commons-io | C5: Hub-like Modularization | D5: org.apache.commons.io.input.ClassLoaderObjectInputStream | E5: link | F5: link | G5: 1 | H5: =VLOOKUP(D5,G1P1!$D$32:$E$41,2,0) -> no | I5: =VLOOKUP(D5,G1P2!$D$32:$E$41,2,0) -> no | J5: =VLOOKUP(D5,G1P3!$D$32:$E$41,2,0) -> no | K5: =IF(COUNTIF(H5:J5,"yes")>=2,1,0) -> 0
A6: 5 | B6: byte-buddy | C6: Hub-like Modularization | D6: net.bytebuddy.agent.builder.AgentBuilder | E6: link | F6: link | G6: 1 | H6: =VLOOKUP(D6,G1P1!$D$32:$E$41,2,0) -> yes | I6: =VLOOKUP(D6,G1P2!$D$32:$E$41,2,0) -> yes | J6: =VLOOKUP(D6,G1P3!$D$32:$E$41,2,0) -> yes | K6: =IF(COUNTIF(H6:J6,"yes")>=2,1,0) -> 1
A7: 6 | B7: google-java-format | C7: Hub-like Modularization | D7: com.google.googlejavaformat.intellij.UiFormatterStyle | E7: link | F7: link | G7: 1 | H7: =VLOOKUP(D7,G1P1!$D$32:$E$41,2,0) -> no | I7: =VLOOKUP(D7,G1P2!$D$32:$E$41,2,0) -> no | J7: =VLOOKUP(D7,G1P3!$D$32:$E$41,2,0) -> no | K7: =IF(COUNTIF(H7:J7,"yes")>=2,1,0) -> 0
A8: 7 | B8: byte-buddy | C8: Hub-like Modularization | D8: net.bytebuddy.dynamic.loading.ClassInjector | E8: link | F8: link | G8: 1 | H8: =VLOOKUP(D8,G1P1!$D$32:$E$41,2,0) -> yes | I8: =VLOOKUP(D8,G1P2!$D$32:$E$41,2,0) -> yes | J8: =VLOOKUP(D8,G1P3!$D$32:$E$41,2,0) -> yes | K8: =IF(COUNTIF(H8:J8,"yes")>=2,1,0) -> 1
A9: 8 | B9: zxing | C9: Hub-like Modularization | D9: com.google.zxing.LuminanceSource | E9: link | F9: link | G9: 1 | H9: =VLOOKUP(D9,G1P1!$D$32:$E$41,2,0) -> no | I9: =VLOOKUP(D9,G1P2!$D$32:$E$41,2,0) -> yes | J9: =VLOOKUP(D9,G1P3!$D$32:$E$41,2,0) -> no | K9: =IF(COUNTIF(H9:J9,"yes")>=2,1,0) -> 0
A10: 9 | B10: commons-io | C10: Hub-like Modularization | D10: org.apache.commons.io.channels.ByteArraySeekableByteChannel | E10: link | F10: link | G10: 1 | H10: =VLOOKUP(D10,G1P1!$D$32:$E$41,2,0) -> no | I10: =VLOOKUP(D10,G1P2!$D$32:$E$41,2,0) -> no | J10: =VLOOKUP(D10,G1P3!$D$32:$E$41,2,0) -> no | K10: =IF(COUNTIF(H10:J10,"yes")>=2,1,0) -> 0
A11: 10 | B11: google-java-format | C11: Hub-like Modularization | D11: com.google.googlejavaformat.java.GoogleJavaFormatTool | E11: link | F11: link | G11: 1 | H11: =VLOOKUP(D11,G1P1!$D$32:$E$41,2,0) -> no | I11: =VLOOKUP(D11,G1P2!$D$32:$E$41,2,0) -> no | J11: =VLOOKUP(D11,G1P3!$D$32:$E$41,2,0) -> no | K11: =IF(COUNTIF(H11:J11,"yes")>=2,1,0) -> 0
A12: 11 | B12: gson | C12: Hub-like Modularization | D12: com.google.gson.Gson | E12: link | F12: link | G12: 2 | H12: =VLOOKUP(D12,G2P1!$D$32:$E$41,2,0) -> no | I12: =VLOOKUP(D12,G2P2!$D$32:$E$41,2,0) -> yes | J12: yes | K12: =IF(COUNTIF(H12:J12,"yes")>=2,1,0) -> 1
A13: 12 | B13: javaparser | C13: Hub-like Modularization | D13: com.github.javaparser.symbolsolver.javaparsermodel.JavaParserFacade | E13: link | F13: link | G13: 2 | H13: =VLOOKUP(D13,G2P1!$D$32:$E$41,2,0) -> yes | I13: =VLOOKUP(D13,G2P2!$D$32:$E$41,2,0) -> yes | J13: no | K13: =IF(COUNTIF(H13:J13,"yes")>=2,1,0) -> 1
A14: 13 | B14: javaparser | C14: Hub-like Modularization | D14: com.github.javaparser.symbolsolver.javassistmodel.JavassistEnumDeclaration | E14: link | F14: link | G14: 2 | H14: =VLOOKUP(D14,G2P1!$D$32:$E$41,2,0) -> no | I14: =VLOOKUP(D14,G2P2!$D$32:$E$41,2,0) -> no | J14: no | K14: =IF(COUNTIF(H14:J14,"yes")>=2,1,0) -> 0
A15: 14 | B15: javaparser | C15: Hub-like Modularization | D15: com.github.javaparser.StaticJavaParser | E15: link | F15: link | G15: 2 | H15: =VLOOKUP(D15,G2P1!$D$32:$E$41,2,0) -> yes | I15: =VLOOKUP(D15,G2P2!$D$32:$E$41,2,0) -> yes | J15: no | K15: =IF(COUNTIF(H15:J15,"yes")>=2,1,0) -> 1
A16: 15 | B16: byte-buddy | C16: Hub-like Modularization | D16: net.bytebuddy.asm.MemberSubstitution | E16: link | F16: link | G16: 2 | H16: =VLOOKUP(D16,G2P1!$D$32:$E$41,2,0) -> yes | I16: =VLOOKUP(D16,G2P2!$D$32:$E$41,2,0) -> yes | J16: no | K16: =IF(COUNTIF(H16:J16,"yes")>=2,1,0) -> 1
A17: 16 | B17: jsoup | C17: Hub-like Modularization | D17: org.jsoup.nodes.Element | E17: link | F17: link | G17: 2 | H17: =VLOOKUP(D17,G2P1!$D$32:$E$41,2,0) -> yes | I17: =VLOOKUP(D17,G2P2!$D$32:$E$41,2,0) -> yes | J17: no | K17: =IF(COUNTIF(H17:J17,"yes")>=2,1,0) -> 1
A18: 17 | B18: commons-lang | C18: Hub-like Modularization | D18: org.apache.commons.lang3.function.FailableRunnable | E18: link | F18: link | G18: 2 | H18: =VLOOKUP(D18,G2P1!$D$32:$E$41,2,0) -> no | I18: =VLOOKUP(D18,G2P2!$D$32:$E$41,2,0) -> no | J18: no | K18: =IF(COUNTIF(H18:J18,"yes")>=2,1,0) -> 0
A19: 18 | B19: jsoup | C19: Hub-like Modularization | D19: org.jsoup.UnsupportedMimeTypeException | E19: link | F19: link | G19: 2 | H19: =VLOOKUP(D19,G2P1!$D$32:$E$41,2,0) -> no | I19: =VLOOKUP(D19,G2P2!$D$32:$E$41,2,0) -> no | J19: no | K19: =IF(COUNTIF(H19:J19,"yes")>=2,1,0) -> 0
A20: 19 | B20: zxing | C20: Hub-like Modularization | D20: com.google.zxing.pdf417.detector.Detector | E20: link | F20: link | G20: 2 | H20: =VLOOKUP(D20,G2P1!$D$32:$E$41,2,0) -> no | I20: =VLOOKUP(D20,G2P2!$D$32:$E$41,2,0) -> no | J20: no | K20: =IF(COUNTIF(H20:J20,"yes")>=2,1,0) -> 0
A21: 20 | B21: commons-io | C21: Hub-like Modularization | D21: org.apache.commons.io.function.IOBiConsumer | E21: link | F21: link | G21: 2 | H21: =VLOOKUP(D21,G2P1!$D$32:$E$41,2,0) -> no | I21: =VLOOKUP(D21,G2P2!$D$32:$E$41,2,0) -> no | J21: no | K21: =IF(COUNTIF(H21:J21,"yes")>=2,1,0) -> 0
A22: 21 | B22: jimfs | C22: Hub-like Modularization | D22: com.google.common.jimfs.PathURLConnection | E22: link | F22: link | G22: 3 | H22: =VLOOKUP(D22,G3P1!$D$32:$E$41,2,0) -> no | I22: =VLOOKUP(D22,G3P2!$D$32:$E$41,2,0) -> no | J22: =VLOOKUP(D22,G3P3!$D$32:$E$41,2,0) -> no | K22: =IF(COUNTIF(H22:J22,"yes")>=2,1,0) -> 0
A23: 22 | B23: javaparser | C23: Hub-like Modularization | D23: com.github.javaparser.symbolsolver.JavaSymbolSolver | E23: link | F23: link | G23: 3 | H23: =VLOOKUP(D23,G3P1!$D$32:$E$41,2,0) -> yes | I23: =VLOOKUP(D23,G3P2!$D$32:$E$41,2,0) -> yes | J23: =VLOOKUP(D23,G3P3!$D$32:$E$41,2,0) -> no | K23: =IF(COUNTIF(H23:J23,"yes")>=2,1,0) -> 1
A24: 23 | B24: commons-lang | C24: Hub-like Modularization | D24: org.apache.commons.lang3.time.GmtTimeZone | E24: link | F24: link | G24: 3 | H24: =VLOOKUP(D24,G3P1!$D$32:$E$41,2,0) -> no | I24: =VLOOKUP(D24,G3P2!$D$32:$E$41,2,0) -> no | J24: =VLOOKUP(D24,G3P3!$D$32:$E$41,2,0) -> no | K24: =IF(COUNTIF(H24:J24,"yes")>=2,1,0) -> 0
A25: 24 | B25: javaparser | C25: Hub-like Modularization | D25: com.github.javaparser.ast.Node | E25: link | F25: link | G25: 3 | H25: =VLOOKUP(D25,G3P1!$D$32:$E$41,2,0) -> yes | I25: =VLOOKUP(D25,G3P2!$D$32:$E$41,2,0) -> no | J25: =VLOOKUP(D25,G3P3!$D$32:$E$41,2,0) -> no | K25: =IF(COUNTIF(H25:J25,"yes")>=2,1,0) -> 0
A26: 25 | B26: byte-buddy | C26: Hub-like Modularization | D26: net.bytebuddy.dynamic.scaffold.MethodRegistry | E26: link | F26: link | G26: 3 | H26: =VLOOKUP(D26,G3P1!$D$32:$E$41,2,0) -> yes | I26: =VLOOKUP(D26,G3P2!$D$32:$E$41,2,0) -> yes | J26: =VLOOKUP(D26,G3P3!$D$32:$E$41,2,0) -> yes | K26: =IF(COUNTIF(H26:J26,"yes")>=2,1,0) -> 1
A27: 26 | B27: javaparser | C27: Hub-like Modularization | D27: com.github.javaparser.ast.CompilationUnit | E27: link | F27: link | G27: 3 | H27: =VLOOKUP(D27,G3P1!$D$32:$E$41,2,0) -> yes | I27: =VLOOKUP(D27,G3P2!$D$32:$E$41,2,0) -> no | J27: =VLOOKUP(D27,G3P3!$D$32:$E$41,2,0) -> no | K27: =IF(COUNTIF(H27:J27,"yes")>=2,1,0) -> 0
A28: 27 | B28: byte-buddy | C28: Hub-like Modularization | D28: net.bytebuddy.dynamic.scaffold.MethodGraph | E28: link | F28: link | G28: 3 | H28: =VLOOKUP(D28,G3P1!$D$32:$E$41,2,0) -> yes | I28: =VLOOKUP(D28,G3P2!$D$32:$E$41,2,0) -> no | J28: =VLOOKUP(D28,G3P3!$D$32:$E$41,2,0) -> no | K28: =IF(COUNTIF(H28:J28,"yes")>=2,1,0) -> 0
A29: 28 | B29: javaparser | C29: Hub-like Modularization | D29: com.github.javaparser.metamodel.JavaParserMetaModel | E29: link | F29: link | G29: 3 | H29: =VLOOKUP(D29,G3P1!$D$32:$E$41,2,0) -> yes | I29: =VLOOKUP(D29,G3P2!$D$32:$E$41,2,0) -> yes | J29: =VLOOKUP(D29,G3P3!$D$32:$E$41,2,0) -> yes | K29: =IF(COUNTIF(H29:J29,"yes")>=2,1,0) -> 1
A30: 29 | B30: javaparser | C30: Hub-like Modularization | D30: com.github.javaparser.ast.stmt.Statement | E30: link | F30: link | G30: 3 | H30: =VLOOKUP(D30,G3P1!$D$32:$E$41,2,0) -> yes | I30: =VLOOKUP(D30,G3P2!$D$32:$E$41,2,0) -> no | J30: =VLOOKUP(D30,G3P3!$D$32:$E$41,2,0) -> no | K30: =IF(COUNTIF(H30:J30,"yes")>=2,1,0) -> 0
A31: 30 | B31: javaparser | C31: Hub-like Modularization | D31: com.github.javaparser.printer.lexicalpreservation.LexicalPreservingPrinter | E31: link | F31: link | G31: 3 | H31: =VLOOKUP(D31,G3P1!$D$32:$E$41,2,0) -> yes | I31: =VLOOKUP(D31,G3P2!$D$32:$E$41,2,0) -> yes | J31: =VLOOKUP(D31,G3P3!$D$32:$E$41,2,0) -> no | K31: =IF(COUNTIF(H31:J31,"yes")>=2,1,0) -> 1
A32: 31 | B32: byte-buddy | C32: Hub-like Modularization | D32: net.bytebuddy.asm.Advice | E32: link | F32: link | G32: 4 | H32: =VLOOKUP(D32,G4P1!$D$32:$E$41,2,0) -> yes | I32: =VLOOKUP(D32,G4P2!$D$32:$E$41,2,0) -> yes | J32: no | K32: =IF(COUNTIF(H32:J32,"yes")>=2,1,0) -> 1
A33: 32 | B33: javaparser | C33: Hub-like Modularization | D33: com.github.javaparser.JavaParserAdapter | E33: link | F33: link | G33: 4 | H33: =VLOOKUP(D33,G4P1!$D$32:$E$41,2,0) -> yes | I33: =VLOOKUP(D33,G4P2!$D$32:$E$41,2,0) -> no | J33: no | K33: =IF(COUNTIF(H33:J33,"yes")>=2,1,0) -> 0
A34: 33 | B34: jitwatch | C34: Hub-like Modularization | D34: org.adoptopenjdk.jitwatch.model.bytecode.LineTable | E34: link | F34: link | G34: 4 | H34: =VLOOKUP(D34,G4P1!$D$32:$E$41,2,0) -> no | I34: =VLOOKUP(D34,G4P2!$D$32:$E$41,2,0) -> no | J34: no | K34: =IF(COUNTIF(H34:J34,"yes")>=2,1,0) -> 0
A35: 34 | B35: javaparser | C35: Hub-like Modularization | D35: com.github.javaparser.ast.nodeTypes.modifiers.NodeWithProtectedModifier | E35: link | F35: link | G35: 4 | H35: =VLOOKUP(D35,G4P1!$D$32:$E$41,2,0) -> no | I35: =VLOOKUP(D35,G4P2!$D$32:$E$41,2,0) -> no | J35: no | K35: =IF(COUNTIF(H35:J35,"yes")>=2,1,0) -> 0
A36: 35 | B36: byte-buddy | C36: Hub-like Modularization | D36: net.bytebuddy.matcher.ElementMatchers | E36: link | F36: link | G36: 4 | H36: =VLOOKUP(D36,G4P1!$D$32:$E$41,2,0) -> yes | I36: =VLOOKUP(D36,G4P2!$D$32:$E$41,2,0) -> yes | J36: no | K36: =IF(COUNTIF(H36:J36,"yes")>=2,1,0) -> 1
A37: 36 | B37: javaparser | C37: Hub-like Modularization | D37: (default package).InnerClassDotExpressions | E37: link | F37: link | G37: 4 | H37: =VLOOKUP(D37,G4P1!$D$32:$E$41,2,0) -> no | I37: =VLOOKUP(D37,G4P2!$D$32:$E$41,2,0) -> no | J37: no | K37: =IF(COUNTIF(H37:J37,"yes")>=2,1,0) -> 0
A38: 37 | B38: javaparser | C38: Hub-like Modularization | D38: com.github.javaparser.symbolsolver.reflectionmodel.ReflectionEnumConstantDeclaration | E38: link | F38: link | G38: 4 | H38: =VLOOKUP(D38,G4P1!$D$32:$E$41,2,0) -> no | I38: =VLOOKUP(D38,G4P2!$D$32:$E$41,2,0) -> no | J38: no | K38: =IF(COUNTIF(H38:J38,"yes")>=2,1,0) -> 0
A39: 38 | B39: commons-lang | C39: Hub-like Modularization | D39: org.apache.commons.lang3.time.AbstractFormatCache | E39: link | F39: link | G39: 4 | H39: =VLOOKUP(D39,G4P1!$D$32:$E$41,2,0) -> no | I39: =VLOOKUP(D39,G4P2!$D$32:$E$41,2,0) -> no | J39: no | K39: =IF(COUNTIF(H39:J39,"yes")>=2,1,0) -> 0
A40: 39 | B40: commons-io | C40: Hub-like Modularization | D40: org.apache.commons.io.RandomAccessFileMode | E40: link | F40: link | G40: 4 | H40: =VLOOKUP(D40,G4P1!$D$32:$E$41,2,0) -> no | I40: =VLOOKUP(D40,G4P2!$D$32:$E$41,2,0) -> no | J40: no | K40: =IF(COUNTIF(H40:J40,"yes")>=2,1,0) -> 0
...

Sheet G1P1
A1: id | B1: project | C1: smell | D1: package | E1: is the smell detected? | F1: comment (not required)
A2: 1 | B2: javaparser | C2: God Component | D2: com.github.javaparser.symbolsolver | E2: yes
A3: 2 | B3: jitwatch | C3: God Component | D3: org.adoptopenjdk.jitwatch.ui.parserchooser | E3: no
A4: 3 | B4: jsoup | C4: God Component | D4: org.jsoup.helper | E4: no | F4: Although some classes have high LOC, the domain of the package seems well defined.
A5: 4 | B5: zxing | C5: God Component | D5: com.google.zxing.multi.qrcode.detector | E5: no
A6: 5 | B6: gson | C6: God Component | D6: com.google.gson.internal | E6: yes | F6: High number of classes and LOC
A7: 6 | B7: zxing | C7: God Component | D7: com.google.zxing.oned | E7: yes
A8: 7 | B8: byte-buddy | C8: God Component | D8: net.bytebuddy.description.modifier | E8: yes
A9: 8 | B9: zxing | C9: God Component | D9: com.google.zxing.common | E9: yes
A10: 9 | B10: javaparser | C10: God Component | D10: com.github.javaparser.metamodel | E10: yes
A11: 10 | B11: javaparser | C11: God Component | D11: issue1945.interfaces | E11: no
A12: 11 | B12: jitwatch | C12: Unstable Dependency | D12: org.adoptopenjdk.jitwatch.toplist | E12: yes
A13: 12 | B13: byte-buddy | C13: Unstable Dependency | D13: org.gradle.work | E13: yes
A14: 13 | B14: jitwatch | C14: Unstable Dependency | D14: org.adoptopenjdk.jitwatch.ui.triview.source | E14: yes
A15: 14 | B15: jitwatch | C15: Unstable Dependency | D15: org.adoptopenjdk.jitwatch.model.assembly | E15: yes
A16: 15 | B16: jitwatch | C16: Unstable Dependency | D16: org.adoptopenjdk.jitwatch.process.javap | E16: yes
A17: 16 | B17: zxing | C17: Unstable Dependency | D17: com.google.zxing.aztec.detector | E17: yes
A18: 17 | B18: jitwatch | C18: Unstable Dependency | D18: org.adoptopenjdk.jitwatch.ui.nmethod.compilerthread | E18: yes
A19: 18 | B19: zxing | C19: Unstable Dependency | D19: com.google.zxing.client.android.history | E19: yes | F19: The instability of the package result is equal (0.6), but the two remaining are smaller
A20: 19 | B20: byte-buddy | C20: Unstable Dependency | D20: org.gradle.api.file | E20: yes
A21: 20 | B21: jitwatch | C21: Unstable Dependency | D21: org.adoptopenjdk.jitwatch.process.runtime | E21: yes
A22: 21 | B22: javaparser | C22: Insufficient Modularization | D22: com.github.javaparser.symbolsolver.javassistmodel.JavassistMethodDeclaration | E22: no
A23: 22 | B23: javaparser | C23: Insufficient Modularization | D23: com.github.javaparser.ast.type.PrimitiveType | E23: yes
A24: 23 | B24: javaparser | C24: Insufficient Modularization | D24: com.github.javaparser.Range | E24: yes
A25: 24 | B25: zxing | C25: Insufficient Modularization | D25: com.google.zxing.common.BitMatrix | E25: yes
A26: 25 | B26: javaparser | C26: Insufficient Modularization | D26: com.github.javaparser.symbolsolver.resolution.typeinference.BoundSet | E26: yes
A27: 26 | B27: zxing | C27: Insufficient Modularization | D27: com.google.zxing.EncodeHintType | E27: no
A28: 27 | B28: jitwatch | C28: Insufficient Modularization | D28: org.adoptopenjdk.jitwatch.util.StringUtil | E28: yes
A29: 28 | B29: byte-buddy | C29: Insufficient Modularization | D29: net.bytebuddy.dynamic.TypeResolutionStrategy | E29: no
A30: 29 | B30: jimfs | C30: Insufficient Modularization | D30: com.google.common.jimfs.RegularFile | E30: yes
A31: 30 | B31: javaparser | C31: Insufficient Modularization | D31: com.github.javaparser.ast.modules.ModuleOpensDirective | E31: no
... A38: 37 | B38: byte-buddy | C38: Hub-like Modularization | D38: net.bytebuddy.dynamic.loading.ClassInjector | E38: yes
A39: 38 | B39: zxing | C39: Hub-like Modularization | D39: com.google.zxing.LuminanceSource | E39: no | F39: Just fanin is high.
A40: 39 | B40: commons-io | C40: Hub-like Modularization | D40: org.apache.commons.io.channels.ByteArraySeekableByteChannel | E40: no
A41: 40 | B41: google-java-format | C41: Hub-like Modularization | D41: com.google.googlejavaformat.java.GoogleJavaFormatTool | E41: no

Sheet G1P2
A1: id | B1: project | C1: smell | D1: package | E1: is the smell detected? | F1: comment (not required)
A2: 1 | B2: javaparser | C2: God Component | D2: com.github.javaparser.symbolsolver | E2: yes
A3: 2 | B3: jitwatch | C3: God Component | D3: org.adoptopenjdk.jitwatch.ui.parserchooser | E3: no
A4: 3 | B4: jsoup | C4: God Component | D4: org.jsoup.helper | E4: yes
A5: 4 | B5: zxing | C5: God Component | D5: com.google.zxing.multi.qrcode.detector | E5: no
A6: 5 | B6: gson | C6: God Component | D6: com.google.gson.internal | E6: yes
A7: 6 | B7: zxing | C7: God Component | D7: com.google.zxing.oned | E7: yes
A8: 7 | B8: byte-buddy | C8: God Component | D8: net.bytebuddy.description.modifier | E8: yes
A9: 8 | B9: zxing | C9: God Component | D9: com.google.zxing.common | E9: yes
A10: 9 | B10: javaparser | C10: God Component | D10: com.github.javaparser.metamodel | E10: yes
A11: 10 | B11: javaparser | C11: God Component | D11: issue1945.interfaces | E11: no
A12: 11 | B12: jitwatch | C12: Unstable Dependency | D12: org.adoptopenjdk.jitwatch.toplist | E12: no
A13: 12 | B13: byte-buddy | C13: Unstable Dependency | D13: org.gradle.work | E13: yes
... A26: 25 | B26: javaparser | C26: Insufficient Modularization | D26: com.github.javaparser.symbolsolver.resolution.typeinference.BoundSet | E26: yes
