Workbook

Sheet samples
A1: project | B1: smell | C1: package | D1: class | E1: fqn | F1: prompt_file | G1: context_size | H1: designite | I1: gpt | J1: deepseek | K1: qwen
A2: byte-buddy | B2: Hub-like Modularization | C2: net.bytebuddy.agent.builder | D2: AgentBuilder | E2: net.bytebuddy.agent.builder.AgentBuilder | G2: 16845 | H2: 1 | I2: =VLOOKUP(E2,gpt!$E$2:$F$5412,2,0) -> 1 | J2: =VLOOKUP(E2,deepseek!$E$2:$F$5412,2,0) -> 1 | K2: =VLOOKUP(E2,qwen!$E$2:$F$5412,2,0) -> 1
A3: byte-buddy | B3: Hub-like Modularization | C3: net.bytebuddy.matcher | D3: ElementMatchers | E3: net.bytebuddy.matcher.ElementMatchers | G3: 10914 | H3: 1 | I3: =VLOOKUP(E3,gpt!$E$2:$F$5412,2,0) -> 1 | J3: =VLOOKUP(E3,deepseek!$E$2:$F$5412,2,0) -> 1 | K3: =VLOOKUP(E3,qwen!$E$2:$F$5412,2,0) -> 1
A4: byte-buddy | B4: Hub-like Modularization | C4: net.bytebuddy.asm | D4: Advice | E4: net.bytebuddy.asm.Advice | G4: 16814 | H4: 1 | I4: =VLOOKUP(E4,gpt!$E$2:$F$5412,2,0) -> 1 | J4: =VLOOKUP(E4,deepseek!$E$2:$F$5412,2,0) -> 1 | K4: =VLOOKUP(E4,qwen!$E$2:$F$5412,2,0) -> 1
A5: byte-buddy | B5: Hub-like Modularization | C5: net.bytebuddy.asm | D5: MemberSubstitution | E5: net.bytebuddy.asm.MemberSubstitution | G5: 12594 | H5: 1 | I5: =VLOOKUP(E5,gpt!$E$2:$F$5412,2,0) -> 0 | J5: =VLOOKUP(E5,deepseek!$E$2:$F$5412,2,0) -> 1 | K5: =VLOOKUP(E5,qwen!$E$2:$F$5412,2,0) -> 1
A6: byte-buddy | B6: Hub-like Modularization | C6: net.bytebuddy | D6: ByteBuddy | E6: net.bytebuddy.ByteBuddy | G6: 13466 | H6: 1 | I6: =VLOOKUP(E6,gpt!$E$2:$F$5412,2,0) -> 1 | J6: =VLOOKUP(E6,deepseek!$E$2:$F$5412,2,0) -> 1 | K6: =VLOOKUP(E6,qwen!$E$2:$F$5412,2,0) -> 1
A7: jsoup | B7: Hub-like Modularization | C7: org.jsoup.nodes | D7: Element | E7: org.jsoup.nodes.Element | G7: 4742 | H7: 1 | I7: =VLOOKUP(E7,gpt!$E$2:$F$5412,2,0) -> 1 | J7: =VLOOKUP(E7,deepseek!$E$2:$F$5412,2,0) -> 1 | K7: =VLOOKUP(E7,qwen!$E$2:$F$5412,2,0) -> 1
A8: gson | B8: Hub-like Modularization | C8: com.google.gson | D8: Gson | E8: com.google.gson.Gson | G8: 5856 | H8: 1 | I8: =VLOOKUP(E8,gpt!$E$2:$F$5412,2,0) -> 1 | J8: =VLOOKUP(E8,deepseek!$E$2:$F$5412,2,0) -> 1 | K8: =VLOOKUP(E8,qwen!$E$2:$F$5412,2,0) -> 1
A9: javaparser | B9: Hub-like Modularization | C9: com.github.javaparser.symbolsolver | D9: JavaSymbolSolver | E9: com.github.javaparser.symbolsolver.JavaSymbolSolver | G9: 6074 | H9: 1 | I9: =VLOOKUP(E9,gpt!$E$2:$F$5412,2,0) -> 0 | J9: =VLOOKUP(E9,deepseek!$E$2:$F$5412,2,0) -> 1 | K9: =VLOOKUP(E9,qwen!$E$2:$F$5412,2,0) -> 1
A10: javaparser | B10: Hub-like Modularization | C10: com.github.javaparser.symbolsolver.javaparsermodel | D10: JavaParserFacade | E10: com.github.javaparser.symbolsolver.javaparsermodel.JavaParserFacade | G10: 20287 | H10: 1 | I10: =VLOOKUP(E10,gpt!$E$2:$F$5412,2,0) -> 1 | J10: =VLOOKUP(E10,deepseek!$E$2:$F$5412,2,0) -> 1 | K10: =VLOOKUP(E10,qwen!$E$2:$F$5412,2,0) -> 1
A11: javaparser | B11: Hub-like Modularization | C11: com.github.javaparser.ast | D11: CompilationUnit | E11: com.github.javaparser.ast.CompilationUnit | G11: 44654 | H11: 1 | I11: =VLOOKUP(E11,gpt!$E$2:$F$5412,2,0) -> 1 | J11: =VLOOKUP(E11,deepseek!$E$2:$F$5412,2,0) -> 1 | K11: =VLOOKUP(E11,qwen!$E$2:$F$5412,2,0) -> 1
A12: zxing | B12: Hub-like Modularization | C12: com.google.zxing.oned.Code128Writer | D12: Latch | E12: =C12&"."&D12 -> com.google.zxing.oned.Code128Writer.Latch | F12: data/processed/prompts/hublike_modularization/zxing/com_google_zxing_oned_Code128Writer_Latch.txt | G12: 358 | H12: 0 | I12: =VLOOKUP(E12,gpt!$E$2:$F$5412,2,0) -> 0 | J12: =VLOOKUP(E12,deepseek!$E$2:$F$5412,2,0) -> 0 | K12: =VLOOKUP(E12,qwen!$E$2:$F$5412,2,0) -> 0
A13: zxing | B13: Hub-like Modularization | C13: com.google.zxing.client.result | D13: WifiParsedResult | E13: =C13&"."&D13 -> com.google.zxing.client.result.WifiParsedResult | F13: data/processed/prompts/hublike_modularization/zxing/com_google_zxing_client_result_WifiParsedResult.txt | G13: 480 | H13: 0 | I13: =VLOOKUP(E13,gpt!$E$2:$F$5412,2,0) -> 0 | J13: =VLOOKUP(E13,deepseek!$E$2:$F$5412,2,0) -> 0 | K13: =VLOOKUP(E13,qwen!$E$2:$F$5412,2,0) -> 0
A14: commons-lang | B14: Hub-like Modularization | C14: org.apache.commons.lang3.function | D14: FailableBiPredicate | E14: =C14&"."&D14 -> org.apache.commons.lang3.function.FailableBiPredicate | F14: data/processed/prompts/hublike_modularization/commons-lang/org_apache_commons_lang3_function_FailableBiPredicate.txt | G14: 511 | H14: 0 | I14: =VLOOKUP(E14,gpt!$E$2:$F$5412,2,0) -> 0 | J14: =VLOOKUP(E14,deepseek!$E$2:$F$5412,2,0) -> 0 | K14: =VLOOKUP(E14,qwen!$E$2:$F$5412,2,0) -> 0
A15: byte-buddy | B15: Hub-like Modularization | C15: net.bytebuddy.utility.JavaConstant | D15: OfClassDesc | E15: =C15&"."&D15 -> net.bytebuddy.utility.JavaConstant.OfClassDesc | F15: data/processed/prompts/hublike_modularization/byte-buddy/net_bytebuddy_utility_JavaConstant_OfClassDesc.txt | G15: 810 | H15: 0 | I15: =VLOOKUP(E15,gpt!$E$2:$F$5412,2,0) -> 0 | J15: =VLOOKUP(E15,deepseek!$E$2:$F$5412,2,0) -> 0 | K15: =VLOOKUP(E15,qwen!$E$2:$F$5412,2,0) -> 0
A16: byte-buddy | B16: Hub-like Modularization | C16: net.bytebuddy.build.Plugin | D16: ForJarOutputStream | E16: =C16&"."&D16 -> net.bytebuddy.build.Plugin.ForJarOutputStream | F16: data/processed/prompts/hublike_modularization/byte-buddy/net_bytebuddy_build_Plugin_ForJarOutputStream.txt | G16: 509 | H16: 0 | I16: =VLOOKUP(E16,gpt!$E$2:$F$5412,2,0) -> 0 | J16: =VLOOKUP(E16,deepseek!$E$2:$F$5412,2,0) -> 0 | K16: =VLOOKUP(E16,qwen!$E$2:$F$5412,2,0) -> 0
A17: commons-io | B17: Hub-like Modularization | C17: org.apache.commons.io | D17: CopyUtils | E17: =C17&"."&D17 -> org.apache.commons.io.CopyUtils | F17: data/processed/prompts/hublike_modularization/commons-io/org_apache_commons_io_CopyUtils.txt | G17: 474 | H17: 0 | I17: =VLOOKUP(E17,gpt!$E$2:$F$5412,2,0) -> 0 | J17: =VLOOKUP(E17,deepseek!$E$2:$F$5412,2,0) -> 0 | K17: =VLOOKUP(E17,qwen!$E$2:$F$5412,2,0) -> 0
A18: byte-buddy | B18: Hub-like Modularization | C18: net.bytebuddy.benchmark.jmh.generated.ClassByImplementationBenchmark.benchmarkJdkProxy | D18: jmhTest | E18: =C18&"."&D18 -> net.bytebuddy.benchmark.jmh.generated.ClassByImplementationBenchmark.benchmarkJdkProxy.jmhTest | F18: data/processed/prompts/hublike_modularization/byte-buddy/net_bytebuddy_benchmark_jmh_generated_ClassByImplementationBenchmark_benchmarkJdkProxy_jmhTest.txt | G18: 4425 | H18: 0 | I18: =VLOOKUP(E18,gpt!$E$2:$F$5412,2,0) -> 0 | J18: =VLOOKUP(E18,deepseek!$E$2:$F$5412,2,0) -> 0 | K18: =VLOOKUP(E18,qwen!$E$2:$F$5412,2,0) -> 0
A19: commons-lang | B19: Hub-like Modularization | C19: org.apache.commons.lang3.concurrent | D19: UncheckedExecutionException | E19: =C19&"."&D19 -> org.apache.commons.lang3.concurrent.UncheckedExecutionException | F19: data/processed/prompts/hublike_modularization/commons-lang/org_apache_commons_lang3_concurrent_UncheckedExecutionException.txt | G19: 248 | H19: 0 | I19: =VLOOKUP(E19,gpt!$E$2:$F$5412,2,0) -> 0 | J19: =VLOOKUP(E19,deepseek!$E$2:$F$5412,2,0) -> 0 | K19: =VLOOKUP(E19,qwen!$E$2:$F$5412,2,0) -> 0
A20: byte-buddy | B20: Hub-like Modularization | C20: net.bytebuddy.description.type.TypeDescription | D20: OfAnnotatedElement | E20: =C20&"."&D20 -> net.bytebuddy.description.type.TypeDescription.OfAnnotatedElement | F20: data/processed/prompts/hublike_modularization/byte-buddy/net_bytebuddy_description_type_TypeDescription_OfAnnotatedElement.txt | G20: 249 | H20: 0 | I20: =VLOOKUP(E20,gpt!$E$2:$F$5412,2,0) -> 0 | J20: =VLOOKUP(E20,deepseek!$E$2:$F$5412,2,0) -> 0 | K20: =VLOOKUP(E20,qwen!$E$2:$F$5412,2,0) -> 0
A21: byte-buddy | B21: Hub-like Modularization | C21: net.bytebuddy.dynamic.TypeResolutionStrategy | D21: Passive | E21: =C21&"."&D21 -> net.bytebuddy.dynamic.TypeResolutionStrategy.Passive | F21: data/processed/prompts/hublike_modularization/byte-buddy/net_bytebuddy_dynamic_TypeResolutionStrategy_Passive.txt | G21: 248 | H21: 0 | I21: =VLOOKUP(E21,gpt!$E$2:$F$5412,2,0) -> 0 | J21: =VLOOKUP(E21,deepseek!$E$2:$F$5412,2,0) -> 0 | K21: =VLOOKUP(E21,qwen!$E$2:$F$5412,2,0) -> 0
A22: byte-buddy | B22: Hub-like Modularization | C22: net.bytebuddy.implementation.attribute.AnnotationAppender | D22: OnField | E22: =C22&"."&D22 -> net.bytebuddy.implementation.attribute.AnnotationAppender.OnField | F22: data/processed/prompts/hublike_modularization/byte-buddy/net_bytebuddy_implementation_attribute_AnnotationAppender_OnField.txt | G22: 263 | H22: 0 | I22: =VLOOKUP(E22,gpt!$E$2:$F$5412,2,0) -> 0 | J22: =VLOOKUP(E22,deepseek!$E$2:$F$5412,2,0) -> 0 | K22: =VLOOKUP(E22,qwen!$E$2:$F$5412,2,0) -> 0
A23: byte-buddy | B23: Hub-like Modularization | C23: com.service.definition | D23: ServiceDefinition | E23: =C23&"."&D23 -> com.service.definition.ServiceDefinition | F23: data/processed/prompts/hublike_modularization/byte-buddy/com_service_definition_ServiceDefinition.txt | G23: 244 | H23: 0 | I23: =VLOOKUP(E23,gpt!$E$2:$F$5412,2,0) -> 0 | J23: =VLOOKUP(E23,deepseek!$E$2:$F$5412,2,0) -> 0 | K23: =VLOOKUP(E23,qwen!$E$2:$F$5412,2,0) -> 0
... A361: byte-buddy | B361: Hub-like Modularization | C361: net.bytebuddy.description.modifier | D361: MethodStrictness | E361: =C361&"."&D361 -> net.bytebuddy.description.modifier.MethodStrictness | F361: data/processed/prompts/hublike_modularization/byte-buddy/net_bytebuddy_description_modifier_MethodStrictness.txt | G361: 761 | H361: 0 | I361: =VLOOKUP(E361,gpt!$E$2:$F$5412,2,0) -> 0 | J361: =VLOOKUP(E361,deepseek!$E$2:$F$5412,2,0) -> 0 | K361: =VLOOKUP(E361,qwen!$E$2:$F$5412,2,0) -> 0

Sheet gpt
A1: project | B1: file_name | C1: smell | D1: entity_type | E1: entity | F1: detection | G1: justification
A2: byte-buddy | B2: (default package)_MavenWrapperDownloader.txt | D2: class | E2: (default package).MavenWrapperDownloader | F2: 0 | G2: Hub-like modularization requires many incoming and outgoing dependencies. For this class both dependency lists are empty: incoming_dependencies: [], outgoing_dependencies: []. Therefore it does not exhibit a hub-like dependency structure.
A3: byte-buddy | B3: com.service.definition_ServiceDefinition.txt | D3: class | E3: com.service.definition.ServiceDefinition | F3: 0 | G3: Both incoming_dependencies and outgoing_dependencies are empty (0). The class has no incoming or outgoing connections to many other abstractions, so it does not meet the criteria for Hub-like Modularization.
A4: byte-buddy | B4: com.service.usage2_ServiceImplementation.txt | D4: class | E4: com.service.usage2.ServiceImplementation | F4: 0 | G4: Both incoming_dependencies and outgoing_dependencies are empty (incoming_dependencies: [], outgoing_dependencies: []), resulting in 0 incoming and 0 outgoing connections. Hub-like Modularization requires a large number of both incoming and outgoing dependencies, which is not the case here.
A5: byte-buddy | B5: com.service.usage_ServiceImplementation.txt | D5: class | E5: com.service.usage.ServiceImplementation | F5: 0 | G5: Both incoming_dependencies and outgoing_dependencies are empty (0 incoming, 0 outgoing). Hub-like Modularization requires an abstraction to have dependencies with a large number of other abstractions; this class has no incoming or outgoing dependencies, so it does not exhibit the smell.
A6: byte-buddy | B6: net.bytebuddy.agent.builder_AgentBuilder.Adapter.txt | D6: class | E6: net.bytebuddy.agent.builder.AgentBuilder.Adapter | F6: 0 | G6: Hub-like Modularization requires an abstraction to have many incoming and many outgoing dependencies. For net.bytebuddy.agent.builder.AgentBuilder.Adapter the incoming dependency count is 0 (no incoming dependencies) and the outgoing dependency count is 1 (only depends on net.bytebuddy.build.HashCodeAndEqualsPlugin). Although that target class lists many dependencies, AgentBuilder.Adapter itself does not exhibit a large number of incoming or outgoing links, so it is not a hub.
A7: byte-buddy | B7: net.bytebuddy.agent.builder_AgentBuilder.Appender.txt | D7: class | E7: net.bytebuddy.agent.builder.AgentBuilder.Appender | F7: 0 | G7: Although AgentBuilder.Appender has multiple outgoing dependencies (9 distinct abstractions: net.bytebuddy.implementation.bytecode.assign.Assigner, net.bytebuddy.description.method.MethodDescription, net.bytebuddy.implementation.bytecode.member.MethodReturn, net.bytebuddy.implementation.bytecode.StackManipulation, net.bytebuddy.utility.JavaConstant, net.bytebuddy.description.field.FieldDescription, net.bytebuddy.build.HashCodeAndEqualsPlugin, net.bytebuddy.description.type.TypeDescription, net.bytebuddy.implementation.bytecode.Duplication), it has zero incoming dependencies in the provided data. Hub-like Modularization requires an abstraction to have both many incoming and many outgoing dependencies; because incoming dependencies are absent, this class does not qualify as a hub under the given, isolated metrics.
A8: byte-buddy | B8: net.bytebuddy.agent.builder_AgentBuilder.Asynchronous.txt | D8: class | E8: net.bytebuddy.agent.builder.AgentBuilder.Asynchronous | F8: 0 | G8: AgentBuilder.Asynchronous has only 2 outgoing dependencies (net.bytebuddy.build.HashCodeAndEqualsPlugin, net.bytebuddy.description.type.TypeDescription) and 0 incoming dependencies. Hub-like Modularization requires an abstraction to have many incoming and outgoing ties to other abstractions; this class does not exhibit a large number of direct incoming or outgoing dependencies.
A9: byte-buddy | B9: net.bytebuddy.agent.builder_AgentBuilder.AtFixedRate.txt | D9: class | E9: net.bytebuddy.agent.builder.AgentBuilder.AtFixedRate | F9: 0 | G9: The class has only 1 outgoing dependency (net.bytebuddy.build.HashCodeAndEqualsPlugin) and 0 incoming dependencies. Hub-like Modularization requires an abstraction to have many incoming and outgoing dependencies; this class does not meet that criterion.
A10: byte-buddy | B10: net.bytebuddy.agent.builder_AgentBuilder.BatchAllocator.txt | D10: class | E10: net.bytebuddy.agent.builder.AgentBuilder.BatchAllocator | F10: 0 | G10: The class has only 3 outgoing dependencies (net.bytebuddy.build.HashCodeAndEqualsPlugin, net.bytebuddy.build.SafeVarargsPlugin, net.bytebuddy.description.type.TypeDescription) and only 1 incoming dependency recorded (net.bytebuddy.agent.builder.AgentBuilder). A hub-like modularization requires an abstraction to have many incoming and many outgoing dependency connections; the provided data shows neither a large number of incoming dependents nor a large number of direct outgoing dependencies. Note: although one outgoing target (TypeDescription) itself lists many dependencies, those are not direct dependencies of BatchAllocator and therefore do not make BatchAllocator a hub in the provided, isolated context.
A11: byte-buddy | B11: net.bytebuddy.agent.builder_AgentBuilder.BatchReallocator.txt | D11: class | E11: net.bytebuddy.agent.builder.AgentBuilder.BatchReallocator | F11: 0 | G11: AgentBuilder.BatchReallocator has 0 incoming dependencies and only 1 outgoing dependency (net.bytebuddy.build.HashCodeAndEqualsPlugin). Hub-like Modularization requires the abstraction itself to have a large number of both incoming and outgoing dependencies; those conditions are not met here. Although the single outgoing target (HashCodeAndEqualsPlugin) has many dependencies, that represents second-level connectivity and does not make BatchReallocator a hub when analyzed in isolation.
A12: byte-buddy | B12: net.bytebuddy.agent.builder_AgentBuilder.BootstrapMarkerAction.txt | D12: class | E12: net.bytebuddy.agent.builder.AgentBuilder.BootstrapMarkerAction | F12: 0 | G12: The class has a single incoming dependency (net.bytebuddy.agent.builder.AgentBuilder) and a single outgoing dependency (net.bytebuddy.dynamic.loading.ClassLoadingStrategy). Hub-like modularization requires many incoming and outgoing relationships; here there is only one direct incoming and one direct outgoing dependency. Note: although AgentBuilder and ClassLoadingStrategy themselves reference many other types in the provided data, those are not direct additional incoming/outgoing edges for BootstrapMarkerAction in the given inputs.
A13: byte-buddy | B13: net.bytebuddy.agent.builder_AgentBuilder.BridgeMethodImplementation.txt | D13: class | E13: net.bytebuddy.agent.builder.AgentBuilder.BridgeMethodImplementation | F13: 0 | G13: The class has no incoming dependencies (incoming_dependencies = []). It has only 4 outgoing dependencies: net.bytebuddy.build.HashCodeAndEqualsPlugin, net.bytebuddy.description.method.MethodDescription, net.bytebuddy.utility.JavaConstant, and net.bytebuddy.implementation.bytecode.StackManipulation. Hub-like Modularization requires an abstraction to have a large number of both incoming and outgoing relationships; here incoming = 0 and outgoing is small, so the smell is not present.
... A1475: byte-buddy | B1475: net.bytebuddy.dynamic_VisibilityBridgeStrategy.Default.txt | D1475: class | E1475: net.bytebuddy.dynamic.VisibilityBridgeStrategy.Default | F1475: 0 | G1475: Incoming dependencies: 0 (incoming_dependencies is empty); Outgoing dependencies: 0 (outgoing_dependencies is empty). Hub-like Modularization requires an abstraction to have a large number of both incoming and outgoing dependencies; this class has none, so it is not a hub.
A1476: byte-buddy | B1476: net.bytebuddy.dynamic_VisibilityBridgeStrategy.txt | C1476: hublike_modularization | D1476: class | E1476: net.bytebuddy.dynamic.VisibilityBridgeStrategy | G1476: {_x000D_ "class": "net.bytebuddy.dynamic.VisibilityBridgeStrategy",_x000D_ "detection": false,_x000D_ "justification": "The class has many incoming dependencies (13 distinct classes in the provided data reference net.bytebuddy.dynamic.VisibilityBridgeStrategy, e.g. net.bytebuddy.dynamic.DynamicType, net.bytebuddy.dynamic.DynamicType.Builder, net.bytebuddy.dynamic.scaffold.MethodRegistry, net.bytebuddy.agent.builder.AgentBuilder, net.bytebuddy.ByteBuddy, etc.), but it has only a single direct outgoing dependency: net.bytebuddy.description.method.MethodDescription. Hub-like Modularization requires an abstraction to have both a large number of incoming and a large number of outgoing dependencies. Although MethodDescription (the single outgoing target) itself has many dependencies, VisibilityBridgeStrategy directly depends on only one other abstraction, so the hub-like smell is not present."
A1477: byte-buddy | B1477: net.bytebuddy.implementation.attribute_AnnotationAppender.Default.txt | D1477: class | E1477: net.bytebuddy.implementation.attribute.AnnotationAppender.Default | F1477: 0 | G1477: The class has a low number of dependencies in isolation: outgoing dependencies = 3 (net.bytebuddy.build.HashCodeAndEqualsPlugin, net.bytebuddy.description.method.MethodDescription, net.bytebuddy.implementation.attribute.AnnotationValueFilter) and incoming dependencies = 1 (net.bytebuddy.implementation.attribute.AnnotationAppender). Hub-like Modularization requires an abstraction to have many incoming and many outgoing dependencies; this class does not exhibit high fan-in and fan-out based on the provided data.
A1478: byte-buddy | B1478: net.bytebuddy.implementation.attribute_AnnotationAppender.ForTypeAnnotations.txt | D1478: class | E1478: net.bytebuddy.implementation.attribute.AnnotationAppender.ForTypeAnnotations | F1478: 0 | G1478: The class has 0 incoming dependencies (no other abstractions depend on it) and 5 outgoing dependencies: net.bytebuddy.implementation.attribute.AnnotationAppender, net.bytebuddy.implementation.attribute.AnnotationValueFilter, net.bytebuddy.build.HashCodeAndEqualsPlugin, net.bytebuddy.description.type.TypeList, net.bytebuddy.description.type.TypeDescription. Hub-like Modularization requires an abstraction to have a large number of both incoming and outgoing dependencies; the absence of incoming dependencies (and a modest number of outgoing ones) means this class is not a hub.
A1479: byte-buddy | B1479: net.bytebuddy.implementation.attribute_AnnotationAppender.OnField.txt | D1479: class | E1479: net.bytebuddy.implementation.attribute.AnnotationAppender.OnField | F1479: 0 | G1479: The class has only one outgoing dependency (net.bytebuddy.build.HashCodeAndEqualsPlugin) and no incoming dependencies. Hub-like Modularization requires an abstraction to have both incoming and outgoing relationships with a large number of other abstractions; this class does not meet that criterion.
A1480: byte-buddy | B1480: net.bytebuddy.implementation.attribute_AnnotationAppender.OnMethod.txt | D1480: class | E1480: net.bytebuddy.implementation.attribute.AnnotationAppender.OnMethod | F1480: 0 | G1480: The class has 0 incoming dependencies and only 1 direct outgoing dependency (net.bytebuddy.build.HashCodeAndEqualsPlugin). Hub-like Modularization requires an abstraction to have many incoming and outgoing relationships. Although the single outgoing dependency (HashCodeAndEqualsPlugin) itself references many other types, those are transitive and not direct dependencies of AnnotationAppender.OnMethod in the provided data, so it does not meet the hub-like criteria.
A1481: byte-buddy | B1481: net.bytebuddy.implementation.attribute_AnnotationAppender.OnMethodParameter.txt | D1481: class | E1481: net.bytebuddy.implementation.attribute.AnnotationAppender.OnMethodParameter | F1481: 0 | G1481: The class has only one outgoing dependency (net.bytebuddy.build.HashCodeAndEqualsPlugin) and zero incoming dependencies. Hub-like Modularization requires an abstraction to have a large number of both incoming and outgoing dependencies; this class does not exhibit that (outgoing count = 1, incoming count = 0).
A1482: byte-buddy | B1482: net.bytebuddy.implementation.attribute_AnnotationAppender.OnRecordComponent.txt | D1482: class | E1482: net.bytebuddy.implementation.attribute.AnnotationAppender.OnRecordComponent | F1482: 0 | G1482: The class has 0 incoming dependencies and only 1 outgoing dependency (to net.bytebuddy.build.HashCodeAndEqualsPlugin). Hub-like Modularization requires an abstraction to have many incoming and outgoing dependencies. Although the referenced HashCodeAndEqualsPlugin lists 16 dependencies, the analyzed class itself directly depends on a single abstraction and has no incoming links, so it is not a hub.
A1483: byte-buddy | B1483: net.bytebuddy.implementation.attribute_AnnotationAppender.OnType.txt | D1483: class | E1483: net.bytebuddy.implementation.attribute.AnnotationAppender.OnType | F1483: 0 | G1483: The class has only one outgoing dependency (net.bytebuddy.build.HashCodeAndEqualsPlugin) and zero incoming dependencies. Hub-like modularization requires an abstraction to have many incoming and outgoing relationships. Although the outgoing target (net.bytebuddy.build.HashCodeAndEqualsPlugin) itself references many other types, those are indirect and do not constitute direct incoming/outgoing dependencies for this class.
A1484: byte-buddy | B1484: net.bytebuddy.implementation.attribute_AnnotationAppender.Target.txt | D1484: class | E1484: net.bytebuddy.implementation.attribute.AnnotationAppender.Target | F1484: 0 | G1484: The class has a very small number of direct relationships: a single incoming dependency from net.bytebuddy.implementation.attribute.AnnotationAppender and a single outgoing dependency to net.bytebuddy.build.HashCodeAndEqualsPlugin. Hub-like Modularization requires an abstraction to have many incoming and outgoing dependencies. Although net.bytebuddy.build.HashCodeAndEqualsPlugin (the single outgoing target) itself references many other types, the analyzed class's direct incoming/outgoing degree is low (1 incoming, 1 outgoing), so it does not qualify as a hub.
A1485: byte-buddy | B1485: net.bytebuddy.implementation.attribute_AnnotationAppender.txt | D1485: class | E1485: net.bytebuddy.implementation.attribute.AnnotationAppender | F1485: 1 | G1485: AnnotationAppender has a large number of incoming and outgoing relationships. Incoming: at least 23 distinct classes depend on it (examples include net.bytebuddy.dynamic.scaffold.TypeWriter, TypeWriter.Record, TypeWriter.MethodPool, TypeWriter.ForDefinedMethod, TypeWriter.WithAnnotationDefaultValue, net.bytebuddy.implementation.attribute.TypeAttributeAppender, FieldAttributeAppender, MethodAttributeAppender, RecordComponentAttributeAppender and many of their nested/variant classes). Outgoing: AnnotationAppender depends on at least 8 other abstractions (net.bytebuddy.description.annotation.AnnotationDescription; net.bytebuddy.implementation.attribute.AnnotationAppender.Default; net.bytebuddy.description.method.MethodDescription; net.bytebuddy.implementation.attribute.AnnotationValueFilter; net.bytebuddy.implementation.attribute.AnnotationAppender.Target; net.bytebuddy.build.HashCodeAndEqualsPlugin; net.bytebuddy.description.type.TypeList; net.bytebuddy.description.type.TypeDescription). The combination of many distinct incoming dependents and multiple outgoing dependencies identifies AnnotationAppender as a hub-like module.
A1486: byte-buddy | B1486: net.bytebuddy.implementation.attribute_AnnotationRetention.txt | D1486: class | E1486: net.bytebuddy.implementation.attribute.AnnotationRetention | F1486: 0 | G1486: AnnotationRetention has many incoming dependencies (12 distinct incoming references: net.bytebuddy.dynamic.DynamicType; net.bytebuddy.dynamic.DynamicType.Builder; net.bytebuddy.dynamic.DynamicType.AbstractBase; net.bytebuddy.dynamic.DynamicType.Adapter; net.bytebuddy.dynamic.scaffold.TypeWriter; net.bytebuddy.dynamic.scaffold.TypeWriter.Default; net.bytebuddy.dynamic.scaffold.subclass.SubclassDynamicTypeBuilder; net.bytebuddy.dynamic.scaffold.inline.RebaseDynamicTypeBuilder; net.bytebuddy.dynamic.scaffold.inline.AbstractInliningDynamicTypeBuilder; net.bytebuddy.dynamic.scaffold.inline.RedefinitionDynamicTypeBuilder; net.bytebuddy.dynamic.scaffold.inline.DecoratingDynamicTypeBuilder; net.bytebuddy.ByteBuddy), but it has zero outgoing dependencies (outgoing_dependencies is empty). Hub-like Modularization requires an abstraction to have both a large number of incoming and outgoing dependencies; since outgoing dependencies = 0, the smell is not detected.
A1487: byte-buddy | B1487: net.bytebuddy.implementation.attribute_AnnotationValueFilter.Default.txt | D1487: class | E1487: net.bytebuddy.implementation.attribute.AnnotationValueFilter.Default | F1487: 0 | G1487: The class has 1 outgoing dependency (net.bytebuddy.description.method.MethodDescription) and 0 incoming dependencies. Hub-like Modularization requires an abstraction to have many incoming and outgoing dependencies; here the provided data shows only a single outgoing dependency and no incoming dependencies, so the smell is not detected.
A1488: byte-buddy | B1488: net.bytebuddy.implementation.attribute_AnnotationValueFilter.Factory.txt | D1488: class | E1488: net.bytebuddy.implementation.attribute.AnnotationValueFilter.Factory | F1488: 0 | G1488: The class has 0 outgoing dependencies and 0 incoming dependencies (both dependency lists are empty), so it does not have numerous incoming and outgoing relationships required to be classified as Hub-like Modularization.
... A1526: byte-buddy | B1526: net.bytebuddy.implementation.auxiliary_MethodCallProxy.MethodCall.txt | D1526: class | E1526: net.bytebuddy.implementation.auxiliary.MethodCallProxy.MethodCall | F1526: 0 | G1526: The class has a small set of direct outgoing dependencies (5: net.bytebuddy.implementation.bytecode.assign.Assigner, net.bytebuddy.description.method.MethodDescription, net.bytebuddy.implementation.bytecode.StackManipulation, net.bytebuddy.build.HashCodeAndEqualsPlugin, net.bytebuddy.description.type.TypeDescription) and only one incoming dependency recorded (net.bytebuddy.implementation.auxiliary.MethodCallProxy). Because the number of distinct incoming and outgoing relationships is low, it does not exhibit the hub-like modularization smell (which requires dependencies with a large number of other abstractions).
A1527: byte-buddy | B1527: net.bytebuddy.implementation.auxiliary_MethodCallProxy.PrecomputedMethodGraph.txt | C1527: hublike_modularization | D1527: class | E1527: net.bytebuddy.implementation.auxiliary.MethodCallProxy.PrecomputedMethodGraph | G1527: {_x000D_ "class": "net.bytebuddy.implementation.auxiliary.MethodCallProxy.PrecomputedMethodGraph",_x000D_ "detection": false,_x000D_ "justification": "Direct outgoing dependencies: 5 (net.bytebuddy.dynamic.scaffold.MethodGraph, net.bytebuddy.description.method.MethodDescription, net.bytebuddy.description.method.ParameterDescription, net.bytebuddy.description.type.TypeDescription, net.bytebuddy.description.annotation.AnnotationValue). Direct incoming dependencies: 1 (net.bytebuddy.implementation.auxiliary.MethodCallProxy). Hub-like modularization requires an abstraction to have a large number of both incoming and outgoing links. Although some of the outgoing target types themselves have many internal dependencies, the analyzed class has a small set of direct outgoing dependencies (5) and only a single incoming dependent, so it does not meet the criterion for a hub."
A1528: byte-buddy | B1528: net.bytebuddy.implementation.auxiliary_MethodCallProxy.txt | D1528: class | E1528: net.bytebuddy.implementation.auxiliary.MethodCallProxy | F1528: 0 | G1528: Hub-like modularization requires an abstraction to have a large number of both incoming and outgoing dependencies. MethodCallProxy has a large number of outgoing dependencies (21 distinct referenced abstractions such as net.bytebuddy.dynamic.scaffold.TypeValidation, net.bytebuddy.implementation.Implementation, net.bytebuddy.description.type.TypeDescription, net.bytebuddy.ByteBuddy, net.bytebuddy.dynamic.DynamicType, etc.). However, it has only a single incoming dependency recorded (net.bytebuddy.implementation.bind.annotation.Binder). Because the class does not exhibit a large number of incoming dependencies, it does not meet the definition of a hub-like module.
A1529: byte-buddy | B1529: net.bytebuddy.implementation.auxiliary_PrivilegedMemberLookupAction.txt | D1529: class | E1529: net.bytebuddy.implementation.auxiliary.PrivilegedMemberLookupAction | F1529: 0 | G1529: PrivilegedMemberLookupAction has a significant number of outgoing dependencies (13 outgoing: net.bytebuddy.dynamic.scaffold.TypeValidation, net.bytebuddy.implementation.MethodAccessorFactory, net.bytebuddy.implementation.FieldAccessor, net.bytebuddy.description.modifier.Visibility, net.bytebuddy.description.method.MethodDescription, net.bytebuddy.matcher.ElementMatchers, net.bytebuddy.ClassFileVersion, net.bytebuddy.dynamic.DynamicType, net.bytebuddy.implementation.auxiliary.AuxiliaryType, net.bytebuddy.ByteBuddy, net.bytebuddy.dynamic.scaffold.subclass.ConstructorStrategy, net.bytebuddy.implementation.Implementation, net.bytebuddy.description.type.TypeDescription) but zero incoming dependencies (incoming_dependencies is empty). Hub-like Modularization requires both many incoming and many outgoing relationships. Because this class lacks incoming dependencies, it does not meet the definition of a hub-like module.
A1530: byte-buddy | B1530: net.bytebuddy.implementation.auxiliary_TrivialType.txt | D1530: class | E1530: net.bytebuddy.implementation.auxiliary.TrivialType | F1530: 0 | G1530: TrivialType has outgoing dependencies to 7 distinct abstractions (AnnotationDescription, TypeValidation, MethodGraph, MethodAccessorFactory, ClassFileVersion, DynamicType, ConstructorStrategy) and only 2 incoming dependents (net.bytebuddy.dynamic.scaffold.inline.MethodRebaseResolver and MethodRebaseResolver.Default). The smell 'Hub-like Modularization' requires an abstraction to have dependencies both incoming and outgoing with a large number of other abstractions; the provided data shows a moderate number of outgoing links and very few incoming links, so it does not qualify as a hub in isolation.
A1531: byte-buddy | B1531: net.bytebuddy.implementation.auxiliary_TypeProxy.AbstractMethodErrorThrow.txt | D1531: class | E1531: net.bytebuddy.implementation.auxiliary.TypeProxy.AbstractMethodErrorThrow | F1531: 0 | G1531: The class has only 1 incoming dependency (net.bytebuddy.implementation.auxiliary.TypeProxy) and 5 outgoing dependencies (net.bytebuddy.implementation.bytecode.Throw, net.bytebuddy.implementation.bytecode.StackManipulation, net.bytebuddy.implementation.Implementation, net.bytebuddy.description.type.TypeDescription, net.bytebuddy.implementation.bytecode.Duplication). Hub-like modularization requires an abstraction to have many incoming and many outgoing dependencies; this class does not exhibit a large number of both.
A1532: byte-buddy | B1532: net.bytebuddy.implementation.auxiliary_TypeProxy.AccessorMethodInvocation.txt | D1532: class | E1532: net.bytebuddy.implementation.auxiliary.TypeProxy.AccessorMethodInvocation | F1532: 0 | G1532: The class has outgoing dependencies to five abstractions (net.bytebuddy.implementation.MethodAccessorFactory, net.bytebuddy.description.method.MethodDescription, net.bytebuddy.implementation.bytecode.StackManipulation, net.bytebuddy.build.HashCodeAndEqualsPlugin, net.bytebuddy.implementation.Implementation) but has no incoming dependencies (incoming_dependencies is empty). Hub-like Modularization requires an abstraction to have both a large number of incoming and outgoing dependencies; the absence of incoming dependencies prevents this class from being a hub.
A1533: byte-buddy | B1533: net.bytebuddy.implementation.auxiliary_TypeProxy.Appender.txt | D1533: class | E1533: net.bytebuddy.implementation.auxiliary.TypeProxy.Appender | F1533: 0 | G1533: The class has outgoing dependencies to six abstractions (net.bytebuddy.implementation.MethodAccessorFactory, net.bytebuddy.description.method.MethodDescription, net.bytebuddy.implementation.bytecode.StackManipulation, net.bytebuddy.build.HashCodeAndEqualsPlugin, net.bytebuddy.implementation.Implementation, net.bytebuddy.description.type.TypeDescription) but has zero incoming dependencies. Hub-like Modularization requires an abstraction to have dependencies both incoming and outgoing with a large number of other abstractions. Because there are no incoming dependencies, the class does not meet the bidirectional connectivity criterion for this smell.
A1534: byte-buddy | B1534: net.bytebuddy.implementation.auxiliary_TypeProxy.Default.txt | D1534: class | E1534: net.bytebuddy.implementation.auxiliary.TypeProxy.Default | F1534: 0 | G1534: The class has only a single outgoing dependency (net.bytebuddy.implementation.Implementation) and a single incoming dependency (referenced by net.bytebuddy.implementation.auxiliary.TypeProxy). Hub-like Modularization requires an abstraction to have dependencies (both incoming and outgoing) with a large number of other abstractions; this class does not exhibit many incoming or outgoing relationships.
A1535: byte-buddy | B1535: net.bytebuddy.implementation.auxiliary_TypeProxy.ForDefaultMethod.txt | D1535: class | E1535: net.bytebuddy.implementation.auxiliary.TypeProxy.ForDefaultMethod | F1535: 0 | G1535: The class has outgoing dependencies to 5 abstractions (net.bytebuddy.implementation.bytecode.StackManipulation, net.bytebuddy.build.HashCodeAndEqualsPlugin, net.bytebuddy.implementation.Implementation, net.bytebuddy.description.type.TypeDescription, net.bytebuddy.implementation.bytecode.Duplication) but has no incoming dependencies (incoming_dependencies is empty). Hub-like Modularization requires an abstraction to have a large number of both incoming and outgoing dependencies; this class lacks incoming dependencies and thus does not meet the smell's criteria.
A1536: byte-buddy | B1536: net.bytebuddy.implementation.auxiliary_TypeProxy.ForSuperMethodByConstructor.txt | D1536: class | E1536: net.bytebuddy.implementation.auxiliary.TypeProxy.ForSuperMethodByConstructor | F1536: 0 | G1536: Incoming dependencies: none (incoming_dependencies is empty). Outgoing dependencies: 6 distinct abstractions (net.bytebuddy.description.method.MethodDescription, net.bytebuddy.implementation.bytecode.StackManipulation, net.bytebuddy.build.HashCodeAndEqualsPlugin, net.bytebuddy.implementation.Implementation, net.bytebuddy.description.type.TypeDescription, net.bytebuddy.implementation.bytecode.Duplication). Hub-like Modularization requires an abstraction to have many incoming and outgoing dependencies; this class has no incoming dependencies and only a moderate number (6) of outgoing dependencies, so it is not a hub.
A1537: byte-buddy | B1537: net.bytebuddy.implementation.auxiliary_TypeProxy.ForSuperMethodByReflectionFactory.txt | D1537: class | E1537: net.bytebuddy.implementation.auxiliary.TypeProxy.ForSuperMethodByReflectionFactory | F1537: 0 | G1537: Not detected: Hub-like Modularization requires an abstraction to have both many incoming and many outgoing dependencies. This class has 5 outgoing dependencies (net.bytebuddy.implementation.bytecode.StackManipulation, net.bytebuddy.build.HashCodeAndEqualsPlugin, net.bytebuddy.implementation.Implementation, net.bytebuddy.description.type.TypeDescription, net.bytebuddy.implementation.bytecode.Duplication) but 0 incoming dependencies, so it does not meet the hub-like criteria.
A1538: byte-buddy | B1538: net.bytebuddy.implementation.auxiliary_TypeProxy.InvocationFactory.txt | D1538: class | E1538: net.bytebuddy.implementation.auxiliary.TypeProxy.InvocationFactory | F1538: 0 | G1538: InvocationFactory has only 1 outgoing dependency (net.bytebuddy.implementation.Implementation) and 1 incoming dependency (net.bytebuddy.implementation.auxiliary.TypeProxy) according to the provided data. Hub-like Modularization requires an abstraction to have many incoming and outgoing dependencies; those large numbers are not present here. Although the referenced Implementation class has many dependencies, those are not direct incoming/outgoing links for InvocationFactory in the given context, and the analysis is constrained to the provided dependencies only.
...

Sheet deepseek
A1: project | B1: file_name | C1: smell | D1: entity_type | E1: entity | F1: detection | G1: justification
A2: byte-buddy | B2: (default package)_MavenWrapperDownloader.txt | D2: class | E2: (default package).MavenWrapperDownloader | F2: 0 | G2: The class has zero outgoing dependencies and zero incoming dependencies. It does not have dependencies with a large number of other abstractions.
A3: byte-buddy | B3: com.service.definition_ServiceDefinition.txt | D3: class | E3: com.service.definition.ServiceDefinition | F3: 0 | G3: The class has zero outgoing dependencies and zero incoming dependencies. It does not have dependencies with a large number of other abstractions.
A4: byte-buddy | B4: com.service.usage2_ServiceImplementation.txt | D4: class | E4: com.service.usage2.ServiceImplementation | F4: 0 | G4: The class has zero outgoing dependencies and zero incoming dependencies. It does not have dependencies with a large number of other abstractions.
A5: byte-buddy | B5: com.service.usage_ServiceImplementation.txt | D5: class | E5: com.service.usage.ServiceImplementation | F5: 0 | G5: The class has zero incoming dependencies and zero outgoing dependencies, which does not indicate a large number of dependencies with other abstractions.
A6: byte-buddy | B6: net.bytebuddy.agent.builder_AgentBuilder.Adapter.txt | D6: class | E6: net.bytebuddy.agent.builder.AgentBuilder.Adapter | F6: 0 | G6: The class has only one outgoing dependency and zero incoming dependencies, which does not constitute a large number of dependencies in either direction.
A7: byte-buddy | B7: net.bytebuddy.agent.builder_AgentBuilder.Appender.txt | D7: class | E7: net.bytebuddy.agent.builder.AgentBuilder.Appender | F7: 0 | G7: The class has 9 outgoing dependencies, which is not a large number. It has 0 incoming dependencies. The total number of distinct dependencies (incoming + outgoing) is 9, which does not indicate a hub-like abstraction.
A8: byte-buddy | B8: net.bytebuddy.agent.builder_AgentBuilder.Asynchronous.txt | D8: class | E8: net.bytebuddy.agent.builder.AgentBuilder.Asynchronous | F8: 0 | G8: The class has only 2 outgoing dependencies and 0 incoming dependencies, which is not a large number of dependencies in either direction.
A9: byte-buddy | B9: net.bytebuddy.agent.builder_AgentBuilder.AtFixedRate.txt | D9: class | E9: net.bytebuddy.agent.builder.AgentBuilder.AtFixedRate | F9: 0 | G9: The analyzed class has only one outgoing dependency and zero incoming dependencies, which does not constitute a large number of dependencies in either direction.
A10: byte-buddy | B10: net.bytebuddy.agent.builder_AgentBuilder.BatchAllocator.txt | D10: class | E10: net.bytebuddy.agent.builder.AgentBuilder.BatchAllocator | F10: 0 | G10: The class has only 3 outgoing dependencies and 1 incoming dependency, which is not a large number of dependencies in either direction.
A11: byte-buddy | B11: net.bytebuddy.agent.builder_AgentBuilder.BatchReallocator.txt | D11: class | E11: net.bytebuddy.agent.builder.AgentBuilder.BatchReallocator | F11: 0 | G11: The class has only one outgoing dependency and zero incoming dependencies, which does not constitute a large number of dependencies in either direction.
A12: byte-buddy | B12: net.bytebuddy.agent.builder_AgentBuilder.BootstrapMarkerAction.txt | D12: class | E12: net.bytebuddy.agent.builder.AgentBuilder.BootstrapMarkerAction | F12: 0 | G12: The analyzed class has only one outgoing dependency (ClassLoadingStrategy) and one incoming dependency (AgentBuilder). This does not constitute a large number of dependencies in either direction, which is required for Hub-like Modularization.
A13: byte-buddy | B13: net.bytebuddy.agent.builder_AgentBuilder.BridgeMethodImplementation.txt | D13: class | E13: net.bytebuddy.agent.builder.AgentBuilder.BridgeMethodImplementation | F13: 0 | G13: The class has only 4 outgoing dependencies and 0 incoming dependencies. This does not constitute a large number of dependencies in either direction, which is required for Hub-like Modularization.
... A5412: zxing | B5412: com.google.zxing_WriterException.txt | D5412: class | E5412: com.google.zxing.WriterException | F5412: 0 | G5412: The class has 0 outgoing dependencies and only 2 incoming dependencies, which is not a large number of dependencies in either direction.

Sheet qwen
A1: project | B1: file_name | C1: smell | D1: entity_type | E1: entity | F1: detection | G1: justification
A2: byte-buddy | B2: (default package)_MavenWrapperDownloader.txt | D2: class | E2: (default package).MavenWrapperDownloader | F2: 0 | G2: The class has no outgoing dependencies and no incoming dependencies, therefore it does not exhibit hub-like modularization as it is not connected to any other abstractions in the system.
A3: byte-buddy | B3: com.service.definition_ServiceDefinition.txt | D3: class | E3: com.service.definition.ServiceDefinition | F3: 0 | G3: The class has no outgoing dependencies and no incoming dependencies, therefore it does not exhibit hub-like modularization as it is not connected to any other abstractions in the system.
A4: byte-buddy | B4: com.service.usage2_ServiceImplementation.txt | D4: class | E4: com.service.usage2.ServiceImplementation | F4: 0 | G4: The class has no outgoing dependencies and no incoming dependencies, therefore it does not exhibit hub-like modularization as it is not connected to any other abstractions in the system.
A5: byte-buddy | B5: com.service.usage_ServiceImplementation.txt | C5: hublike_modularization | D5: class | E5: com.service.usage.ServiceImplementation
A6: byte-buddy | B6: net.bytebuddy.agent.builder_AgentBuilder.Adapter.txt | D6: class | E6: net.bytebuddy.agent.builder.AgentBuilder.Adapter | F6: 0 | G6: The class has only one outgoing dependency to 'net.bytebuddy.build.HashCodeAndEqualsPlugin' and no incoming dependencies. The number of dependencies is low and does not indicate hub-like modularization.
A7: byte-buddy | B7: net.bytebuddy.agent.builder_AgentBuilder.Appender.txt | D7: class | E7: net.bytebuddy.agent.builder.AgentBuilder.Appender | F7: 1 | G7: The class 'AgentBuilder.Appender' has outgoing dependencies to 9 distinct classes across multiple packages. The dependencies include 'FieldDescription', 'JavaConstant', 'MethodReturn', 'StackManipulation', 'MethodDescription', 'Assigner', 'TypeDescription', 'Duplication', and 'HashCodeAndEqualsPlugin'. This wide range of dependencies indicates that the class interacts with a large number of other abstractions, which is characteristic of Hub-like Modularization.
A8: byte-buddy | B8: net.bytebuddy.agent.builder_AgentBuilder.Asynchronous.txt | D8: class | E8: net.bytebuddy.agent.builder.AgentBuilder.Asynchronous | F8: 0 | G8: The class 'AgentBuilder.Asynchronous' has only two outgoing dependencies ('TypeDescription' and 'HashCodeAndEqualsPlugin') and no incoming dependencies. The number of dependencies is relatively low, and there is no evidence of it acting as a hub with numerous connections to other abstractions in the provided data.
A9: byte-buddy | B9: net.bytebuddy.agent.builder_AgentBuilder.AtFixedRate.txt | D9: class | E9: net.bytebuddy.agent.builder.AgentBuilder.AtFixedRate | F9: 0 | G9: The class has only one outgoing dependency to 'net.bytebuddy.build.HashCodeAndEqualsPlugin' and no incoming dependencies. The number of dependencies is limited and does not indicate hub-like modularization.
A10: byte-buddy | B10: net.bytebuddy.agent.builder_AgentBuilder.BatchAllocator.txt | D10: class | E10: net.bytebuddy.agent.builder.AgentBuilder.BatchAllocator | F10: 0 | G10: The class 'AgentBuilder.BatchAllocator' has a limited number of outgoing dependencies (3) and incoming dependencies (1). The outgoing dependencies are to 'TypeDescription', 'HashCodeAndEqualsPlugin', and 'SafeVarargsPlugin', which are specific and focused. The incoming dependencies come solely from 'AgentBuilder', which is expected given its role as a nested class. There is no evidence of excessive or widespread dependencies that would indicate hub-like modularization.
A11: byte-buddy | B11: net.bytebuddy.agent.builder_AgentBuilder.BatchReallocator.txt | D11: class | E11: net.bytebuddy.agent.builder.AgentBuilder.BatchReallocator | F11: 0 | G11: The class has only one outgoing dependency to net.bytebuddy.build.HashCodeAndEqualsPlugin and no incoming dependencies. The number of dependencies is limited and does not indicate hub-like modularization.
A12: byte-buddy | B12: net.bytebuddy.agent.builder_AgentBuilder.BootstrapMarkerAction.txt | D12: class | E12: net.bytebuddy.agent.builder.AgentBuilder.BootstrapMarkerAction | F12: 0 | G12: The class 'AgentBuilder.BootstrapMarkerAction' has only one outgoing dependency to 'net.bytebuddy.dynamic.loading.ClassLoadingStrategy' and one incoming dependency from 'net.bytebuddy.agent.builder.AgentBuilder'. The number of dependencies is relatively low, and it does not exhibit hub-like modularization where a class has dependencies with a large number of other abstractions.
A13: byte-buddy | B13: net.bytebuddy.agent.builder_AgentBuilder.BridgeMethodImplementation.txt | D13: class | E13: net.bytebuddy.agent.builder.AgentBuilder.BridgeMethodImplementation | F13: 0 | G13: The class has only 4 outgoing dependencies and no incoming dependencies. The outgoing dependencies are to JavaConstant, HashCodeAndEqualsPlugin, StackManipulation, and MethodDescription. While some of these dependencies have extensive dependency lists themselves, the analyzed class does not directly depend on a large number of abstractions, nor does it have a high number of incoming dependencies, which would be indicative of Hub-like Modularization.
A14: byte-buddy | B14: net.bytebuddy.agent.builder_AgentBuilder.ByThrowableType.txt | D14: class | E14: net.bytebuddy.agent.builder.AgentBuilder.ByThrowableType | F14: 0 | G14: The class has only 2 outgoing dependencies and no incoming dependencies. The outgoing dependencies themselves have multiple dependencies, but the class in question does not directly depend on a large number of abstractions nor is it depended upon by many other abstractions.
A15: byte-buddy | B15: net.bytebuddy.agent.builder_AgentBuilder.Cancelable.txt | D15: class | E15: net.bytebuddy.agent.builder.AgentBuilder.Cancelable | F15: 0 | G15: The class 'AgentBuilder.Cancelable' has only one outgoing dependency to 'HashCodeAndEqualsPlugin' and is listed as a dependency in the incoming dependencies of 'AgentBuilder'. The number of dependencies is not excessively high, and there is no evidence of it being a hub with numerous connections to other abstractions.
A16: byte-buddy | B16: net.bytebuddy.agent.builder_AgentBuilder.CircularityLock.txt | D16: class | E16: net.bytebuddy.agent.builder.AgentBuilder.CircularityLock | F16: 0 | G16: The class 'AgentBuilder.CircularityLock' has only one outgoing dependency to 'HashCodeAndEqualsPlugin' and one incoming dependency from 'AgentBuilder'. The number of dependencies is relatively low, and there is no evidence of excessive incoming or outgoing connections that would indicate hub-like modularization.
A17: byte-buddy | B17: net.bytebuddy.agent.builder_AgentBuilder.ClassFileBufferStrategy.txt | D17: class | E17: net.bytebuddy.agent.builder.AgentBuilder.ClassFileBufferStrategy | F17: 1 | G17: The class 'AgentBuilder.ClassFileBufferStrategy' has a high number of incoming dependencies from 'AgentBuilder' (60+ dependencies listed) and outgoing dependencies to 'ClassFileLocator' (18 dependencies listed), indicating hub-like modularization where this abstraction acts as a central point connecting numerous other abstractions.
... A210: byte-buddy | B210: net.bytebuddy.agent_VirtualMachine.Factory.txt | D210: class | E210: net.bytebuddy.agent.VirtualMachine.Factory | F210: 0 | G210: The class has no outgoing dependencies and only one incoming dependency from VirtualMachine class. The incoming dependency shows VirtualMachine depends on multiple classes including this one, but this Factory class itself does not have dependencies with a large number of other abstractions. It appears to be a simple factory class with limited coupling.
A211: byte-buddy | B211: net.bytebuddy.agent_VirtualMachine.ForHotSpot.txt | C211: hublike_modularization | D211: class | E211: net.bytebuddy.agent.VirtualMachine.ForHotSpot
A212: byte-buddy | B212: net.bytebuddy.agent_VirtualMachine.ForJnaPosixEnvironment.txt | D212: class | E212: net.bytebuddy.agent.VirtualMachine.ForJnaPosixEnvironment | F212: 0 | G212: The class has no outgoing dependencies and no incoming dependencies, therefore it does not exhibit hub-like modularization as it has no dependencies with other abstractions.
A213: byte-buddy | B213: net.bytebuddy.agent_VirtualMachine.ForJnaPosixSocket.txt | D213: class | E213: net.bytebuddy.agent.VirtualMachine.ForJnaPosixSocket | F213: 0 | G213: The class has no outgoing dependencies and only one incoming dependency from VirtualMachine class. The incoming dependency shows VirtualMachine depends on multiple classes including this one, but this specific class does not exhibit hub-like behavior as it has minimal connections (0 outgoing, 1 incoming source). Hub-like modularization requires both high incoming and outgoing dependencies.
A214: byte-buddy | B214: net.bytebuddy.agent_VirtualMachine.ForJnaSolarisDoor.txt | D214: class | E214: net.bytebuddy.agent.VirtualMachine.ForJnaSolarisDoor | F214: 0 | G214: The class has no outgoing dependencies and only one incoming dependency from VirtualMachine class. The incoming dependency shows VirtualMachine class depends on this class along with 11 other VirtualMachine inner classes and implementations, but this does not indicate hub-like modularization for this specific class as it has minimal dependencies itself.
A215: byte-buddy | B215: net.bytebuddy.agent_VirtualMachine.ForJnaWindowsEnvironment.txt | D215: class | E215: net.bytebuddy.agent.VirtualMachine.ForJnaWindowsEnvironment | F215: 0 | G215: No dependencies found. The class has neither outgoing dependencies nor incoming dependencies, therefore it cannot be hub-like.
A216: byte-buddy | B216: net.bytebuddy.agent_VirtualMachine.ForJnaWindowsNamedPipe.txt | D216: class | E216: net.bytebuddy.agent.VirtualMachine.ForJnaWindowsNamedPipe | F216: 0 | G216: The class has no outgoing dependencies and only one incoming dependency from VirtualMachine class. The incoming dependency shows that VirtualMachine depends on this class along with other VirtualMachine inner classes and implementations, but this does not indicate hub-like modularization for this specific class. Hub-like modularization requires the class itself to have dependencies with a large number of other abstractions, which is not the case here.
A217: byte-buddy | B217: net.bytebuddy.agent_VirtualMachine.ForOpenJ9.txt | D217: class | E217: net.bytebuddy.agent.VirtualMachine.ForOpenJ9 | F217: 0 | G217: The class has no outgoing dependencies and no incoming dependencies, therefore it does not exhibit hub-like modularization as it has no dependencies with other abstractions.
A218: byte-buddy | B218: net.bytebuddy.agent_VirtualMachine.ForSocketFile.txt | D218: class | E218: net.bytebuddy.agent.VirtualMachine.ForSocketFile | F218: 0 | G218: The class has no outgoing dependencies and no incoming dependencies, therefore it does not exhibit hub-like modularization as it has no dependencies with other abstractions.
A219: byte-buddy | B219: net.bytebuddy.agent_VirtualMachine.MacLibrary.txt | D219: class | E219: net.bytebuddy.agent.VirtualMachine.MacLibrary | F219: 0 | G219: The class has no outgoing dependencies and only one incoming dependency from VirtualMachine class. The incoming dependency shows VirtualMachine depends on multiple libraries including MacLibrary, but this represents a typical dependency structure where a factory/manager class depends on several implementation classes, not hub-like modularization where the class itself would have many dependencies.
A220: byte-buddy | B220: net.bytebuddy.agent_VirtualMachine.NamedPipeResponse.txt | D220: class | E220: net.bytebuddy.agent.VirtualMachine.NamedPipeResponse | F220: 0 | G220: The class has no outgoing dependencies and no incoming dependencies, therefore it does not exhibit hub-like modularization as it has no dependencies with other abstractions.
A221: byte-buddy | B221: net.bytebuddy.agent_VirtualMachine.OnPersistentByteChannel.txt | D221: class | E221: net.bytebuddy.agent.VirtualMachine.OnPersistentByteChannel | F221: 0 | G221: The class has no outgoing dependencies and no incoming dependencies, therefore it does not exhibit hub-like modularization as it has no dependencies with other abstractions.
A222: byte-buddy | B222: net.bytebuddy.agent_VirtualMachine.PosixLibrary.txt | D222: class | E222: net.bytebuddy.agent.VirtualMachine.PosixLibrary | F222: 0 | G222: The class has no outgoing dependencies and only one incoming dependency from VirtualMachine class. The incoming dependency shows that VirtualMachine depends on multiple classes including this one, but this class itself does not have dependencies with a large number of other abstractions. The class appears to be a simple library class with minimal coupling.
A223: byte-buddy | B223: net.bytebuddy.agent_VirtualMachine.PosixOwnerProvider.txt | D223: class | E223: net.bytebuddy.agent.VirtualMachine.PosixOwnerProvider | F223: 0 | G223: The class has no outgoing dependencies and only one incoming dependency from VirtualMachine class. The incoming dependency shows that VirtualMachine depends on multiple classes including this one, but this class itself does not exhibit hub-like behavior with numerous dependencies. It appears to be a simple provider class with minimal coupling.
... A510: byte-buddy | B510: net.bytebuddy.benchmark.jmh_generated_ClassByExtensionBenchmark_benchmarkByteBuddyWithPrefixAndReusedDelegator_jmhTest.txt | D510: class | E510: net.bytebuddy.benchmark.jmh.generated.ClassByExtensionBenchmark.benchmarkByteBuddyWithPrefixAndReusedDelegator.jmhTest | F510: 0 | G510: The class has only one outgoing dependency to ClassByExtensionBenchmark_jmhType and no incoming dependencies, which does not constitute a hub-like modularization pattern where there would be dependencies with a large number of other abstractions.
A511: byte-buddy | B511: net.bytebuddy.benchmark.jmh_generated_ClassByExtensionBenchmark_benchmarkByteBuddyWithPrefixWithTypePool_jmhTest.txt | C511: hublike_modularization | D511: class | E511: net.bytebuddy.benchmark.jmh.generated.ClassByExtensionBenchmark.benchmarkByteBuddyWithPrefixWithTypePool.jmhTest
A512: byte-buddy | B512: net.bytebuddy.benchmark.jmh_generated_ClassByExtensionBenchmark_benchmarkByteBuddyWithPrefix_jmhTest.txt | D512: class | E512: net.bytebuddy.benchmark.jmh.generated.ClassByExtensionBenchmark.benchmarkByteBuddyWithPrefix.jmhTest | F512: 0 | G512: The class has only one outgoing dependency to ClassByExtensionBenchmark_jmhType and no incoming dependencies. The low number of dependencies (both incoming and outgoing) indicates this is not a hub-like abstraction.
A513: byte-buddy | B513: net.bytebuddy.benchmark.jmh_generated_ClassByExtensionBenchmark_benchmarkByteBuddyWithProxyAndReusedDelegatorWithTypePool_jmhTest.txt | D513: class | E513: net.bytebuddy.benchmark.jmh.generated.ClassByExtensionBenchmark.benchmarkByteBuddyWithProxyAndReusedDelegatorWithTypePool.jmhTest | F513: 0 | G513: The class has only one outgoing dependency to ClassByExtensionBenchmark_jmhType and no incoming dependencies. The low number of dependencies (both incoming and outgoing) indicates this is not a hub-like modularization smell.
A514: byte-buddy | B514: net.bytebuddy.benchmark.jmh_generated_ClassByExtensionBenchmark_benchmarkByteBuddyWithProxyAndReusedDelegator_jmhTest.txt | D514: class | E514: net.bytebuddy.benchmark.jmh.generated.ClassByExtensionBenchmark.benchmarkByteBuddyWithProxyAndReusedDelegator.jmhTest | F514: 0 | G514: The class has only one outgoing dependency to ClassByExtensionBenchmark_jmhType and no incoming dependencies, which does not constitute a hub-like modularization pattern where there would be dependencies with a large number of other abstractions.
A515: byte-buddy | B515: net.bytebuddy.benchmark.jmh_generated_ClassByExtensionBenchmark_benchmarkByteBuddyWithProxyWithTypePool_jmhTest.txt | D515: class | E515: net.bytebuddy.benchmark.jmh.generated.ClassByExtensionBenchmark.benchmarkByteBuddyWithProxyWithTypePool.jmhTest | F515: 0 | G515: The class has only one outgoing dependency to ClassByExtensionBenchmark_jmhType and no incoming dependencies. The low number of dependencies (1 outgoing, 0 incoming) does not indicate hub-like modularization, which requires dependencies with a large number of other abstractions.
A516: byte-buddy | B516: net.bytebuddy.benchmark.jmh_generated_ClassByExtensionBenchmark_benchmarkByteBuddyWithProxy_jmhTest.txt | D516: class | E516: net.bytebuddy.benchmark.jmh.generated.ClassByExtensionBenchmark.benchmarkByteBuddyWithProxy.jmhTest | F516: 0 | G516: The class has only one outgoing dependency to ClassByExtensionBenchmark_jmhType and no incoming dependencies. The low number of dependencies (both incoming and outgoing) does not indicate hub-like modularization, as it does not connect to a large number of other abstractions.
A517: byte-buddy | B517: net.bytebuddy.benchmark.jmh_generated_ClassByExtensionBenchmark_benchmarkCglib_jmhTest.txt | D517: class | E517: net.bytebuddy.benchmark.jmh.generated.ClassByExtensionBenchmark.benchmarkCglib.jmhTest | F517: 0 | G517: The class has only 1 outgoing dependency to ClassByExtensionBenchmark_jmhType and no incoming dependencies. The low number of dependencies (both incoming and outgoing) does not indicate hub-like modularization, as it is not acting as a central hub connecting to a large number of other abstractions.
