Workbook

Sheet samples
A1: project | B1: smell | C1: package | D1: class | E1: fqn | F1: prompt_file | G1: context_size | H1: designite | I1: gpt | J1: deepseek | K1: qwen
A2: javaparser | B2: Insufficient Modularization | C2: com.github.javaparser.symbolsolver.javaparsermodel.contexts | D2: AnonymousClassDeclarationContext | E2: =C2&"."&D2 -> com.github.javaparser.symbolsolver.javaparsermodel.contexts.AnonymousClassDeclarationContext | F2: data/processed/prompts/insufficient_modularization/javaparser/com_github_javaparser_symbolsolver_javaparsermodel_contexts_AnonymousClassDeclarationContext.txt | G2: 495 | H2: 0 | I2: =VLOOKUP(E2,gpt!E2:F5422,2,0) -> 1 | J2: =VLOOKUP(E2,deepseek!E2:F5422,2,0) -> 0 | K2: =VLOOKUP(E2,qwen!E2:F5422,2,0) -> 0
A3: byte-buddy | B3: Insufficient Modularization | C3: net.bytebuddy.dynamic.DynamicType | D3: Initial | E3: =C3&"."&D3 -> net.bytebuddy.dynamic.DynamicType.Initial | F3: data/processed/prompts/insufficient_modularization/byte-buddy/net_bytebuddy_dynamic_DynamicType_Initial.txt | G3: 348 | H3: 0 | I3: =VLOOKUP(E3,gpt!E3:F5423,2,0) -> 0 | J3: =VLOOKUP(E3,deepseek!E3:F5423,2,0) -> 1 | K3: =VLOOKUP(E3,qwen!E3:F5423,2,0) -> 0
A4: javaparser | B4: Insufficient Modularization | C4: com.packageName | D4: ClassInPackage | E4: =C4&"."&D4 -> com.packageName.ClassInPackage | F4: data/processed/prompts/insufficient_modularization/javaparser/com_packageName_ClassInPackage.txt | G4: 338 | H4: 0 | I4: =VLOOKUP(E4,gpt!E4:F5424,2,0) -> 0 | J4: =VLOOKUP(E4,deepseek!E4:F5424,2,0) -> 0 | K4: =VLOOKUP(E4,qwen!E4:F5424,2,0) -> 0
A5: byte-buddy | B5: Insufficient Modularization | C5: net.bytebuddy.description.type.TypeList | D5: Empty | E5: =C5&"."&D5 -> net.bytebuddy.description.type.TypeList.Empty | F5: data/processed/prompts/insufficient_modularization/byte-buddy/net_bytebuddy_description_type_TypeList_Empty.txt | G5: 368 | H5: 0 | I5: =VLOOKUP(E5,gpt!E5:F5425,2,0) -> 0 | J5: =VLOOKUP(E5,deepseek!E5:F5425,2,0) -> 0 | K5: =VLOOKUP(E5,qwen!E5:F5425,2,0) -> 0
A6: byte-buddy | B6: Insufficient Modularization | C6: net.bytebuddy.description.type.RecordComponentDescription | D6: InDefinedShape | E6: =C6&"."&D6 -> net.bytebuddy.description.type.RecordComponentDescription.InDefinedShape | F6: data/processed/prompts/insufficient_modularization/byte-buddy/net_bytebuddy_description_type_RecordComponentDescription_InDefinedShape.txt | G6: 355 | H6: 0 | I6: =VLOOKUP(E6,gpt!E6:F5426,2,0) -> 0 | J6: =VLOOKUP(E6,deepseek!E6:F5426,2,0) -> 0 | K6: =VLOOKUP(E6,qwen!E6:F5426,2,0) -> 0
A7: commons-io | B7: Insufficient Modularization | C7: org.apache.commons.io | D7: CloseableURLConnection | E7: =C7&"."&D7 -> org.apache.commons.io.CloseableURLConnection | F7: data/processed/prompts/insufficient_modularization/commons-io/org_apache_commons_io_CloseableURLConnection.txt | G7: 327 | H7: 1 | I7: =VLOOKUP(E7,gpt!E7:F5427,2,0) -> 1 | J7: =VLOOKUP(E7,deepseek!E7:F5427,2,0) -> 1 | K7: =VLOOKUP(E7,qwen!E7:F5427,2,0) -> 1
A8: byte-buddy | B8: Insufficient Modularization | C8: net.bytebuddy.implementation.bind.MethodDelegationBinder | D8: Compound | E8: =C8&"."&D8 -> net.bytebuddy.implementation.bind.MethodDelegationBinder.Compound | F8: data/processed/prompts/insufficient_modularization/byte-buddy/net_bytebuddy_implementation_bind_MethodDelegationBinder_Compound.txt | G8: 350 | H8: 0 | I8: =VLOOKUP(E8,gpt!E8:F5428,2,0) -> 0 | J8: =VLOOKUP(E8,deepseek!E8:F5428,2,0) -> 1 | K8: =VLOOKUP(E8,qwen!E8:F5428,2,0) -> 0
A9: zxing | B9: Insufficient Modularization | C9: com.google.zxing | D9: ResultPointCallback | E9: =C9&"."&D9 -> com.google.zxing.ResultPointCallback | F9: data/processed/prompts/insufficient_modularization/zxing/com_google_zxing_ResultPointCallback.txt | G9: 330 | H9: 0 | I9: =VLOOKUP(E9,gpt!E9:F5429,2,0) -> 0 | J9: =VLOOKUP(E9,deepseek!E9:F5429,2,0) -> 0 | K9: =VLOOKUP(E9,qwen!E9:F5429,2,0) -> 0
A10: byte-buddy | B10: Insufficient Modularization | C10: net.bytebuddy.dynamic.scaffold.inline | D10: MethodRebaseResolver | E10: =C10&"."&D10 -> net.bytebuddy.dynamic.scaffold.inline.MethodRebaseResolver | F10: data/processed/prompts/insufficient_modularization/byte-buddy/net_bytebuddy_dynamic_scaffold_inline_MethodRebaseResolver.txt | G10: 478 | H10: 0 | I10: =VLOOKUP(E10,gpt!E10:F5430,2,0) -> 1 | J10: =VLOOKUP(E10,deepseek!E10:F5430,2,0) -> 1 | K10: =VLOOKUP(E10,qwen!E10:F5430,2,0) -> 1
A11: byte-buddy | B11: Insufficient Modularization | C11: net.bytebuddy.implementation.bytecode.assign.primitive.PrimitiveUnboxingDelegate | D11: UnboxingResponsible | E11: =C11&"."&D11 -> net.bytebuddy.implementation.bytecode.assign.primitive.PrimitiveUnboxingDelegate.UnboxingResponsible | F11: data/processed/prompts/insufficient_modularization/byte-buddy/net_bytebuddy_implementation_bytecode_assign_primitive_PrimitiveUnboxingDelegate_UnboxingResponsible.txt | G11: 370 | H11: 0 | I11: =VLOOKUP(E11,gpt!E11:F5431,2,0) -> 0 | J11: =VLOOKUP(E11,deepseek!E11:F5431,2,0) -> 0 | K11: =VLOOKUP(E11,qwen!E11:F5431,2,0) -> 0
A12: jitwatch | B12: Insufficient Modularization | C12: (default package) | D12: ElisionTest | E12: =C12&"."&D12 -> (default package).ElisionTest | F12: data/processed/prompts/insufficient_modularization/jitwatch/(default package)_ElisionTest.txt | G12: 320 | H12: 0 | I12: =VLOOKUP(E12,gpt!E12:F5432,2,0) -> 0 | J12: =VLOOKUP(E12,deepseek!E12:F5432,2,0) -> 0 | K12: =VLOOKUP(E12,qwen!E12:F5432,2,0) -> 0
A13: byte-buddy | B13: Insufficient Modularization | C13: net.bytebuddy | D13: NamingStrategy | E13: =C13&"."&D13 -> net.bytebuddy.NamingStrategy | F13: data/processed/prompts/insufficient_modularization/byte-buddy/net_bytebuddy_NamingStrategy.txt | G13: 387 | H13: 0 | I13: =VLOOKUP(E13,gpt!E13:F5433,2,0) -> 1 | J13: =VLOOKUP(E13,deepseek!E13:F5433,2,0) -> 1 | K13: =VLOOKUP(E13,qwen!E13:F5433,2,0) -> 0
... A33: byte-buddy | B33: Insufficient Modularization | C33: net.bytebuddy.description.method.ParameterList | D33: OfMethod | E33: =C33&"."&D33 -> net.bytebuddy.description.method.ParameterList.OfMethod | F33: data/processed/prompts/insufficient_modularization/byte-buddy/net_bytebuddy_description_method_ParameterList_OfMethod.txt | G33: 343 | H33: 0 | I33: =VLOOKUP(E33,gpt!E33:F5453,2,0) -> 0 | J33: =VLOOKUP(E33,deepseek!E33:F5453,2,0) -> 0 | K33: =VLOOKUP(E33,qwen!E33:F5453,2,0) -> 0
A34: byte-buddy | B34: Insufficient Modularization | C34: net.bytebuddy.benchmark.jmh.generated.SuperClassInvocationBenchmark.benchmarkByteBuddyWithPrefix | D34: jmhTest | E34: =C34&"."&D34 -> net.bytebuddy.benchmark.jmh.generated.SuperClassInvocationBenchmark.benchmarkByteBuddyWithPrefix.jmhTest | F34: data/processed/prompts/insufficient_modularization/byte-buddy/net_bytebuddy_benchmark_jmh_generated_SuperClassInvocationBenchmark_benchmarkByteBuddyWithPrefix_jmhTest.txt | G34: 4528 | H34: 0 | I34: =VLOOKUP(E34,gpt!E34:F5454,2,0) -> 1 | J34: =VLOOKUP(E34,deepseek!E34:F5454,2,0) -> 1 | K34: 0
A35: zxing | B35: Insufficient Modularization | C35: com.google.zxing.oned.rss.expanded.decoders | D35: AI013103decoder | E35: =C35&"."&D35 -> com.google.zxing.oned.rss.expanded.decoders.AI013103decoder | F35: data/processed/prompts/insufficient_modularization/zxing/com_google_zxing_oned_rss_expanded_decoders_AI013103decoder.txt | G35: 350 | H35: 0 | I35: =VLOOKUP(E35,gpt!E35:F5455,2,0) -> 0 | J35: =VLOOKUP(E35,deepseek!E35:F5455,2,0) -> 0 | K35: =VLOOKUP(E35,qwen!E35:F5455,2,0) -> 0
A36: javaparser | B36: Insufficient Modularization | C36: com.github.javaparser.symbolsolver.utils | D36: FileUtils | E36: =C36&"."&D36 -> com.github.javaparser.symbolsolver.utils.FileUtils | F36: data/processed/prompts/insufficient_modularization/javaparser/com_github_javaparser_symbolsolver_utils_FileUtils.txt | G36: 340 | H36: 0 | I36: =VLOOKUP(E36,gpt!E36:F5456,2,0) -> 0 | J36: =VLOOKUP(E36,deepseek!E36:F5456,2,0) -> 0 | K36: =VLOOKUP(E36,qwen!E36:F5456,2,0) -> 0
A37: commons-lang | B37: Insufficient Modularization | C37: org.apache.commons.lang3.event | D37: EventListenerSupport | E37: =C37&"."&D37 -> org.apache.commons.lang3.event.EventListenerSupport | F37: data/processed/prompts/insufficient_modularization/commons-lang/org_apache_commons_lang3_event_EventListenerSupport.txt | G37: 342 | H37: 0 | I37: =VLOOKUP(E37,gpt!E37:F5457,2,0) -> 0 | J37: =VLOOKUP(E37,deepseek!E37:F5457,2,0) -> 1 | K37: =VLOOKUP(E37,qwen!E37:F5457,2,0) -> 0
A38: commons-lang | B38: Insufficient Modularization | C38: org.apache.commons.lang3.Strings | D38: CsStrings | E38: =C38&"."&D38 -> org.apache.commons.lang3.Strings.CsStrings | F38: data/processed/prompts/insufficient_modularization/commons-lang/org_apache_commons_lang3_Strings_CsStrings.txt | G38: 326 | H38: 0 | I38: =VLOOKUP(E38,gpt!E38:F5458,2,0) -> 0 | J38: =VLOOKUP(E38,deepseek!E38:F5458,2,0) -> 0 | K38: =VLOOKUP(E38,qwen!E38:F5458,2,0) -> 0
A39: zxing | B39: Insufficient Modularization | C39: com.google.zxing.web | D39: OutputUtils | E39: =C39&"."&D39 -> com.google.zxing.web.OutputUtils | F39: data/processed/prompts/insufficient_modularization/zxing/com_google_zxing_web_OutputUtils.txt | G39: 331 | H39: 0 | I39: =VLOOKUP(E39,gpt!E39:F5459,2,0) -> 1 | J39: =VLOOKUP(E39,deepseek!E39:F5459,2,0) -> 0 | K39: =VLOOKUP(E39,qwen!E39:F5459,2,0) -> 0
A40: byte-buddy | B40: Insufficient Modularization | C40: net.bytebuddy.asm.MemberSubstitution | D40: Dispatcher | E40: =C40&"."&D40 -> net.bytebuddy.asm.MemberSubstitution.Dispatcher | F40: data/processed/prompts/insufficient_modularization/byte-buddy/net_bytebuddy_asm_MemberSubstitution_Dispatcher.txt | G40: 394 | H40: 0 | I40: =VLOOKUP(E40,gpt!E40:F5460,2,0) -> 1 | J40: =VLOOKUP(E40,deepseek!E40:F5460,2,0) -> 1 | K40: =VLOOKUP(E40,qwen!E40:F5460,2,0) -> 1
A41: byte-buddy | B41: Insufficient Modularization | C41: net.bytebuddy.implementation.bytecode.member | D41: Invokedynamic | E41: =C41&"."&D41 -> net.bytebuddy.implementation.bytecode.member.Invokedynamic | F41: data/processed/prompts/insufficient_modularization/byte-buddy/net_bytebuddy_implementation_bytecode_member_Invokedynamic.txt | G41: 392 | H41: 0 | I41: =VLOOKUP(E41,gpt!E41:F5461,2,0) -> 0 | J41: =VLOOKUP(E41,deepseek!E41:F5461,2,0) -> 0 | K41: =VLOOKUP(E41,qwen!E41:F5461,2,0) -> 0
A42: byte-buddy | B42: Insufficient Modularization | C42: net.bytebuddy.description.method.ParameterList | D42: OfLegacyVmMethod | E42: =C42&"."&D42 -> net.bytebuddy.description.method.ParameterList.OfLegacyVmMethod | F42: data/processed/prompts/insufficient_modularization/byte-buddy/net_bytebuddy_description_method_ParameterList_OfLegacyVmMethod.txt | G42: 354 | H42: 0 | I42: =VLOOKUP(E42,gpt!E42:F5462,2,0) -> 0 | J42: =VLOOKUP(E42,deepseek!E42:F5462,2,0) -> 0 | K42: =VLOOKUP(E42,qwen!E42:F5462,2,0) -> 0
A43: javaparser | B43: Insufficient Modularization | C43: com.github.javaparser.utils | D43: ParserCollectionStrategy | E43: =C43&"."&D43 -> com.github.javaparser.utils.ParserCollectionStrategy | F43: data/processed/prompts/insufficient_modularization/javaparser/com_github_javaparser_utils_ParserCollectionStrategy.txt | G43: 357 | H43: 0 | I43: =VLOOKUP(E43,gpt!E43:F5463,2,0) -> 0 | J43: =VLOOKUP(E43,deepseek!E43:F5463,2,0) -> 0 | K43: =VLOOKUP(E43,qwen!E43:F5463,2,0) -> 0
A44: byte-buddy | B44: Insufficient Modularization | C44: org.gradle.api.tasks | D44: PathSensitivity | E44: =C44&"."&D44 -> org.gradle.api.tasks.PathSensitivity | F44: data/processed/prompts/insufficient_modularization/byte-buddy/org_gradle_api_tasks_PathSensitivity.txt | G44: 335 | H44: 0 | I44: =VLOOKUP(E44,gpt!E44:F5464,2,0) -> 0 | J44: =VLOOKUP(E44,deepseek!E44:F5464,2,0) -> 0 | K44: =VLOOKUP(E44,qwen!E44:F5464,2,0) -> 0
A45: commons-io | B45: Insufficient Modularization | C45: org.apache.commons.io.input | D45: UncheckedFilterReader | E45: =C45&"."&D45 -> org.apache.commons.io.input.UncheckedFilterReader | F45: data/processed/prompts/insufficient_modularization/commons-io/org_apache_commons_io_input_UncheckedFilterReader.txt | G45: 347 | H45: 0 | I45: =VLOOKUP(E45,gpt!E45:F5465,2,0) -> 0 | J45: =VLOOKUP(E45,deepseek!E45:F5465,2,0) -> 0 | K45: =VLOOKUP(E45,qwen!E45:F5465,2,0) -> 0
A46: byte-buddy | B46: Insufficient Modularization | C46: net.bytebuddy.implementation.auxiliary.TypeProxy | D46: MethodCall | E46: =C46&"."&D46 -> net.bytebuddy.implementation.auxiliary.TypeProxy.MethodCall | F46: data/processed/prompts/insufficient_modularization/byte-buddy/net_bytebuddy_implementation_auxiliary_TypeProxy_MethodCall.txt | G46: 398 | H46: 0 | I46: =VLOOKUP(E46,gpt!E46:F5466,2,0) -> 0 | J46: =VLOOKUP(E46,deepseek!E46:F5466,2,0) -> 1 | K46: =VLOOKUP(E46,qwen!E46:F5466,2,0) -> 0
... A135: byte-buddy | B135: Insufficient Modularization | C135: net.bytebuddy.utility | D135: StreamDrainer | E135: =C135&"."&D135 -> net.bytebuddy.utility.StreamDrainer | F135: data/processed/prompts/insufficient_modularization/byte-buddy/net_bytebuddy_utility_StreamDrainer.txt | G135: 347 | H135: 0 | I135: =VLOOKUP(E135,gpt!E135:F5555,2,0) -> 1 | J135: =VLOOKUP(E135,deepseek!E135:F5555,2,0) -> 0 | K135: =VLOOKUP(E135,qwen!E135:F5555,2,0) -> 0
A136: javaparser | B136: Insufficient Modularization | C136: com.github.javaparser.javasymbolsolver.javassist.symbols.main.jar | D136: InterfaceUserOwnJar | E136: =C136&"."&D136 -> com.github.javaparser.javasymbolsolver.javassist.symbols.main.jar.InterfaceUserOwnJar | F136: data/processed/prompts/insufficient_modularization/javaparser/com_github_javaparser_javasymbolsolver_javassist_symbols_main_jar_InterfaceUserOwnJar.txt | G136: 369 | H136: 0 | I136: =VLOOKUP(E136,gpt!E136:F5556,2,0) -> 0 | J136: =VLOOKUP(E136,deepseek!E136:F5556,2,0) -> 0 | K136: 0
A137: byte-buddy | B137: Insufficient Modularization | C137: net.bytebuddy.build.maven | D137: Initialization | E137: =C137&"."&D137 -> net.bytebuddy.build.maven.Initialization | F137: data/processed/prompts/insufficient_modularization/byte-buddy/net_bytebuddy_build_maven_Initialization.txt | G137: 348 | H137: 0 | I137: =VLOOKUP(E137,gpt!E137:F5557,2,0) -> 0 | J137: =VLOOKUP(E137,deepseek!E137:F5557,2,0) -> 0 | K137: =VLOOKUP(E137,qwen!E137:F5557,2,0) -> 0
A138: byte-buddy | B138: Insufficient Modularization | C138: net.bytebuddy.implementation.attribute | D138: AnnotationValueFilter | E138: =C138&"."&D138 -> net.bytebuddy.implementation.attribute.AnnotationValueFilter | F138: data/processed/prompts/insufficient_modularization/byte-buddy/net_bytebuddy_implementation_attribute_AnnotationValueFilter.txt | G138: 353 | H138: 0 | I138: =VLOOKUP(E138,gpt!E138:F5558,2,0) -> 0 | J138: =VLOOKUP(E138,deepseek!E138:F5558,2,0) -> 1 | K138: =VLOOKUP(E138,qwen!E138:F5558,2,0) -> 0
A139: javaparser | B139: Insufficient Modularization | C139: main.Clazz | D139: MyEnum | E139: =C139&"."&D139 -> main.Clazz.MyEnum | F139: data/processed/prompts/insufficient_modularization/javaparser/main_Clazz_MyEnum.txt | G139: 336 | H139: 0 | I139: =VLOOKUP(E139,gpt!E139:F5559,2,0) -> 0 | J139: =VLOOKUP(E139,deepseek!E139:F5559,2,0) -> 0 | K139: =VLOOKUP(E139,qwen!E139:F5559,2,0) -> 0
A140: byte-buddy | B140: Insufficient Modularization | C140: net.bytebuddy.asm.MemberSubstitution | D140: Sort | E140: =C140&"."&D140 -> net.bytebuddy.asm.MemberSubstitution.Sort | F140: data/processed/prompts/insufficient_modularization/byte-buddy/net_bytebuddy_asm_MemberSubstitution_Sort.txt | G140: 349 | H140: 0 | I140: =VLOOKUP(E140,gpt!E140:F5560,2,0) -> 1 | J140: =VLOOKUP(E140,deepseek!E140:F5560,2,0) -> 1 | K140: =VLOOKUP(E140,qwen!E140:F5560,2,0) -> 0
A141: byte-buddy | B141: Insufficient Modularization | C141: net.bytebuddy.implementation.Implementation | D141: FrameGeneration | E141: =C141&"."&D141 -> net.bytebuddy.implementation.Implementation.FrameGeneration | F141: data/processed/prompts/insufficient_modularization/byte-buddy/net_bytebuddy_implementation_Implementation_FrameGeneration.txt | G141: 332 | H141: 0 | I141: =VLOOKUP(E141,gpt!E141:F5561,2,0) -> 0 | J141: =VLOOKUP(E141,deepseek!E141:F5561,2,0) -> 1 | K141: =VLOOKUP(E141,qwen!E141:F5561,2,0) -> 0
A142: javaparser | B142: Insufficient Modularization | C142: com.github.javaparser.printer.lexicalpreservation.ReshuffledDiffElementExtractor | D142: MatchClassification | E142: =C142&"."&D142 -> com.github.javaparser.printer.lexicalpreservation.ReshuffledDiffElementExtractor.MatchClassification | F142: data/processed/prompts/insufficient_modularization/javaparser/com_github_javaparser_printer_lexicalpreservation_ReshuffledDiffElementExtractor_MatchClassification.txt | G142: 354 | H142: 0 | I142: =VLOOKUP(E142,gpt!E142:F5562,2,0) -> 0 | J142: =VLOOKUP(E142,deepseek!E142:F5562,2,0) -> 0 | K142: =VLOOKUP(E142,qwen!E142:F5562,2,0) -> 0
A143: byte-buddy | B143: Insufficient Modularization | C143: net.bytebuddy.build.HashCodeAndEqualsPlugin | D143: Sort | E143: =C143&"."&D143 -> net.bytebuddy.build.HashCodeAndEqualsPlugin.Sort | F143: data/processed/prompts/insufficient_modularization/byte-buddy/net_bytebuddy_build_HashCodeAndEqualsPlugin_Sort.txt | G143: 337 | H143: 0 | I143: =VLOOKUP(E143,gpt!E143:F5563,2,0) -> 0 | J143: =VLOOKUP(E143,deepseek!E143:F5563,2,0) -> 0 | K143: =VLOOKUP(E143,qwen!E143:F5563,2,0) -> 0
A144: jitwatch | B144: Insufficient Modularization | C144: org.adoptopenjdk.jitwatch.ui.Dialogs | D144: Dialog | E144: =C144&"."&D144 -> org.adoptopenjdk.jitwatch.ui.Dialogs.Dialog | F144: data/processed/prompts/insufficient_modularization/jitwatch/org_adoptopenjdk_jitwatch_ui_Dialogs_Dialog.txt | G144: 332 | H144: 0 | I144: =VLOOKUP(E144,gpt!E144:F5564,2,0) -> 0 | J144: =VLOOKUP(E144,deepseek!E144:F5564,2,0) -> 0 | K144: =VLOOKUP(E144,qwen!E144:F5564,2,0) -> 0
A145: commons-lang | B145: Insufficient Modularization | C145: org.apache.commons.lang3.exception | D145: CloneFailedException | E145: =C145&"."&D145 -> org.apache.commons.lang3.exception.CloneFailedException | F145: data/processed/prompts/insufficient_modularization/commons-lang/org_apache_commons_lang3_exception_CloneFailedException.txt | G145: 330 | H145: 0 | I145: =VLOOKUP(E145,gpt!E145:F5565,2,0) -> 0 | J145: =VLOOKUP(E145,deepseek!E145:F5565,2,0) -> 0 | K145: =VLOOKUP(E145,qwen!E145:F5565,2,0) -> 0
A146: javaparser | B146: Insufficient Modularization | C146: com.github.javaparser.metamodel | D146: TypeParameterMetaModel | E146: =C146&"."&D146 -> com.github.javaparser.metamodel.TypeParameterMetaModel | F146: data/processed/prompts/insufficient_modularization/javaparser/com_github_javaparser_metamodel_TypeParameterMetaModel.txt | G146: 347 | H146: 0 | I146: =VLOOKUP(E146,gpt!E146:F5566,2,0) -> 0 | J146: =VLOOKUP(E146,deepseek!E146:F5566,2,0) -> 0 | K146: =VLOOKUP(E146,qwen!E146:F5566,2,0) -> 0
A147: zxing | B147: Insufficient Modularization | C147: com.google.zxing.datamatrix.decoder | D147: DataBlock | E147: =C147&"."&D147 -> com.google.zxing.datamatrix.decoder.DataBlock | F147: data/processed/prompts/insufficient_modularization/zxing/com_google_zxing_datamatrix_decoder_DataBlock.txt | G147: 339 | H147: 0 | I147: =VLOOKUP(E147,gpt!E147:F5567,2,0) -> 0 | J147: =VLOOKUP(E147,deepseek!E147:F5567,2,0) -> 0 | K147: =VLOOKUP(E147,qwen!E147:F5567,2,0) -> 0
...

Sheet gpt
A1: project | B1: file_name | C1: smell | D1: entity_type | E1: entity | F1: detection | G1: justification
A2: byte-buddy | B2: (default package)_MavenWrapperDownloader.txt | D2: class | E2: (default package).MavenWrapperDownloader | F2: 1 | G2: LOC=93 and WMC=12 indicate moderate size and complexity; NOM=6 with NOPM=1 (only one public method) implies many internal/helper methods, suggesting multiple responsibilities hidden inside the class; LCOM=0.8333 (high, near 1) shows low cohesion among methods/fields. These elements (size, internal complexity, low cohesion, few public entry points) justify that the class is insufficiently modularized and would benefit from decomposition (extraction of responsibilities into separate classes or helper objects).
A3: byte-buddy | B3: com.service.definition_ServiceDefinition.txt | D3: class | E3: com.service.definition.ServiceDefinition | F3: 0 | G3: False — the class shows no signs of Insufficient Modularization: LOC=3, NOM=1, WMC=1, NOF=0, NOPF=0, NOPM=0, fanin=0, fanout=0, LCOM=-1.0. It is very small, has a single method, no fields and minimal complexity/cohesion metrics, so there is no evidence it needs further decomposition.
A4: byte-buddy | B4: com.service.usage2_ServiceImplementation.txt | D4: class | E4: com.service.usage2.ServiceImplementation | F4: 0 | G4: The class is small and simple (loc=5, wmc=1) with a single method (nom=1, nopm=1) and no fields (nof=0, nopf=0). Cohesion metric is high/acceptable (lcom=-1.0) and there are no incoming or outgoing dependencies (fanin=0, fanout=0). Given the minimal size, low complexity, and lack of multiple responsibilities, there is no evidence that the class is insufficiently modularized.
A5: byte-buddy | B5: com.service.usage_ServiceImplementation.txt | D5: class | E5: com.service.usage.ServiceImplementation | F5: 0 | G5: Not detected: class is very small and simple — LOC=5, NOM=1, WMC=1, NOF=0, NOPF=0, NOPM=1, LCOM=-1.0, fanin=0, fanout=0. Low size, single method, low complexity and no coupling indicate no further decomposition is warranted.
A6: byte-buddy | B6: net.bytebuddy.agent.builder_AgentBuilder.Adapter.txt | D6: class | E6: net.bytebuddy.agent.builder.AgentBuilder.Adapter | F6: 0 | G6: Metrics show a very small, trivial class: LOC=21, NOM=0, NOF=0, WMC=0, fanin=0, fanout=0 and only one external dependency. There are no methods or fields to decompose and complexity is zero, so there is no evidence that further modularization is needed (LCOM=-1.0 is not indicative of missing decomposition).
A7: byte-buddy | B7: net.bytebuddy.agent.builder_AgentBuilder.Appender.txt | D7: class | E7: net.bytebuddy.agent.builder.AgentBuilder.Appender | F7: 0 | G7: The class is small and already highly cohesive/low complexity: LOC=22, NOM=0, WMC=0, NOF=1. LCOM=-1.0 indicates strong cohesion. Coupling is negligible (fanin=0, fanout=0). Given the lack of methods, low size, and low complexity, there is no evidence that the class has not been decomposed further; insufficient modularization is not detected.
A8: byte-buddy | B8: net.bytebuddy.agent.builder_AgentBuilder.Asynchronous.txt | D8: class | E8: net.bytebuddy.agent.builder.AgentBuilder.Asynchronous | F8: 1 | G8: High source size (loc: 141) combined with a non-trivial number of fields (nof: 8) while declaring zero methods (nom: 0, nopm: 0) indicates the class body contains substantial implementation that has not been decomposed into smaller methods or helper types. The mismatch between large LOC and zero reported methods suggests responsibilities or implementation details are embedded in initializers/inline code rather than modularized. WMC: 0 and LCOM: -1.0 provide no evidence of well-distributed complexity/cohesion, and the small dependency set (2 entries) implies functionality is implemented inside this class rather than delegated—together these elements justify detecting Insufficient Modularization.
A9: byte-buddy | B9: net.bytebuddy.agent.builder_AgentBuilder.AtFixedRate.txt | D9: class | E9: net.bytebuddy.agent.builder.AgentBuilder.AtFixedRate | F9: 0 | G9: The class does not exhibit signs of insufficient modularization: small size (LOC=40), very low complexity (WMC=0), no methods (nom=0), few fields (NOF=3, NOPF=0), high cohesion indicator (LCOM=-1.0), and no incoming/outgoing coupling (fanin=0, fanout=0). Only a single listed dependency (net.bytebuddy.build.HashCodeAndEqualsPlugin). Based on these metrics in isolation, the class is not large or complex enough to require further decomposition.
A10: byte-buddy | B10: net.bytebuddy.agent.builder_AgentBuilder.BatchAllocator.txt | D10: class | E10: net.bytebuddy.agent.builder.AgentBuilder.BatchAllocator | F10: 1 | G10: High size and state: LOC = 370 and number of fields (nof) = 14 while number of methods (nom) = 0. The large line count combined with many fields indicates the class is large and likely mixes responsibilities, suggesting it has not been sufficiently decomposed and would benefit from modularization.
A11: byte-buddy | B11: net.bytebuddy.agent.builder_AgentBuilder.BatchReallocator.txt | D11: class | E11: net.bytebuddy.agent.builder.AgentBuilder.BatchReallocator | F11: 0 | G11: Class is small and simple: LOC=26, NOF=1, NOM=0, WMC=0, DIT=0. Coupling is minimal (fanin=0, fanout=0) and only one external dependency (net.bytebuddy.build.HashCodeAndEqualsPlugin). These metrics indicate low size and complexity, so there is no evidence that further decomposition is needed.
A12: byte-buddy | B12: net.bytebuddy.agent.builder_AgentBuilder.BootstrapMarkerAction.txt | D12: class | E12: net.bytebuddy.agent.builder.AgentBuilder.BootstrapMarkerAction | F12: 0 | G12: The class is small and non-complex: LOC=13, NOM=0, WMC=0, NOPM=0. Coupling is minimal (fanin=0, fanout=0, single listed dependency: net.bytebuddy.dynamic.loading.ClassLoadingStrategy). With no methods or fields to decompose and very low complexity and size, there is no evidence that further decomposition is needed in isolation.
A13: byte-buddy | B13: net.bytebuddy.agent.builder_AgentBuilder.BridgeMethodImplementation.txt | D13: class | E13: net.bytebuddy.agent.builder.AgentBuilder.BridgeMethodImplementation | F13: 0 | G13: The class does not show signs of insufficient modularization: small size (loc=56), very low complexity (wmc=0), no methods to split (nom=0), only three fields (nof=3), minimal inheritance depth (dit=1), and low coupling (fanin=0, fanout=0). The cohesion metric (lcom=-1.0) does not indicate poor cohesion. Although there are a few external type references, the class's limited size and complexity mean further decomposition is not justified based on the provided metrics.
... A541: byte-buddy | B541: net.bytebuddy.benchmark.jmh_generated_StubInvocationBenchmark_jmhType_B3.txt | D541: class | E541: net.bytebuddy.benchmark.jmh.generated.StubInvocationBenchmark.jmhType.B3 | F541: 1 | G541: The class has an extremely large number of fields (nof = 256) while having no methods (nom = 0) and very low LOC (18). WMC = 0 and LCOM = -1.0 indicate absence of encapsulated behavior; DIT = 3 shows deeper inheritance but does not reduce the field bloat. The combination of many fields with no behavior/operations suggests the class has not been decomposed and should be modularized into smaller, cohesive units.
A542: byte-buddy | B542: net.bytebuddy.benchmark.jmh_generated_SuperClassInvocationBenchmark_baseline_jmhTest.txt | C542: insufficient_modularization | D542: class | E542: net.bytebuddy.benchmark.jmh.generated.SuperClassInvocationBenchmark.baseline.jmhTest | G542: {
A543: ""class"": ""net.bytebuddy.benchmark.jmh_generated.SuperClassInvocationBenchmark_baseline_jmhTest""
A544: ""detection"": true
A545: ""justification"": ""The class exhibits characteristics of Insufficient Modularization: extremely high number of fields (nof = 263) concentrated in a single class while LOC is 276 and number of methods is small (nom = 9 | B545: nopm = 8) | C545: indicating many attributes/responsibilities are not split into smaller types. Complexity is non-trivial (wmc = 42). Additionally | D545: there is no inheritance decomposition (dit = 0 | E545: nopm = 8) | F545: fanout = 0) | G545: suggesting the class itself holds much structure/behavior that could be factored out. These elements together justify that the class has not been sufficiently decomposed and would benefit from modularization/refactoring."""
A546: byte-buddy | B546: net.bytebuddy.benchmark.jmh_generated_SuperClassInvocationBenchmark_benchmarkByteBuddySpecialized_jmhTest.txt | D546: class | E546: net.bytebuddy.benchmark.jmh.generated.SuperClassInvocationBenchmark.benchmarkByteBuddySpecialized.jmhTest | F546: 1 | G546: The class exhibits signs of insufficient modularization: very high number of fields (nof = 263) combined with substantial size (loc = 276) and elevated complexity (wmc = 42) despite a relatively small number of methods (nom = 9). The disproportionate field count relative to methods and overall size suggests the class aggregates many responsibilities or data elements that could be decomposed into smaller, more focused classes or modules.
A547: byte-buddy | B547: net.bytebuddy.benchmark.jmh_generated_SuperClassInvocationBenchmark_benchmarkByteBuddyWithAccessor_jmhTest.txt | D547: class | E547: net.bytebuddy.benchmark.jmh.generated.SuperClassInvocationBenchmark.benchmarkByteBuddyWithAccessor.jmhTest | F547: 1 | G547: Detected because the class has an extremely high number of fields (nof=263) while exposing a small number of methods (nom=9, nopm=8), together with sizable size and complexity (loc=276, wmc=42). The disproportion between very large state (many fields) and relatively few operations, plus overall LOC/WMC, indicates the class aggregates too much responsibility and state and could be further decomposed to reduce size and implementation complexity.
A548: byte-buddy | B548: net.bytebuddy.benchmark.jmh_generated_SuperClassInvocationBenchmark_benchmarkByteBuddyWithPrefix_jmhTest.txt | D548: class | E548: net.bytebuddy.benchmark.jmh.generated.SuperClassInvocationBenchmark.benchmarkByteBuddyWithPrefix.jmhTest | F548: 1 | G548: The class shows signs of being a monolithic unit: very high number of fields (nof = 263) and substantial size (loc = 276) while having a relatively small set of methods (nom = 9, nopm = 8). Combined with a high complexity score (wmc = 42) this indicates many responsibilities and large internal state that could be decomposed. The lack of inheritance depth (dit = 0) implies decomposition has not been applied via subclasses. These elements together justify detecting Insufficient Modularization.
A549: byte-buddy | B549: net.bytebuddy.benchmark.jmh_generated_SuperClassInvocationBenchmark_benchmarkByteBuddyWithProxy_jmhTest.txt | D549: class | E549: net.bytebuddy.benchmark.jmh.generated.SuperClassInvocationBenchmark.benchmarkByteBuddyWithProxy.jmhTest | F549: 1 | G549: The class shows signs of insufficient modularization: extremely high number of fields (nof = 263) while having few methods (nom = 9, nopm = 8) and only moderate LOC (loc = 276). The weighted method complexity is relatively high (wmc = 42) given the small method count, indicating concentrated complexity. The disparity between a very large field set and few methods suggests multiple responsibilities or bundled state that could be split into smaller, more cohesive classes to reduce size and implementation complexity.
A550: byte-buddy | B550: net.bytebuddy.benchmark.jmh_generated_SuperClassInvocationBenchmark_benchmarkCglib_jmhTest.txt | D550: class | E550: net.bytebuddy.benchmark.jmh.generated.SuperClassInvocationBenchmark.benchmarkCglib.jmhTest | F550: 1 | G550: The class shows signs of being too large and complex to remain monolithic: very high number of features/elements (nof = 263) and large size (loc = 276) indicate heavy implementation volume; high cyclomatic/weight metric (wmc = 42) indicates substantial internal complexity. Although method count is moderate (nom = 9) and LCOM = 0.0 implies those methods are cohesive, the overall size and element count (nof = 263) together with elevated WMC justify that the class could be further decomposed to reduce size and complexity.
A551: byte-buddy | B551: net.bytebuddy.benchmark.jmh_generated_SuperClassInvocationBenchmark_benchmarkJavassist_jmhTest.txt | D551: class | E551: net.bytebuddy.benchmark.jmh.generated.SuperClassInvocationBenchmark.benchmarkJavassist.jmhTest | F551: 1 | G551: The class exhibits signs of insufficient modularization: very large number of fields (nof = 263) and substantial size (loc = 276) indicate a bloated single unit; relatively high overall complexity (wmc = 42) across its methods (nom = 9, nopm = 8) suggests concentration of behavior rather than separation; there is no internal decomposition via nested classes (nc = 0) nor inheritance (dit = 0) to distribute responsibilities, and zero fanin/fanout (fanin = 0, fanout = 0) indicates the class is self-contained and likely monolithic. These elements together justify that further decomposition would likely reduce size and implementation complexity.
A552: byte-buddy | B552: net.bytebuddy.benchmark.jmh_generated_SuperClassInvocationBenchmark_jmhType.txt | D552: class | E552: net.bytebuddy.benchmark.jmh.generated.SuperClassInvocationBenchmark.jmhType | F552: 0 | G552: Class has LOC=2, NOM=0, NOF=0, NOPM=0 and WMC=0 indicating no methods, no fields and no implementation complexity. Fanin=0 and Fanout=0 show no coupling through calls. Although DIT=4 indicates a deep inheritance level, the class itself is trivially small and contains no decomposable responsibilities, so there is no evidence of insufficient modularization.
A553: byte-buddy | B553: net.bytebuddy.benchmark.jmh_generated_SuperClassInvocationBenchmark_jmhType_B1.txt | D553: class | E553: net.bytebuddy.benchmark.jmh.generated.SuperClassInvocationBenchmark.jmhType.B1 | F553: 1 | G553: High number of fields with no behavior: nof=256 while nom=0 and wmc=0, with very low LOC=18. This large aggregation of data (256 fields) without methods or internal decomposition indicates the class groups many responsibilities/attributes and could be split into smaller classes (insufficient modularization). Additional supporting metrics: nc=1, dit=1, fanin=0, fanout=0 — the class is isolated but monolithic, reinforcing the need for further decomposition.
A554: byte-buddy | B554: net.bytebuddy.benchmark.jmh_generated_SuperClassInvocationBenchmark_jmhType_B2.txt | D554: class | E554: net.bytebuddy.benchmark.jmh.generated.SuperClassInvocationBenchmark.jmhType.B2 | F554: 0 | G554: Although the class has 12 fields (nof=12), it contains no methods (nom=0, nopm=0) and very low implementation size and complexity (loc=14, wmc=0). Coupled with zero external coupling (fanin=0, fanout=0) and a single child (nc=1, dit=2), there is no evidence of a large, complex, or multi-responsibility implementation that would benefit from further decomposition. Therefore Insufficient Modularization is not detected.
A555: byte-buddy | B555: net.bytebuddy.benchmark.jmh_generated_SuperClassInvocationBenchmark_jmhType_B3.txt | D555: class | E555: net.bytebuddy.benchmark.jmh.generated.SuperClassInvocationBenchmark.jmhType.B3 | F555: 1 | G555: The class shows signs of insufficient modularization: very high number of fields (nof=256) while having no methods (nom=0) and low lines of code (loc=18), indicating a large data aggregate concentrated in a single class. WMC=0 (no method complexity) and nom=0 imply behavior is not separated into smaller collaborating units; fanin=0 and fanout=0 show it is isolated rather than modularized. The disproportion between nof and loc/nom supports that further decomposition (splitting fields/concerns into separate classes) would reduce size and improve modularity.
A556: byte-buddy | B556: net.bytebuddy.benchmark.jmh_generated_TrivialClassCreationBenchmark_baseline_jmhTest.txt | D556: class | E556: net.bytebuddy.benchmark.jmh.generated.TrivialClassCreationBenchmark.baseline.jmhTest | F556: 1 | G556: The class shows indicators of insufficient modularization: an extremely high number of fields (nof = 263) combined with a relatively large size (loc = 275) and elevated complexity (wmc = 42). Although method count is modest (nom = 9, nopm = 8) and LCOM = 0.0 does not indicate poor cohesion, the disproportionate amount of state (263 fields) and overall complexity suggest the class encapsulates too much responsibility and would benefit from decomposition into smaller, more focused classes or components.
A557: byte-buddy | B557: net.bytebuddy.benchmark.jmh_generated_TrivialClassCreationBenchmark_benchmarkByteBuddy_jmhTest.txt | D557: class | E557: net.bytebuddy.benchmark.jmh.generated.TrivialClassCreationBenchmark.benchmarkByteBuddy.jmhTest | F557: 1 | G557: Class shows signs of insufficient modularization: large size (LOC = 275) and high method-complexity (WMC = 42); very high number of fields/elements (NOF = 263) while having relatively few methods (NOM = 9, NOPM = 8) which suggests aggregation of many responsibilities/data into a single class; fanin = 0 and fanout = 0 indicate it is self-contained rather than composed; cohesion metric LCOM = 0.0 provides no counter-evidence. Together these metrics justify decomposing the class to reduce size and complexity.
... A692: byte-buddy | B692: net.bytebuddy.build_BuildLogger.StreamWriting.txt | D692: class | E692: net.bytebuddy.build.BuildLogger.StreamWriting | F692: 0 | G692: Metrics do not indicate a decomposable, high-responsibility unit: although LOC = 114, the class has nom = 0 (no methods), nof = 1 (one field), wmc = 0 (no cyclomatic complexity), fanin = 0 and fanout = 0 (no coupling), and LCOM = -1.0 (no cohesion concerns reported). Given the lack of methods, complexity, and coupling in isolation, there is no evidence that the class requires further decomposition.
A693: byte-buddy | B693: net.bytebuddy.build_BuildLogger.txt | C693: insufficient_modularization | D693: class | E693: net.bytebuddy.build.BuildLogger | G693: {
A694: ""class"": ""net.bytebuddy.build.BuildLogger""
A695: ""detection"": true
A696: ""justification"": ""The class is a strong candidate for Insufficient Modularization: very large size (loc=478) with a non-trivial number of methods (nom=12) indicates concentrated functionality that could be split; combined with moderate overall complexity (wmc=12) and high LOC this suggests long or complex method bodies that would benefit from decomposition. The class has no inheritance (dit=0) and zero fan-in/fan-out (fanin=0 | B696: fanout=0) | C696: meaning it is an isolated | D696: self-contained unit likely carrying multiple responsibilities rather than delegating them. LCOM=-1.0 does not provide evidence of high cohesion to counter decomposition. Dependency list is minimal (net.bytebuddy.build.HashCodeAndEqualsPlugin) | E696: fanout=0)
A697: byte-buddy | B697: net.bytebuddy.build_CachedReturnPlugin.AdviceResolver.txt | D697: class | E697: net.bytebuddy.build.CachedReturnPlugin.AdviceResolver | F697: 1 | G697: The class has a large size (loc: 153) while holding multiple fields (nof: 6) and referencing many external types (12 distinct dependencies), indicating it touches multiple responsibilities and high coupling. Cohesion metrics are not clearly positive (lcom: -1.0) and there are no recorded fine-grained method counts, suggesting substantial implementation concentrated in a single class. These indicators together point to insufficient modularization — the class is large and interacts with diverse concerns and would likely benefit from decomposition.
A698: byte-buddy | B698: net.bytebuddy.build_CachedReturnPlugin.CacheFieldOffsetMapping.txt | D698: class | E698: net.bytebuddy.build.CachedReturnPlugin.CacheFieldOffsetMapping | F698: 0 | G698: The class does not exhibit Insufficient Modularization: it has very small size and complexity (loc=22), only one field (nof=1) and no methods (nom=0, wmc=0), indicating there is little to decompose. Coupling is minimal (fanin=0, fanout=0) and cohesion metric is non-problematic (lcom=-1.0). These metrics show the class is already small and simple, so further decomposition is not warranted based on the provided data.
A699: byte-buddy | B699: net.bytebuddy.build_CachedReturnPlugin.ExitAdviceByteCodeAppender.txt | D699: class | E699: net.bytebuddy.build.CachedReturnPlugin.ExitAdviceByteCodeAppender | F699: 0 | G699: The class shows no indicators of an undecomposed, overly complex implementation: LOC is modest (62), Weighted Methods per Class (wmc) = 0 and Number of Methods (nom) = 0 indicate no large method body complexity to decompose, and Number of Fields (nof) = 5 is small. Coupling is minimal (fanin = 0, fanout = 0), inheritance depth is shallow (dit = 1), and LCOM is non-indicative. Given these metrics in isolation, there is no evidence that the class should be further decomposed, so Insufficient Modularization is not detected.
A700: byte-buddy | B700: net.bytebuddy.build_CachedReturnPlugin.txt | D700: class | E700: net.bytebuddy.build.CachedReturnPlugin | F700: 1 | G700: Insufficient modularization detected: the class is large (loc=260) while exposing few methods (nom=5, nopm=5) and a moderate cyclomatic burden (wmc=11), indicating large/complex methods. It declares many fields (nof=11) but few methods, producing a high field-to-method ratio and suggesting multiple responsibilities. Cohesion is low (lcom=0.8), showing related behavior is not well concentrated. The class depends on a wide variety of unrelated subsystems (19 dependencies, e.g. net.bytebuddy.build.HashCodeAndEqualsPlugin, net.bytebuddy.dynamic.DynamicType, net.bytebuddy.implementation.Implementation, net.bytebuddy.asm.Advice), which implies it mixes responsibilities across different concerns. These factors together justify that the class has not been fully decomposed and would benefit from further modularization.
A701: byte-buddy | B701: net.bytebuddy.build_DispatcherAnnotationPlugin.txt | D701: class | E701: net.bytebuddy.build.DispatcherAnnotationPlugin | F701: 0 | G701: Class has small size and complexity: loc=44, nom=6, nopm=6 and wmc=7 indicate limited implementation surface and moderate cyclomatic complexity. Depth of inheritance is low (dit=1) and lack of children (nc=0) suggests no need to split due to subclassing. Coupling/usage metrics do not indicate broad responsibilities (fanin=0, fanout=0) and cohesion measure (lcom=-1.0) does not imply fragmented responsibilities. Given these metrics, the class does not exhibit signs of insufficient modularization that would require further decomposition.
...

Sheet deepseek
A1: project | B1: file_name | C1: smell | D1: entity_type | E1: entity | F1: detection | G1: justification
A2: byte-buddy | B2: (default package)_MavenWrapperDownloader.txt | D2: class | E2: (default package).MavenWrapperDownloader | F2: 1 | G2: High lack of cohesion (LCOM = 0.833) and moderate complexity (WMC = 12) with 6 methods and 6 fields indicate low internal cohesion, suggesting that further decomposition could reduce implementation complexity and size.
A3: byte-buddy | B3: com.service.definition_ServiceDefinition.txt | D3: class | E3: com.service.definition.ServiceDefinition | F3: 0 | G3: The class has only one method (nom=1), no fields (nof=0), low size (loc=3), and low complexity (wmc=1). Further decomposition would not reduce its size or implementation complexity.
A4: byte-buddy | B4: com.service.usage2_ServiceImplementation.txt | D4: class | E4: com.service.usage2.ServiceImplementation | F4: 0 | G4: The class has only one method, no fields, low lines of code (5), and low complexity (wmc=1). There is no indication that further decomposition would reduce size or complexity.
A5: byte-buddy | B5: com.service.usage_ServiceImplementation.txt | D5: class | E5: com.service.usage.ServiceImplementation | F5: 0 | G5: The class has minimal complexity with only 1 method, 5 lines of code, 0 fields, and no dependencies, indicating it is already sufficiently modularized and does not require further decomposition.
A6: byte-buddy | B6: net.bytebuddy.agent.builder_AgentBuilder.Adapter.txt | D6: class | E6: net.bytebuddy.agent.builder.AgentBuilder.Adapter | F6: 0 | G6: The class has no methods (nom=0), no fields (nof=0), and low lines of code (loc=21). Its complexity is minimal (wmc=0, lcom=-1). There is no indication that further decomposition would reduce size or complexity.
A7: byte-buddy | B7: net.bytebuddy.agent.builder_AgentBuilder.Appender.txt | D7: class | E7: net.bytebuddy.agent.builder.AgentBuilder.Appender | F7: 0 | G7: The class has only 1 field, 0 methods, and 22 lines of code, indicating minimal size and complexity. With no methods (WMC=0) and a single responsibility suggested by its name, further decomposition is unlikely to reduce size or complexity.
A8: byte-buddy | B8: net.bytebuddy.agent.builder_AgentBuilder.Asynchronous.txt | D8: class | E8: net.bytebuddy.agent.builder.AgentBuilder.Asynchronous | F8: 0 | G8: The class has 0 methods (nom=0, nopm=0) and 0 complexity (wmc=0), indicating no behavioral complexity to decompose. The 8 fields (nof=8) and 141 lines of code (loc=141) may represent a data container with extensive comments or formatting, but further decomposition is unlikely to reduce complexity or size significantly given the absence of methods.
A9: byte-buddy | B9: net.bytebuddy.agent.builder_AgentBuilder.AtFixedRate.txt | D9: class | E9: net.bytebuddy.agent.builder.AgentBuilder.AtFixedRate | F9: 0 | G9: The class has no methods (nom=0) and zero complexity (wmc=0), with only three fields (nof=3). Although loc=40 is moderate, there is no evidence of multiple responsibilities or that further decomposition would reduce size or complexity.
A10: byte-buddy | B10: net.bytebuddy.agent.builder_AgentBuilder.BatchAllocator.txt | D10: class | E10: net.bytebuddy.agent.builder.AgentBuilder.BatchAllocator | F10: 1 | G10: The class has 370 lines of code and 14 fields with no methods, indicating a large data structure that could be decomposed. The high field count (nof=14) and substantial code size (loc=370) without behavioral methods suggest insufficient decomposition of responsibilities.
A11: byte-buddy | B11: net.bytebuddy.agent.builder_AgentBuilder.BatchReallocator.txt | D11: class | E11: net.bytebuddy.agent.builder.AgentBuilder.BatchReallocator | F11: 0 | G11: Class has minimal complexity with 0 methods (nom=0, nopm=0), only 1 field (nof=1), and low size (loc=26). No methods exist to decompose, and the single field suggests the class already represents a minimal cohesive unit.
A12: byte-buddy | B12: net.bytebuddy.agent.builder_AgentBuilder.BootstrapMarkerAction.txt | D12: class | E12: net.bytebuddy.agent.builder.AgentBuilder.BootstrapMarkerAction | F12: 0 | G12: The class has no methods (nom=0) and no fields (nof=0), with low lines of code (loc=13) and zero weighted methods per class (wmc=0). This indicates minimal size and complexity, so further decomposition is not warranted.
A13: byte-buddy | B13: net.bytebuddy.agent.builder_AgentBuilder.BridgeMethodImplementation.txt | D13: class | E13: net.bytebuddy.agent.builder.AgentBuilder.BridgeMethodImplementation | F13: 1 | G13: The class has 56 lines of code (loc) but 0 methods (nom). A class with significant size (loc) and no methods suggests that its functionality is not decomposed into discrete, reusable units. This indicates insufficient modularization, as the class likely contains inline or monolithic code that could be broken down into methods to reduce size and complexity.
... A5413: zxing | B5413: com.google.zxing_WriterException.txt | D5413: class | E5413: com.google.zxing.WriterException | F5413: 0 | G5413: Class has minimal complexity with only 3 methods, 14 lines of code, and 0 fields. All methods are public, indicating a simple exception class. No dependencies suggest it is already a focused, single-responsibility unit.

Sheet qwen
A1: project | B1: file_name | C1: smell | D1: entity_type | E1: entity | F1: detection | G1: justification
A2: byte-buddy | B2: (default package).MavenWrapperDownloader | D2: class | E2: (default package).MavenWrapperDownloader | F2: 0 | G2: The class has reasonable size (93 loc) and complexity (WMC=12) for its functionality. With 6 methods and 6 fields, the class maintains a cohesive structure. The LCOM value of 0.833 suggests good cohesion within the class. The absence of dependencies and fan-in/fan-out indicates it's a self-contained utility class, which is appropriately modularized for its purpose as a Maven wrapper downloader.
A3: byte-buddy | B3: com.service.definition.ServiceDefinition | D3: class | E3: com.service.definition.ServiceDefinition | F3: 0 | G3: The class has only 1 method (nom=1, wmc=1), 0 fields (nof=0), and very low complexity (loc=3). The minimal size and complexity indicate sufficient modularization has been achieved.
A4: byte-buddy | B4: com.service.usage2.ServiceImplementation | D4: class | E4: com.service.usage2.ServiceImplementation | F4: 0 | G4: The class has only 1 method (nom=1, nopm=1), 5 lines of code (loc=5), and minimal complexity (wmc=1). With such a small size and low complexity, the class does not exhibit insufficient modularization as it is already sufficiently decomposed.
A5: byte-buddy | B5: com.service.usage.ServiceImplementation | D5: class | E5: com.service.usage.ServiceImplementation | F5: 0 | G5: The class has only 1 method (nom=1, nopm=1), 5 lines of code (loc=5), and no fields (nof=0, nopf=0). The low complexity metrics (wmc=1) and minimal size indicate this class is already sufficiently modularized and does not require further decomposition.
A6: byte-buddy | B6: net.bytebuddy.agent.builder.AgentBuilder.Adapter | D6: class | E6: net.bytebuddy.agent.builder.AgentBuilder.Adapter | F6: 0 | G6: The class has very low complexity with only 21 lines of code, 0 methods, 0 fields, and 0 weighted method count. The class appears to be a simple adapter implementation that does not exhibit signs of insufficient modularization. There is no evidence of excessive size or implementation complexity that would warrant further decomposition.
A7: byte-buddy | B7: net.bytebuddy.agent.builder.AgentBuilder.Appender | D7: class | E7: net.bytebuddy.agent.builder.AgentBuilder.Appender | F7: 0 | G7: The class has very low complexity with only 1 field (nof=1), 0 methods (nom=0), 22 lines of code (loc=22), and weighted method count of 0 (wmc=0). The low number of fields and methods indicates minimal implementation complexity that does not warrant further decomposition. The class appears to be a simple data holder or minimal implementation that does not exhibit the characteristics of insufficient modularization.
A8: byte-buddy | B8: net.bytebuddy.agent.builder.AgentBuilder.Asynchronous | D8: class | E8: net.bytebuddy.agent.builder.AgentBuilder.Asynchronous | F8: 0 | G8: The class has only 8 fields (nof=8) and 0 methods (nom=0), with a relatively small size of 141 lines of code (loc=141). The lack of methods (wmc=0, nopm=0) and minimal complexity indicators suggest this is likely a simple data holder or configuration class rather than a complex class suffering from insufficient modularization. The class does not exhibit high complexity or size that would indicate a need for further decomposition.
A9: byte-buddy | B9: net.bytebuddy.agent.builder.AgentBuilder.AtFixedRate | D9: class | E9: net.bytebuddy.agent.builder.AgentBuilder.AtFixedRate | F9: 0 | G9: The class has very low complexity with only 3 fields (nof=3), 0 methods (nom=0), 40 lines of code (loc=40), and 0 weighted method count (wmc=0). The low number of fields and absence of methods indicate minimal implementation complexity that does not warrant further decomposition. The class appears to be a simple data holder or configuration class rather than a complex class requiring modularization.
A10: byte-buddy | B10: net.bytebuddy.agent.builder.AgentBuilder.BatchAllocator | D10: class | E10: net.bytebuddy.agent.builder.AgentBuilder.BatchAllocator | F10: 1 | G10: The class has 14 fields (nof=14) and 370 lines of code (loc=370), indicating high size and complexity. The lack of methods (nom=0) suggests potential issues with decomposition. With 3 dependencies and significant size, the class likely contains multiple responsibilities that could be separated into smaller, more focused modules.
A11: byte-buddy | B11: net.bytebuddy.agent.builder.AgentBuilder.BatchReallocator | D11: class | E11: net.bytebuddy.agent.builder.AgentBuilder.BatchReallocator | F11: 0 | G11: The class has very low complexity with only 1 field (nof=1), 0 methods (nom=0, wmc=0), 26 lines of code (loc=26), and no dependencies (fanin=0, fanout=0). The class appears to be a simple data holder or configuration class with minimal functionality that does not warrant further decomposition. No signs of insufficient modularization are present given the minimal scope and complexity of this class.
A12: byte-buddy | B12: net.bytebuddy.agent.builder.AgentBuilder.BootstrapMarkerAction | D12: class | E12: net.bytebuddy.agent.builder.AgentBuilder.BootstrapMarkerAction | F12: 0 | G12: The class has very low complexity with only 13 lines of code, 0 methods, 0 fields, and WMC of 0. The lack of methods and fields indicates minimal functionality that does not warrant further decomposition. The class appears to be a simple marker or configuration class rather than a complex entity requiring modularization.
A13: byte-buddy | B13: net.bytebuddy.agent.builder.AgentBuilder.BridgeMethodImplementation | D13: class | E13: net.bytebuddy.agent.builder.AgentBuilder.BridgeMethodImplementation | F13: 0 | G13: The class has low complexity with only 3 fields (nof=3), 0 methods (nom=0), 56 lines of code (loc=56), and weighted method count of 0 (wmc=0). The lack of methods and low field count indicate minimal implementation complexity that does not warrant further decomposition.
... A475: byte-buddy | B475: net.bytebuddy.asm.MemberSubstitution.Source | D475: class | E475: net.bytebuddy.asm.MemberSubstitution.Source | F475: 0 | G475: The class has only 2 fields (nof=2), no methods (nom=0, wmc=0), and relatively low lines of code (loc=162). The lack of methods and low field count indicate it is already well-decomposed and does not exhibit insufficient modularization.
A476: byte-buddy | B476: net.bytebuddy.asm.MemberSubstitution.Step | C476: insufficient_modularization | D476: class | E476: MemberSubstitution.Step | G476: ```json_x000D_ {_x000D_ "class": "net.bytebuddy.asm.MemberSubstitution.Step",_x000D_ "detection": true,_x000D_ "justification": "The class has 191 fields (nof=191) and 4013 lines of code (loc=4013), indicating excessive size and complexity for a single class. The
A477: byte-buddy | B477: net.bytebuddy.asm.MemberSubstitution.Stubbing | D477: class | E477: net.bytebuddy.asm.MemberSubstitution.Stubbing | F477: 0 | G477: The class has very low complexity with only 23 lines of code (loc), zero methods (nom), zero fields (nof), and zero weighted method count (wmc). The low size and complexity metrics indicate that further decomposition would not provide significant benefits for reducing size or implementation complexity.
A478: byte-buddy | B478: net.bytebuddy.asm.MemberSubstitution.SubstitutingMethodVisitor | D478: class | E478: net.bytebuddy.asm.MemberSubstitution.SubstitutingMethodVisitor | F478: 0 | G478: The class has 12 fields (nof=12) and 234 lines of code (loc=234), which indicates a moderate size. With 0 methods (nom=0) and 0 public methods (nopm=0), the class appears to be a specialized visitor implementation. The low number of methods relative to fields suggests it may be a data-focused class rather than a behaviorally complex one. While the LOC count is somewhat high, the metrics do not clearly indicate insufficient modularization as the class seems to serve a specific focused purpose within the ASM framework.
A479: byte-buddy | B479: net.bytebuddy.asm.MemberSubstitution.Substitution | D479: class | E479: net.bytebuddy.asm.MemberSubstitution.Substitution | F479: 1 | G479: The class has 215 fields and 4607 lines of code, indicating excessive size and complexity for a single class. The high number of dependencies (23 external types) suggests it has too many responsibilities and could benefit from decomposition into smaller, more focused classes. The lack of methods (0) despite having many fields indicates poor encapsulation and design, supporting the presence of Insufficient Modularization.
A480: byte-buddy | B480: net.bytebuddy.asm.MemberSubstitution.Target | D480: class | E480: net.bytebuddy.asm.MemberSubstitution.Target | F480: 0 | G480: The class has only 5 fields (nof=5) and 0 methods (nom=0), with 117 lines of code (loc=117). While the LOC is relatively high for the number of methods, this appears to be a data class or value object that holds member substitution target information. The lack of methods (wmc=0) and simple structure without complex behavior does not indicate insufficient modularization - it's appropriately simple for its purpose.
A481: byte-buddy | B481: net.bytebuddy.asm.MemberSubstitution.TypePoolResolver | D481: class | E481: net.bytebuddy.asm.MemberSubstitution.TypePoolResolver | F481: 0 | G481: The class has only 3 fields (nof=3) and 0 methods (nom=0), with a relatively small size of 91 lines of code (loc=91). The lack of methods (wmc=0) and simple field structure suggests it is already well-decomposed and does not exhibit complexity that would warrant further modularization. The class appears to be a simple data holder or configuration class rather than a complex entity requiring decomposition.
A482: byte-buddy | B482: net.bytebuddy.asm.MemberSubstitution.Unbound | D482: class | E482: net.bytebuddy.asm.MemberSubstitution.Unbound | F482: 0 | G482: The class has very low complexity with only 2 fields, 0 methods, and 28 lines of code. The Weighted Methods per Class (wmc) is 0, indicating minimal implementation complexity. With such low size and complexity metrics, further decomposition would not provide meaningful benefits for reducing size or implementation complexity.
A483: byte-buddy | B483: net.bytebuddy.asm.MemberSubstitution.Unresolved | D483: class | E483: net.bytebuddy.asm.MemberSubstitution.Unresolved | F483: 0 | G483: The class has very low complexity with 0 methods (nom=0, nopm=0), 0 fields (nof=0, nopf=0), and only 19 lines of code (loc=19). The weighted method count is 0 (wmc=0) and there are no dependencies on other classes (fanout=0). This indicates a minimal, focused class that does not exhibit signs of insufficient modularization as it is already highly decomposed.
A484: byte-buddy | B484: net.bytebuddy.asm.MemberSubstitution.Value | D484: class | E484: net.bytebuddy.asm.MemberSubstitution.Value | F484: 0 | G484: The class has very low complexity with 0 methods (nom=0, nopm=0), 0 lines of code (loc=36 but this appears to be the file loc not class loc), and 0 weighted method count (wmc=0). The lack of methods and low complexity indicates insufficient data to determine insufficient modularization, and the class appears to be a simple value object or data holder that does not require further decomposition.
A485: byte-buddy | B485: net.bytebuddy.asm.MemberSubstitution.WithCustomMapping | D485: class | E485: net.bytebuddy.asm.MemberSubstitution.WithCustomMapping | F485: 1 | G485: The class has a high Lines of Code (LOC) value of 402, which indicates it is quite large and potentially complex. With only 2 fields (nof=2) and no methods (nom=0), the class appears to have insufficient internal structure and decomposition. The high LOC combined with minimal internal elements suggests the class could benefit from further modularization to reduce its size and implementation complexity.
A486: byte-buddy | B486: net.bytebuddy.asm.MemberSubstitution.WithExplicitType | D486: class | E486: net.bytebuddy.asm.MemberSubstitution.WithExplicitType | F486: 0 | G486: The class has very low complexity with only 1 field (nof=1), 0 methods (nom=0), 25 lines of code (loc=25), and minimal coupling metrics (wmc=0, nc=0, fanin=0, fanout=0). The low number of fields and methods indicates it is already well decomposed and does not exhibit insufficient modularization.
A487: byte-buddy | B487: net.bytebuddy.asm.MemberSubstitution.WithImplicitType | D487: class | E487: net.bytebuddy.asm.MemberSubstitution.WithImplicitType | F487: 0 | G487: The class has very low complexity with only 16 lines of code (loc), zero methods (nom), zero fields (nof), and zero weighted method count (wmc). The lack of methods and fields indicates minimal implementation complexity that does not warrant further decomposition. While the class has dependencies on 4 external classes, this represents typical usage patterns rather than insufficient modularization since the class itself remains simple and focused.
