Workbook

Sheet samples
A1: project | B1: smell | C1: package | D1: class | E1: fqn | F1: prompt_file | G1: context_size | H1: designite | I1: gpt | J1: deepseek | K1: qwen
A2: javaparser | B2: Insufficient Modularization | C2: com.github.javaparser.symbolsolver.javaparsermodel.contexts | D2: AnonymousClassDeclarationContext | E2: =C2&"."&D2 -> com.github.javaparser.symbolsolver.javaparsermodel.contexts.AnonymousClassDeclarationContext | F2: data/processed/prompts/insufficient_modularization/javaparser/com_github_javaparser_symbolsolver_javaparsermodel_contexts_AnonymousClassDeclarationContext.txt | G2: 1965 | H2: 0 | I2: =VLOOKUP(E2,gpt!$D$2:$E$361,2,0) -> 0 | J2: =VLOOKUP(E2,deepseek!$D$2:$E$361,2,0) -> 0 | K2: =VLOOKUP(E2,qwen!$D$2:$E$361,2,0) -> 0
A3: byte-buddy | B3: Insufficient Modularization | C3: net.bytebuddy.dynamic.DynamicType | D3: Initial | E3: =C3&"."&D3 -> net.bytebuddy.dynamic.DynamicType.Initial | F3: data/processed/prompts/insufficient_modularization/byte-buddy/net_bytebuddy_dynamic_DynamicType_Initial.txt | G3: 63017 | H3: 0 | I3: =VLOOKUP(E3,gpt!$D$2:$E$361,2,0) -> 1 | J3: =VLOOKUP(E3,deepseek!$D$2:$E$361,2,0) -> 1 | K3: =VLOOKUP(E3,qwen!$D$2:$E$361,2,0) -> 1
A4: javaparser | B4: Insufficient Modularization | C4: com.packageName | D4: ClassInPackage | E4: =C4&"."&D4 -> com.packageName.ClassInPackage | F4: data/processed/prompts/insufficient_modularization/javaparser/com_packageName_ClassInPackage.txt | G4: 310 | H4: 0 | I4: =VLOOKUP(E4,gpt!$D$2:$E$361,2,0) -> 0 | J4: =VLOOKUP(E4,deepseek!$D$2:$E$361,2,0) -> 0 | K4: =VLOOKUP(E4,qwen!$D$2:$E$361,2,0) -> 0
A5: byte-buddy | B5: Insufficient Modularization | C5: net.bytebuddy.description.type.TypeList | D5: Empty | E5: =C5&"."&D5 -> net.bytebuddy.description.type.TypeList.Empty | F5: data/processed/prompts/insufficient_modularization/byte-buddy/net_bytebuddy_description_type_TypeList_Empty.txt | G5: 7014 | H5: 0 | I5: =VLOOKUP(E5,gpt!$D$2:$E$361,2,0) -> 0 | J5: =VLOOKUP(E5,deepseek!$D$2:$E$361,2,0) -> 0 | K5: =VLOOKUP(E5,qwen!$D$2:$E$361,2,0) -> 0
A6: byte-buddy | B6: Insufficient Modularization | C6: net.bytebuddy.description.type.RecordComponentDescription | D6: InDefinedShape | E6: =C6&"."&D6 -> net.bytebuddy.description.type.RecordComponentDescription.InDefinedShape | F6: data/processed/prompts/insufficient_modularization/byte-buddy/net_bytebuddy_description_type_RecordComponentDescription_InDefinedShape.txt | G6: 3789 | H6: 0 | I6: =VLOOKUP(E6,gpt!$D$2:$E$361,2,0) -> 0 | J6: =VLOOKUP(E6,deepseek!$D$2:$E$361,2,0) -> 0 | K6: =VLOOKUP(E6,qwen!$D$2:$E$361,2,0) -> 0
A7: commons-io | B7: Insufficient Modularization | C7: org.apache.commons.io | D7: CloseableURLConnection | E7: =C7&"."&D7 -> org.apache.commons.io.CloseableURLConnection | F7: data/processed/prompts/insufficient_modularization/commons-io/org_apache_commons_io_CloseableURLConnection.txt | G7: 1768 | H7: 1 | I7: =VLOOKUP(E7,gpt!$D$2:$E$361,2,0) -> 0 | J7: =VLOOKUP(E7,deepseek!$D$2:$E$361,2,0) -> 0 | K7: =VLOOKUP(E7,qwen!$D$2:$E$361,2,0) -> 0
A8: byte-buddy | B8: Insufficient Modularization | C8: net.bytebuddy.implementation.bind.MethodDelegationBinder | D8: Compound | E8: =C8&"."&D8 -> net.bytebuddy.implementation.bind.MethodDelegationBinder.Compound | F8: data/processed/prompts/insufficient_modularization/byte-buddy/net_bytebuddy_implementation_bind_MethodDelegationBinder_Compound.txt | G8: 7950 | H8: 0 | I8: =VLOOKUP(E8,gpt!$D$2:$E$361,2,0) -> 1 | J8: =VLOOKUP(E8,deepseek!$D$2:$E$361,2,0) -> 1 | K8: =VLOOKUP(E8,qwen!$D$2:$E$361,2,0) -> 0
A9: zxing | B9: Insufficient Modularization | C9: com.google.zxing | D9: ResultPointCallback | E9: =C9&"."&D9 -> com.google.zxing.ResultPointCallback | F9: data/processed/prompts/insufficient_modularization/zxing/com_google_zxing_ResultPointCallback.txt | G9: 478 | H9: 0 | I9: =VLOOKUP(E9,gpt!$D$2:$E$361,2,0) -> 0 | J9: =VLOOKUP(E9,deepseek!$D$2:$E$361,2,0) -> 0 | K9: =VLOOKUP(E9,qwen!$D$2:$E$361,2,0) -> 0
A10: byte-buddy | B10: Insufficient Modularization | C10: net.bytebuddy.dynamic.scaffold.inline | D10: MethodRebaseResolver | E10: =C10&"."&D10 -> net.bytebuddy.dynamic.scaffold.inline.MethodRebaseResolver | F10: data/processed/prompts/insufficient_modularization/byte-buddy/net_bytebuddy_dynamic_scaffold_inline_MethodRebaseResolver.txt | G10: 4015 | H10: 0 | I10: =VLOOKUP(E10,gpt!$D$2:$E$361,2,0) -> 1 | J10: =VLOOKUP(E10,deepseek!$D$2:$E$361,2,0) -> 0 | K10: =VLOOKUP(E10,qwen!$D$2:$E$361,2,0) -> 0
A11: byte-buddy | B11: Insufficient Modularization | C11: net.bytebuddy.implementation.bytecode.assign.primitive.PrimitiveUnboxingDelegate | D11: UnboxingResponsible | E11: =C11&"."&D11 -> net.bytebuddy.implementation.bytecode.assign.primitive.PrimitiveUnboxingDelegate.UnboxingResponsible | F11: data/processed/prompts/insufficient_modularization/byte-buddy/net_bytebuddy_implementation_bytecode_assign_primitive_PrimitiveUnboxingDelegate_UnboxingResponsible.txt | G11: 2922 | H11: 0 | I11: =VLOOKUP(E11,gpt!$D$2:$E$361,2,0) -> 0 | J11: =VLOOKUP(E11,deepseek!$D$2:$E$361,2,0) -> 0 | K11: =VLOOKUP(E11,qwen!$D$2:$E$361,2,0) -> 0
A12: jitwatch | B12: Insufficient Modularization | C12: (default package) | D12: ElisionTest | E12: =C12&"."&D12 -> (default package).ElisionTest | F12: data/processed/prompts/insufficient_modularization/jitwatch/(default package)_ElisionTest.txt | G12: 408 | H12: 0 | I12: =VLOOKUP(E12,gpt!$D$2:$E$361,2,0) -> 0 | J12: =VLOOKUP(E12,deepseek!$D$2:$E$361,2,0) -> 0 | K12: =VLOOKUP(E12,qwen!$D$2:$E$361,2,0) -> 0
A13: byte-buddy | B13: Insufficient Modularization | C13: net.bytebuddy | D13: NamingStrategy | E13: =C13&"."&D13 -> net.bytebuddy.NamingStrategy | F13: data/processed/prompts/insufficient_modularization/byte-buddy/net_bytebuddy_NamingStrategy.txt | G13: 4573 | H13: 0 | I13: =VLOOKUP(E13,gpt!$D$2:$E$361,2,0) -> 0 | J13: =VLOOKUP(E13,deepseek!$D$2:$E$361,2,0) -> 0 | K13: =VLOOKUP(E13,qwen!$D$2:$E$361,2,0) -> 0
... A361: byte-buddy | B361: Insufficient Modularization | C361: net.bytebuddy.implementation.FieldAccessor | D361: PropertyConfigurable | E361: =C361&"."&D361 -> net.bytebuddy.implementation.FieldAccessor.PropertyConfigurable | F361: data/processed/prompts/insufficient_modularization/byte-buddy/net_bytebuddy_implementation_FieldAccessor_PropertyConfigurable.txt | G361: 11291 | H361: 0 | I361: =VLOOKUP(E361,gpt!$D$2:$E$361,2,0) -> 1 | J361: =VLOOKUP(E361,deepseek!$D$2:$E$361,2,0) -> 1 | K361: =VLOOKUP(E361,qwen!$D$2:$E$361,2,0) -> 1

Sheet gpt
A1: file_name | B1: smell | C1: entity_type | D1: entity | E1: detection | F1: justification
A2: (default package)_ElisionTest.txt | B2: Insufficient Modularization | C2: class | D2: (default package).ElisionTest | E2: 0 | F2: ElisionTest is small and cohesive: it defines only two methods (the constructor and main) and no instance fields. The constructor contains a single, simple workflow (create a Vector<Long>, populate it in a loop, compute a sum in a loop, print the result). There is no large class interface, no mix of unrelated responsibilities, and no excessive size or complexity that would warrant decomposition. All state is local to the constructor (local variables: vector, sum, loop indices), so there is no evidence of a bloated class or multiple responsibilities requiring modularization.
A3: (default package)_InnerClassDotExpressions_InnerClass.txt | B3: Insufficient Modularization | C3: class | D3: (default package).InnerClassDotExpressions.InnerClass | E3: 0 | F3: ['Classes are very small and focused: each nested class defines a single static method returning a simple string, indicating single responsibility and low complexity (InnerClass.methodCall, InnerInnerClass.innerMethodCall, InnerInnerInnerClass.innerInnerMethodCall).', 'No large methods, long interfaces, or many fields are present that would indicate a bloated abstraction or excessive responsibilities.', 'Nesting depth alone does not imply insufficient modularization; the nested classes do not accumulate unrelated functionality and are invoked only to return simple values (as shown by InnerClassDotExpressions.main).', 'Static methods reduce coupling to outer instances, and there is no evidence of tangled responsibilities or difficulty in understanding/maintaining a single oversized class.']
A4: (default package)_MegamorphicBypass_Quarter.txt | B4: Insufficient Modularization | C4: class | D4: (default package).MegamorphicBypass.Quarter | E4: 0 | F4: ['Quarter is a very small, cohesive class: it implements a single method deposit() that performs one simple action (moneyBox += 25).', 'It does not have a large interface, many fields, or multiple responsibilities to indicate poor decomposition.', 'There is no internal complexity, branching, or size that would suggest the class should be split into smaller abstractions.', 'Although it is an inner class and references the outer static moneyBox, that coupling does not make Quarter bloated or multi-responsibility; its behavior remains narrowly focused.']
A5: (default package)_PolymorphismTest_Quarter.txt | B5: Insufficient Modularization | C5: class | D5: (default package).PolymorphismTest.Quarter | E5: 0 | F5: Quarter is a small, focused inner class that implements the Coin interface with a single method deposit() which increments the static moneyBox by 25. It has one clear responsibility, a minimal interface (no extra fields or methods), and low complexity/size. There is no evidence of a bloated interface, multiple unrelated responsibilities, or excessive size in this class, so Insufficient Modularization is not present.
A6: (default package)_TestInner.txt | B6: Insufficient Modularization | C6: class | D6: (default package).TestInner | E6: 0 | F6: ['The class is small and simple: TestInner has only one public method a(), a constructor, and two nested inner classes (Inner1 and Inner2) that further break behavior into smaller units. Methods a(), b(), and c() are single-purpose print methods with no complex logic or large interfaces. There are no many fields or responsibilities concentrated in TestInner itself; nested classes indicate decomposition rather than a bloated monolith. Therefore it does not exhibit insufficient modularization.']
A7: a_b_c_ExampleClass.txt | B7: Insufficient Modularization | C7: class | D7: a.b.c.ExampleClass | E7: 0 | F7: The class is minimal and not a bloated abstraction: it declares a single field (protected final DataObjectFactory doFactory), a constructor (which sets doFactory = null), and one method (getDataObject) that simply delegates to doFactory.getDataObject(objectID). There are no many unrelated methods, no large state, and no large or complex interface that would indicate an insufficient decomposition. Therefore it does not exhibit Insufficient Modularization.
A8: com_github_javaparser_GeneratedJavaParserBase.txt | B8: Insufficient Modularization | C8: class | D8: com.github.javaparser.GeneratedJavaParserBase | E8: 1 | F8: ['GeneratedJavaParserBase accumulates many distinct responsibilities in one class, indicating insufficient modularization. Examples include: token/token-range management (methods: token(), tokenRange(), range(...), orIfInvalid(...), nodeListBegin(...), setTokenKind(...), setStoreTokens(...)); parser recovery and error reporting (recover(...), recoverStatement(...), addProblem(...), problems field, makeMessageForParseException(...)); AST construction and transformation helpers (generateLambda(...), juggleArrayCreation(...), juggleArrayType(...), scopeToName(...)); small utility/string helpers (unquote(...), unTripleQuote(...)); and propagation of token-range changes (propagateRangeGrowthOnRight(...)).', "The class mixes parsing control flow, token management, error-message formatting, and AST-building logic rather than delegating those concerns to cohesive helper/strategy classes. This leads to a large surface area (many unrelated methods and state like 'problems' and 'storeTokens'), reduced cohesion, and harder maintainability and testability.", 'Many methods are natural extraction targets (e.g., RecoveryHandler for recover/recoverStatement and makeMessageForParseException, TokenRangeUtils/TokenAdapter for token and range helpers, ASTBuilderHelpers for generateLambda/juggleArray* and scopeToName, and StringLiteralUtils for unquote/unTripleQuote), which supports the conclusion that the current class is not adequately decomposed.']
A9: com_github_javaparser_GeneratedJavaParserTokenManager.txt | B9: Insufficient Modularization | C9: class | D9: com.github.javaparser.GeneratedJavaParserTokenManager | E9: 1 | F9: ['Class size and density: the class contains a very large amount of code including many long methods (e.g. jjMoveNfa_0, getNextToken, many jjMoveStringLiteralDfaX methods) and dozens of large static arrays (jjbitVec0..jjbitVec93, jjstrLiteralImages, jjnextStates, jjtoToken, jjtoSkip, etc.), indicating a single monolithic unit rather than multiple focused classes.', 'Multiple responsibilities concentrated in one class: it handles token production (getNextToken, jjFillToken), lexical state management (curLexState, SwitchTo, ReInit), DFA/NFA transition logic (jjMoveStringLiteralDfa*, jjMoveNfa_0, jjCanMove_*), token actions and skipping (TokenLexicalActions, SkipLexicalActions, MoreLexicalActions), and comment/markdown parsing and storage (createMarkdownComment, CommonTokenAction, commentsCollection, markdownCommentTokens). These are distinct concerns that would be better modularized.', 'Large, low-level data + behavior coupling: DFA tables and bitvectors are declared and used directly inside the class (many jjbitVec arrays and next-state tables), coupling huge static data with parsing logic rather than separating a generated automaton/data from token-management and comment-processing logic.', 'Complex internal state and many helper methods: numerous private helper methods and state variables (jjrounds, jjstateSet, jjimage, image, jjimageLen, lengthOfMatch, curChar, etc.) make the class difficult to understand and maintain, which is symptomatic of insufficient decomposition into smaller, more cohesive classes.', 'Missed opportunities for decomposition: identifiable subsystems (automaton engine, token storage & comment collection, markdown comment assembly, lexical-action handlers) are all implemented in the same class rather than split into focused classes or modules, increasing cognitive load and reducing maintainability.']
A10: com_github_javaparser_JavaToken_Kind.txt | B10: Insufficient Modularization | C10: class | D10: com.github.javaparser.JavaToken.Kind | E10: 0 | F10: Although JavaToken.Kind contains a very large number of enum constants and a large generated valueOf switch, it represents a single cohesive abstraction (the set of token kinds). Its methods are few and focused (valueOf, isPrimitive, getKind) and are directly related to the enum's responsibility. The large size is due to the number of tokens (and generated code), not because the class mixes unrelated responsibilities or contains multiple orthogonal concerns, so it does not exhibit insufficient modularization.
A11: com_github_javaparser_Range.txt | B11: Insufficient Modularization | C11: class | D11: com.github.javaparser.Range | E11: 0 | F11: The Range class is small and cohesive: it encapsulates two Position fields (begin,end) and provides only range-related operations (constructors/factories, withX copy helpers, contains/strictlyContains/overlapsWith/isBefore/isAfter comparisons, equals/hashCode/toString, getLineCount). Fields are final and the class does not mix unrelated responsibilities (no I/O, parsing, or other domain logic). The public API surface is appropriate for the abstraction and methods are directly related to representing and querying a textual range, so there is no evidence of excessive size, complexity, or concentrated unrelated responsibilities that would indicate insufficient modularization.
A12: com_github_javaparser_ast_Node_DirectChildrenIterator.txt | B12: Insufficient Modularization | C12: class | D12: com.github.javaparser.ast.Node.DirectChildrenIterator | E12: 1 | F12: ['The class aggregates many distinct responsibilities: AST state (range, tokenRange, parent/children), comment/orphan comment management, observer registration/propagation, arbitrary data storage (DataKey map), printing/printer-configuration, symbol resolution linkage, phantom-node detection/caching, traversal APIs and iterator implementations, and visitor/clone/equals/hashCode delegation.', 'Multiple unrelated concerns are implemented in the same class: printer creation and configuration (getPrinter, createDefaultPrinter, PRINTER_KEY), symbol resolution access (SYMBOL_RESOLVER_KEY and getSymbolResolver), and line-ending configuration (LINE_SEPARATOR_KEY and getLineEndingStyle), which couple I/O/formatting configuration to the AST model.', 'Traversal logic and algorithms are embedded as several nested iterator classes (BreadthFirstIterator, DirectChildrenIterator, ParentsVisitor, PreOrderIterator, PostOrderIterator with Level helper), inflating the class and mixing traversal mechanics with node state.', 'Observer management (ObserverRegistrationMode, register/registerForSubtree, PropagatingAstObserver usage) and child lifecycle methods (setParentNode, setAsParentNodeOf, remove/replace) together enlarge the public surface and violate single-responsibility principles.', 'Specialized utilities such as phantom detection (PHANTOM_KEY, isPhantom, inPhantomNode, LEVELS_TO_EXPLORE) and data-key manipulation further demonstrate orthogonal concerns present in one monolithic class, making it hard to understand, maintain, and evolve.']
A13: com_github_javaparser_ast_body_AnnotationMemberDeclaration.txt | B13: Insufficient Modularization | C13: class | D13: com.github.javaparser.ast.body.AnnotationMemberDeclaration | E13: 0 | F13: The class is cohesive and focused on a single responsibility: representing an annotation member in the AST. It only holds a small set of related fields (modifiers, type, name, defaultValue) and implements node/visitor/resolution interfaces that are appropriate for AST nodes; the many methods are generated property accessors, mutators, visitor/clone/replace/remove helpers and notification/parenting logic rather than unrelated functionality. There is no evidence of many unrelated responsibilities, large unrelated code blocks, or a bloated interface — the implemented interfaces and methods are directly relevant to the node role, so insufficient modularization is not present.
... A361: org_tensorflow_op_Ops.txt | B361: Insufficient Modularization | C361: class | D361: org.tensorflow.op.Ops | E361: 1 | F361: ['The Ops class provides a very large, monolithic API surface exposing hundreds of public factory methods for many unrelated operations (examples: constant(...), assign(...), reshape(...), gather(...), scatterNd(...), tensorArray..., resourceScatter..., etc.).', 'It imports and directly delegates to a huge number of operation classes (many org.tensorflow.op.core.* and other op packages) and centralizes creation logic via a single Scope instance, concentrating many responsibilities that span math, io, image, linalg, random, signal, train, quantization, and more.', 'Although it declares subgroup fields (nn, summary, image, data, io, ...), the class still contains an excessively large flat set of methods rather than cleanly partitioning functionality into cohesive modules. The size and breadth of the class (and its bloated public interface) make it hard to understand, maintain, and evolve — matching the Insufficient Modularization smell.']

Sheet deepseek
A1: file_name | B1: smell | C1: entity_type | D1: entity | E1: detection | F1: justification
A2: (default package)_ElisionTest.txt | B2: Insufficient Modularization | C2: class | D2: (default package).ElisionTest | E2: 0 | F2: The class is small (under 30 lines), has a single constructor performing a simple benchmark task, and a minimal main method. It demonstrates a single, focused responsibility without excessive complexity, bloated interface, or multiple concerns that need decomposition.
A3: (default package)_InnerClassDotExpressions_InnerClass.txt | B3: Insufficient Modularization | C3: class | D3: (default package).InnerClassDotExpressions.InnerClass | E3: 0 | F3: The class is small, focused on demonstrating nested class access patterns, and does not exhibit excessive size, complexity, or bloated interface. The nested structure is intentional for the example's purpose, not due to inadequate decomposition of responsibilities.
A4: (default package)_MegamorphicBypass_Quarter.txt | B4: Insufficient Modularization | C4: class | D4: (default package).MegamorphicBypass.Quarter | E4: 1 | F4: The class combines multiple responsibilities: it defines three distinct Coin implementations (Nickel, Dime, Quarter), manages a static moneyBox state, contains complex constructor logic with performance optimization patterns, and includes a main method. These unrelated concerns should be separated into dedicated classes for each coin type, a money box manager, and a separate performance test harness.
A5: (default package)_PolymorphismTest_Quarter.txt | B5: Insufficient Modularization | C5: class | D5: (default package).PolymorphismTest.Quarter | E5: 1 | F5: The class combines multiple responsibilities: it defines a Coin interface, implements three distinct coin types (Nickel, Dime, Quarter), contains a static moneyBox variable, includes constructor logic for performance testing with polymorphic dispatch, and has a main method. These unrelated concerns (interface definition, multiple implementations, test harness, and application entry point) should be separated into cohesive modules.
A6: (default package)_TestInner.txt | B6: Insufficient Modularization | C6: class | D6: (default package).TestInner | E6: 0 | F6: The class demonstrates appropriate modularization through nested inner classes (Inner1 and Inner2), each with distinct, cohesive responsibilities. The outer class and inner classes are small, focused, and have minimal complexity. No single class exhibits excessive size, bloated interface, or concentration of unrelated responsibilities.
A7: a_b_c_ExampleClass.txt | B7: Insufficient Modularization | C7: class | D7: a.b.c.ExampleClass | E7: 0 | F7: The class is small, focused, and has a single responsibility. It contains only one field, one constructor, and one method. The class delegates its core functionality to DataObjectFactory, showing proper separation of concerns. There is no evidence of excessive size, complexity, or bloated interface.
A8: com_github_javaparser_GeneratedJavaParserBase.txt | B8: Insufficient Modularization | C8: class | D8: com.github.javaparser.GeneratedJavaParserBase | E8: 1 | F8: The class exhibits excessive size and complexity by combining multiple responsibilities: token management, error recovery, range calculation, node list manipulation, lambda expression generation, array creation, type juggling, and parse exception message formatting. It has a bloated interface with 30+ methods handling disparate concerns rather than being decomposed into smaller, cohesive abstractions.
A9: com_github_javaparser_GeneratedJavaParserTokenManager.txt | B9: Insufficient Modularization | C9: class | D9: com.github.javaparser.GeneratedJavaParserTokenManager | E9: 1 | F9: The class exhibits excessive size and complexity with over 3,900 lines of code, containing multiple responsibilities including token management, lexical analysis, comment processing, and state machine logic. It has a bloated interface with numerous private methods for DFA state transitions (jjMoveStringLiteralDfa* methods), token processing logic, and large static data arrays (jjbitVec*). The class lacks decomposition into cohesive abstractions, concentrating lexer generation, token handling, and comment collection in a single monolithic class.
A10: com_github_javaparser_JavaToken_Kind.txt | B10: Insufficient Modularization | C10: class | D10: com.github.javaparser.JavaToken.Kind | E10: 1 | F10: The class contains two large inner enums (Category and Kind) with 8 and 153 constants respectively, plus extensive enum methods. The Kind enum includes a 152-case switch statement for valueOf and other methods. The outer class also manages token list manipulation (insert, delete, replace), range/text handling, and token category logic, concentrating multiple responsibilities in one class.
A11: com_github_javaparser_Range.txt | B11: Insufficient Modularization | C11: class | D11: com.github.javaparser.Range | E11: 0 | F11: The class is small, focused, and cohesive, representing a single abstraction (a character range in source code). It has only two fields, a constructor, and a limited set of operations that are directly related to range manipulation (creation, modification, containment checks, and overlap detection). There is no evidence of excessive size, complexity, or a bloated interface.
A12: com_github_javaparser_ast_Node_DirectChildrenIterator.txt | B12: Insufficient Modularization | C12: class | D12: com.github.javaparser.ast.Node.DirectChildrenIterator | E12: 1 | F12: The Node class exhibits excessive size and complexity with over 1000 lines of code, combining multiple responsibilities including AST node representation, parent-child relationship management, visitor pattern implementation, observer pattern implementation, data storage, tree traversal algorithms, comment handling, range/position management, symbol resolution integration, and printing/formatting logic. It contains five inner iterator classes (BreadthFirstIterator, DirectChildrenIterator, ParentsVisitor, PreOrderIterator, PostOrderIterator) that could be separate classes, and handles diverse concerns from low-level data storage to high-level tree operations, resulting in a bloated interface with numerous public methods.
A13: com_github_javaparser_ast_body_AnnotationMemberDeclaration.txt | B13: Insufficient Modularization | C13: class | D13: com.github.javaparser.ast.body.AnnotationMemberDeclaration | E13: 0 | F13: The class has a single, well-defined responsibility representing an annotation member declaration. It maintains a small, cohesive interface with only four core properties (modifiers, type, name, defaultValue) and implements standard AST node interfaces. The class size is moderate, and all methods are directly related to managing its state and AST node behavior without excessive complexity or unrelated responsibilities.
... A361: org_tensorflow_op_Ops.txt | B361: Insufficient Modularization | C361: class | D361: org.tensorflow.op.Ops | E361: 0 | F361: The class delegates responsibilities to specialized subclasses (NnOps, MathOps, etc.) through composition, has a single primary responsibility of providing a unified API for TensorFlow operations, and follows the facade pattern to organize operations into logical groups rather than implementing all functionality directly.

Sheet qwen
A1: file_name | B1: smell | C1: entity_type | D1: entity | E1: detection | F1: justification
A2: (default package)_ElisionTest.txt | B2: Insufficient Modularization | C2: class | D2: (default package).ElisionTest | E2: 0 | F2: The class ElisionTest is a simple test class with a single responsibility - to demonstrate vector operations and synchronization elision. It contains only a constructor with straightforward logic and a main method for execution. The class is small, focused, and does not exhibit excessive size, complexity, or a bloated interface that would indicate insufficient modularization.
A3: (default package)_InnerClassDotExpressions_InnerClass.txt | B3: Insufficient Modularization | C3: class | D3: (default package).InnerClassDotExpressions.InnerClass | E3: 0 | F3: The InnerClassContainer class and its nested classes are simple data structures with minimal functionality. Each class has a single responsibility and contains only static methods with straightforward implementations. The nesting hierarchy reflects a logical organization rather than excessive complexity. The classes are small, cohesive, and do not exhibit the size, complexity, or bloated interface characteristics that define insufficient modularization.
A4: (default package)_MegamorphicBypass_Quarter.txt | B4: Insufficient Modularization | C4: class | D4: (default package).MegamorphicBypass.Quarter | E4: 0 | F4: The class has a single, well-defined responsibility of demonstrating megamorphic dispatch behavior through a simple simulation. While it contains nested classes (Nickel, Dime, Quarter) and a main execution loop, the overall complexity remains low as all components directly serve the core purpose. The class does not exhibit excessive size, complexity, or a bloated interface that would warrant decomposition into separate modules.
A5: (default package)_PolymorphismTest_Quarter.txt | B5: Insufficient Modularization | C5: class | D5: (default package).PolymorphismTest.Quarter | E5: 0 | F5: The class PolymorphismTest, while containing multiple nested classes and a main method, maintains a clear and focused responsibility centered around demonstrating polymorphism behavior. The nested classes (Nickel, Dime, Quarter) are simple implementations of the Coin interface, each with a single responsibility. The constructor contains a test loop that exercises polymorphic behavior, which aligns with the class's purpose. The class does not exhibit excessive size, complexity, or a bloated interface that would warrant decomposition into smaller abstractions.
A6: (default package)_TestInner.txt | B6: Insufficient Modularization | C6: class | D6: (default package).TestInner | E6: 0 | F6: The class TestInner is relatively small and simple, with only 32 lines of code. It has a clear single responsibility of demonstrating inner class behavior. The nested inner classes (Inner1, Inner2) are logically related and serve to demonstrate the hierarchical relationship. The class does not exhibit excessive size, complexity, or bloated interface - it has only one public method (a()) and a straightforward constructor chain. The nested classes each have single responsibilities and minimal interfaces.
A7: a_b_c_ExampleClass.txt | B7: Insufficient Modularization | C7: class | D7: a.b.c.ExampleClass | E7: 0 | F7: The class is small and focused, containing only a constructor and a single method that delegates to a factory. It has a clear single responsibility of providing data objects through a factory pattern. The class does not exhibit excessive size, complexity, or bloated interface that would indicate insufficient modularization.
A8: com_github_javaparser_GeneratedJavaParserBase.txt | B8: Insufficient Modularization | C8: class | D8: com.github.javaparser.GeneratedJavaParserBase | E8: 1 | F8: ['The class has a high number of methods (over 30), indicating excessive functionality within a single abstraction.', 'Multiple responsibilities are observed such as token management, error recovery, node list operations, lambda expression generation, and array type handling.', 'Several methods deal with low-level parsing details and token manipulations that could be separated into dedicated classes or modules.', 'The class serves as a base for generated parser code but accumulates numerous utility and helper methods that violate the single responsibility principle.', "Complexity is increased by conditional logic based on 'storeTokens' flag scattered across multiple methods, suggesting a lack of cohesive design."]
A9: com_github_javaparser_GeneratedJavaParserTokenManager.txt | B9: Insufficient Modularization | C9: class | D9: com.github.javaparser.GeneratedJavaParserTokenManager | E9: 1 | F9: ['The class has excessive size with numerous methods and fields, making it difficult to understand and maintain.', 'It contains multiple responsibilities including token management, lexical analysis, and comment handling, which could be separated into smaller, more cohesive abstractions.', 'The presence of large switch statements and complex state management logic indicates a lack of decomposition.', 'The class includes many private helper methods and static arrays that contribute to its bloated interface and overall complexity.']
A10: com_github_javaparser_JavaToken_Kind.txt | B10: Insufficient Modularization | C10: class | D10: com.github.javaparser.JavaToken.Kind | E10: 0 | F10: ['The JavaToken.Kind enum is a well-encapsulated component responsible for representing token kinds in the JavaParser library.', 'It contains a reasonable number of constants (152) that correspond to different token types in the Java language, which is appropriate for its purpose.', 'The class provides essential methods such as valueOf(int kind), isPrimitive(), and getKind(), which are cohesive and directly related to token kind management.', 'The switch statement in valueOf(int kind) is a standard and efficient way to map integer values to enum constants, and its size is justified by the number of token types.', 'There is no evidence of excessive complexity, bloated interface, or mixing of responsibilities that would indicate insufficient modularization.', 'The class is focused solely on representing and managing token kinds, adhering to the single responsibility principle.']
A11: com_github_javaparser_Range.txt | B11: Insufficient Modularization | C11: class | D11: com.github.javaparser.Range | E11: 0 | F11: ['The class has a single, well-defined responsibility: representing a range of characters in a source file.', 'The class is relatively small, with only 22 methods and 2 fields, which is manageable.', 'All methods are cohesive and related to the core abstraction of a character range (e.g., creation, comparison, containment checks, and string representation).', 'There are no signs of bloated interface or excessive complexity in the method signatures or implementations.', 'The class does not expose an overly complex public API; it provides essential operations for range manipulation and querying.', "While there are several 'with*' methods for creating modified copies, these are consistent with the immutable value object pattern and do not indicate poor modularization."]
A12: com_github_javaparser_ast_Node_DirectChildrenIterator.txt | B12: Insufficient Modularization | C12: class | D12: com.github.javaparser.ast.Node.DirectChildrenIterator | E12: 0 | F12: The class Node.DirectChildrenIterator is a nested static class with a very focused responsibility - it simply iterates over the direct children of a node. It has only one field (childrenIterator) and implements a standard Iterator interface with hasNext() and next() methods. The class is small, cohesive, and well-encapsulated, representing a single, well-defined abstraction. It does not exhibit excessive size, complexity, or a bloated interface that would indicate insufficient modularization.
A13: com_github_javaparser_ast_body_AnnotationMemberDeclaration.txt | B13: Insufficient Modularization | C13: class | D13: com.github.javaparser.ast.body.AnnotationMemberDeclaration | E13: 0 | F13: The class AnnotationMemberDeclaration is well-focused, representing a single responsibility related to annotation member declarations in Java. It has a manageable size with clear fields (modifiers, type, name, defaultValue) and methods that handle properties, visitor patterns, cloning, and resolution logic. The class leverages multiple interfaces to provide specific behaviors (e.g., NodeWithJavadoc, NodeWithType), which promotes modular design rather than bloating the class. There is no evidence of excessive complexity, duplicated logic, or intertwined responsibilities that would indicate insufficient decomposition.
... A36: com_github_javaparser_metamodel_YieldStmtMetaModel.txt | B36: Insufficient Modularization | C36: class | D36: com.github.javaparser.metamodel.YieldStmtMetaModel | E36: 0 | F36: The class YieldStmtMetaModel is a small, focused class with minimal responsibilities. It extends StatementMetaModel and only contains a constructor and one field, indicating proper decomposition and adherence to single responsibility principle. The class is also auto-generated, which implies it follows a predefined structural pattern rather than manual design flaws.
A37: com_github_javaparser_printer_XmlPrinter.txt | B37: insufficient_modularization | C37: class | D37: com.github.javaparser.printer.XmlPrinter
A38: com_github_javaparser_printer_concretesyntaxmodel_CsmList.txt | B38: Insufficient Modularization | C38: class | D38: com.github.javaparser.printer.concretesyntaxmodel.CsmList | E38: 0 | F38: The class CsmList is well-factored with a single responsibility of handling list printing in the concrete syntax model. It has a clear interface with appropriate constructors and getter methods. The prettyPrint method, while somewhat complex due to handling different node types and separator logic, is cohesive and directly related to the class's core responsibility. The class size is reasonable (approximately 100 lines) and does not exhibit excessive complexity or bloated interface. The design follows good separation of concerns by delegating printing operations to other CsmElement instances and ConcreteSyntaxModel.
A39: com_github_javaparser_printer_lexicalpreservation_ReshuffledDiffElementExtractor_MatchClassification.txt | B39: Insufficient Modularization | C39: class | D39: com.github.javaparser.printer.lexicalpreservation.ReshuffledDiffElementExtractor.MatchClassification | E39: 0 | F39: The class ReshuffledDiffElementExtractor, while containing complex logic for handling reshuffled elements and their correspondence mapping, remains within reasonable size and complexity boundaries. It encapsulates a single cohesive responsibility of extracting and processing reshuffled difference elements. The methods are meaningfully organized, and the inner enum MatchClassification supports the class's functionality without indicating bloating. There is no evidence of excessive size, complexity, or a bloated interface that would suggest the need for further decomposition.
A40: com_github_javaparser_printer_lexicalpreservation_TextElementIteratorsFactory_EmptyIterator.txt | B40: Insufficient Modularization | C40: class | D40: com.github.javaparser.printer.lexicalpreservation.TextElementIteratorsFactory.EmptyIterator | E40: 1 | F40: ['The class TextElementIteratorsFactory contains multiple nested classes (CascadingIterator, EmptyIterator, SingleElementIterator, ComposedIterator) that implement different iterator behaviors, indicating a concentration of responsibilities.', 'The class has multiple public static methods (reverseIterator, partialReverseIterator) that deal with different aspects of iterator creation and composition, adding to its complexity.', 'The class serves as a factory for various iterator types while also containing complex logic for iterator composition and management, making it large and multifaceted.', 'The presence of nested classes and multiple utility methods suggests that the abstraction has not been adequately decomposed into smaller, more cohesive units.']
A41: com_github_javaparser_resolution_Navigator.txt | B41: Insufficient Modularization | C41: class | D41: com.github.javaparser.resolution.Navigator | E41: 0 | F41: ['The class has a single, well-defined responsibility: providing utility methods for navigating and retrieving nodes from a JavaParser AST.', 'All methods are cohesive and related to the core purpose of the class.', 'The class is appropriately sized with 35 methods, which is reasonable for a utility class of this nature.', 'There is no evidence of excessive complexity or bloated interfaces.', "Methods are logically grouped and consistently named, following a clear pattern (e.g., 'demand*' and 'find*' prefixes)."]
A42: com_github_javaparser_resolution_Resolvable.txt | B42: Insufficient Modularization | C42: class | D42: com.github.javaparser.resolution.Resolvable | E42: 0 | F42: The Resolvable interface is a minimal, well-defined abstraction with a single method 'resolve()'. It adheres to the Single Responsibility Principle and does not exhibit excessive size, complexity, or a bloated interface. The interface is properly focused on its core responsibility of resolving a type T, making it sufficiently modular.
A43: com_github_javaparser_resolution_logic_ConstructorResolutionLogic.txt | B43: Insufficient Modularization | C43: class | D43: com.github.javaparser.resolution.logic.ConstructorResolutionLogic | E43: 0 | F43: ['The class has a clear and focused responsibility: resolving constructor applicability and finding the most applicable constructor.', 'The class is of moderate size with only 150 lines of code, which is manageable.', 'It has a well-defined interface with only 3 public methods, all closely related to constructor resolution logic.', 'The class properly uses helper methods (isApplicable, findMostApplicable) to decompose complex logic.', 'There is no evidence of excessive complexity or bloated interface.', 'The class follows single responsibility principle by focusing solely on constructor resolution logic without mixing unrelated concerns.']
A44: com_github_javaparser_resolution_logic_MethodResolutionLogic.txt | B44: Insufficient Modularization | C44: class | D44: com.github.javaparser.resolution.logic.MethodResolutionLogic | E44: 1 | F44: ['The class has excessive size with many methods (more than 50), indicating high complexity.', 'Multiple responsibilities are mixed within the class, including method applicability checking, type inference, lambda conflict resolution, and method specificity determination.', 'Large methods with complex logic, such as `isApplicable` and `findMostApplicable`, suggest insufficient decomposition of responsibilities.', 'Helper methods like `substituteDeclaringTypeParameters` and `inferTypes` indicate tightly coupled logic that could be modularized into separate classes or components.', 'Lack of clear separation of concerns makes the class difficult to understand, maintain, and evolve.']
A45: com_github_javaparser_serialization_JavaParserJsonSerializer.txt | B45: Insufficient Modularization | C45: class | D45: com.github.javaparser.serialization.JavaParserJsonSerializer | E45: 0 | F45: The class JavaParserJsonSerializer is focused on a single responsibility: serializing JavaParser AST nodes to JSON. While it contains several methods, they are all cohesive and directly related to the serialization process. The class has a clear public interface with the main serialize method and protected methods that allow for customization. The presence of nested enums for JSON structure constants is appropriate for encapsulating related data. The class does not exhibit excessive size or complexity that would warrant decomposition into multiple classes. All methods serve the core purpose of serialization, maintaining a consistent level of abstraction.
A46: com_github_javaparser_serialization_JavaParserJsonSerializer_JsonTokenRange.txt | B46: Insufficient Modularization | C46: class | D46: com.github.javaparser.serialization.JavaParserJsonSerializer.JsonTokenRange | E46: 0 | F46: The class JavaParserJsonSerializer is well-focused on its responsibility of serializing AST nodes to JSON. It has a clear separation of concerns with helper methods for writing different parts of the JSON structure (e.g., writeRange, writeTokens, writeToken). The class is of moderate size and does not exhibit excessive complexity or a bloated interface. The inner enums (JsonNode, JsonRange, JsonTokenRange, JsonToken) are used for organizing JSON property keys and are appropriately encapsulated within the class. Overall, the class demonstrates sufficient modularization.
A47: com_github_javaparser_symbolsolver_SourceFileInfoExtractor.txt | B47: Insufficient Modularization | C47: class | D47: com.github.javaparser.symbolsolver.SourceFileInfoExtractor | E47: 0 | F47: ['The class has a single, well-defined responsibility: extracting and reporting information from source files using JavaParser.', 'The class is of moderate size (~150 lines) and does not exhibit excessive complexity.', 'Methods are generally small and focused, each handling a specific aspect of the functionality (e.g., solving types, solving method calls, collecting nodes).', 'There is no evidence of a bloated interface; the public methods are limited and cohesive.', 'The internal logic is well-organized with appropriate helper methods, and there is no significant duplication or entanglement of concerns.']
A48: com_github_javaparser_symbolsolver_cache_NoCache.txt | B48: Insufficient Modularization | C48: class | D48: com.github.javaparser.symbolsolver.cache.NoCache | E48: 0 | F48: The class NoCache is a minimal implementation of the Cache interface with only essential methods. It has a single responsibility of providing a no-op cache implementation. The class is small, simple, and well-cohesive, containing only the necessary methods to fulfill its contract as a cache that stores nothing. There is no evidence of excessive size, complexity, or bloated interface that would indicate insufficient modularization.
A49: com_github_javaparser_symbolsolver_core_resolution_MethodUsageResolutionCapability.txt | B49: Insufficient Modularization | C49: class | D49: com.github.javaparser.symbolsolver.core.resolution.MethodUsageResolutionCapability | E49: 0 | F49: The class is a simple interface with only one method declaration. It has minimal size and complexity, representing a well-defined abstraction with a single responsibility. There is no evidence of inadequate decomposition or bloated interface.
... A86: com_google_zxing_EncodeHintType.txt | B86: Insufficient Modularization | C86: class | D86: com.google.zxing.EncodeHintType | E86: 0 | F86: The EncodeHintType enum is a well-encapsulated enumeration that defines a fixed set of encoding hints. It has a single responsibility of representing different encoding options and their documentation. The class is not excessively large or complex, and each enum constant is clearly defined with appropriate Javadoc comments. The enum does not contain any methods or additional logic that would indicate bloated functionality or inadequate decomposition. This is a proper use of an enum to represent a closed set of options, and it adheres to good modularization principles.
A87: com_google_zxing_ResultPointCallback.txt | B87: insufficient_modularization | C87: class | D87: com.google.zxing.ResultPointCallback
A88: com_google_zxing_aztec_encoder_SimpleToken.txt | B88: Insufficient Modularization | C88: class | D88: com.google.zxing.aztec.encoder.SimpleToken | E88: 0 | F88: The class SimpleToken is small and focused, with only two fields (value and bitCount) and three methods (constructor, appendTo, and toString). It has a single responsibility of representing a simple token in the Aztec encoder and properly encapsulates its behavior. The class does not exhibit excessive size, complexity, or a bloated interface that would indicate insufficient modularization.
A89: com_google_zxing_client_android_HttpHelper_ContentType.txt | B89: Insufficient Modularization | C89: class | D89: com.google.zxing.client.android.HttpHelper.ContentType | E89: 0 | F89: The class HttpHelper is a utility class with a clear, single responsibility: providing HTTP-related helper methods. It has a moderate size (approximately 1888 characters), well-defined methods, and cohesive functionality. The class handles HTTP content downloading, redirection, and connection management, all closely related tasks. It does not exhibit excessive complexity, and its interface is not bloated. The methods are appropriately sized and focused, and the class is well-organized with clear separation of concerns. Therefore, it does not qualify as insufficiently modularized.
A90: com_google_zxing_client_android_Intents.txt | B90: Insufficient Modularization | C90: class | D90: com.google.zxing.client.android.Intents | E90: 0 | F90: ['The class is a utility class containing only public static final nested classes and constants, with no executable code outside of private constructors', 'Each nested class (Scan, History, Encode, SearchBookContents, WifiConnect, Share) represents a distinct conceptual grouping of related constants', 'The class has a clear single responsibility: providing intent constants for different barcode scanning operations', 'The size is appropriate for its purpose (under 200 lines of actual code)', 'The interface is not bloated - it provides a clean, organized structure with logical groupings', 'The class follows good design principles by using nested classes to namespace related constants', 'There is no excessive complexity or mixing of responsibilities that would indicate insufficient decomposition']
A91: com_google_zxing_client_android_PreferencesActivity.txt | B91: Insufficient Modularization | C91: class | D91: com.google.zxing.client.android.PreferencesActivity | E91: 0 | F91: The class is minimal and well-focused, serving only as an entry point for preferences UI. It contains only essential constants for preference keys and a simple onCreate method that delegates to a PreferencesFragment. The class properly separates concerns by delegating UI management to the fragment, maintaining good cohesion and single responsibility.
A92: com_google_zxing_client_android_encode_Formatter.txt | B92: Insufficient Modularization | C92: class | D92: com.google.zxing.client.android.encode.Formatter | E92: 0 | F92: The Formatter interface is properly modularized with a single, well-defined responsibility. It contains only one method (format) that performs a specific formatting task, adhering to the Single Responsibility Principle. The interface is small, focused, and cohesive, representing a clear abstraction for formatting operations. There is no evidence of excessive size, complexity, or bloated interface that would indicate insufficient modularization.
A93: com_google_zxing_client_android_encode_MECARDContactEncoder_MECARDTelDisplayFormatter.txt | B93: Insufficient Modularization | C93: class | D93: com.google.zxing.client.android.encode.MECARDContactEncoder.MECARDTelDisplayFormatter | E93: 0 | F93: The class MECARDTelDisplayFormatter is a private static nested class with a single responsibility: formatting telephone numbers for display in MECARD format. It contains only a constant pattern and a single method implementation, making it highly cohesive and appropriately sized. The class does not exhibit excessive size, complexity, or a bloated interface, and its functionality is well-decomposed from the outer class responsibilities.
A94: com_google_zxing_client_android_history_HistoryActivity.txt | B94: Insufficient Modularization | C94: class | D94: com.google.zxing.client.android.history.HistoryActivity | E94: 0 | F94: ['The class has a single, well-defined responsibility: managing the UI and interactions for displaying and manipulating scan history.', 'The class is of moderate size and does not contain excessive methods or lines of code.', 'Complexity is managed through appropriate separation of concerns, with helper methods like reloadHistoryItems() and proper use of HistoryManager for data operations.', 'The class follows standard Android patterns for ListActivity, context menus, and options menus without unnecessary entanglement of responsibilities.', 'No bloated interface or excessive public methods are present that would indicate insufficient decomposition.']
A95: com_google_zxing_client_android_history_HistoryItemAdapter.txt | B95: Insufficient Modularization | C95: class | D95: com.google.zxing.client.android.history.HistoryItemAdapter | E95: 0 | F95: The class has a single, well-defined responsibility of adapting HistoryItem objects for display in a list view. It contains only essential methods related to view creation and data binding, with minimal complexity. The class is small in size and does not exhibit excessive responsibilities or a bloated interface that would warrant decomposition.
A96: com_google_zxing_client_j2se_EncoderConfig.txt | B96: insufficient_modularization | C96: class | D96: com.google.zxing.client.j2se.EncoderConfig
A97: com_google_zxing_client_j2se_MatrixToImageConfig.txt | B97: Insufficient Modularization | C97: class | D97: com.google.zxing.client.j2se.MatrixToImageConfig | E97: 0 | F97: The class MatrixToImageConfig is a small, cohesive configuration class with only 42 lines of code. It has a single responsibility of encapsulating configuration for matrix to image conversion, with clear and focused methods. The class contains only essential fields (onColor, offColor) and methods directly related to configuration management and color model determination. There is no excessive complexity, bloated interface, or concentrated responsibilities that would indicate insufficient modularization.
A98: com_google_zxing_client_result_AddressBookDoCoMoResultParser.txt | B98: Insufficient Modularization | C98: class | D98: com.google.zxing.client.result.AddressBookDoCoMoResultParser | E98: 0 | F98: The class has a single, well-defined responsibility of parsing MECARD format address book entries. It contains only essential methods for parsing and processing the specific data format, with a clear and focused purpose. The class is not excessively large or complex, and its interface is not bloated. It properly extends a parent class and encapsulates its parsing logic without unnecessary complexity or scattered responsibilities.
...
