Workbook

Sheet samples
A1: project | B1: smell | C1: package | D1: prompt_file | E1: context_size | F1: designite | G1: gpt | H1: deepseek | I1: qwen
A2: jitwatch | B2: Unstable Dependency | C2: org.adoptopenjdk.jitwatch.ui.compilechain | D2: data/processed/prompts/unstable_dependency/jitwatch/org_adoptopenjdk_jitwatch_ui_compilechain.txt | E2: 82305 | F2: 0 | G2: =VLOOKUP(C2,gpt!$D$2:$E$101,2,0) -> 0 | H2: =VLOOKUP(C2,deepseek!$D$2:$E$101,2,0) -> 1 | I2: =VLOOKUP(C2,qwen!$D$2:$E$101,2,0) -> 1
A3: jitwatch | B3: Unstable Dependency | C3: org.adoptopenjdk.jitwatch.jarscan.freqinlinesize | D3: data/processed/prompts/unstable_dependency/jitwatch/org_adoptopenjdk_jitwatch_jarscan_freqinlinesize.txt | E3: 75987 | F3: 0 | G3: =VLOOKUP(C3,gpt!$D$2:$E$101,2,0) -> 0 | H3: =VLOOKUP(C3,deepseek!$D$2:$E$101,2,0) -> 1 | I3: =VLOOKUP(C3,qwen!$D$2:$E$101,2,0) -> 0
A4: jitwatch | B4: Unstable Dependency | C4: org.adoptopenjdk.jitwatch.model.assembly | D4: data/processed/prompts/unstable_dependency/jitwatch/org_adoptopenjdk_jitwatch_model_assembly.txt | E4: 96053 | F4: 1 | G4: =VLOOKUP(C4,gpt!$D$2:$E$101,2,0) -> 1 | H4: =VLOOKUP(C4,deepseek!$D$2:$E$101,2,0) -> 1 | I4: =VLOOKUP(C4,qwen!$D$2:$E$101,2,0) -> 0
A5: jitwatch | B5: Unstable Dependency | C5: org.adoptopenjdk.jitwatch.model.assembly.arm | D5: data/processed/prompts/unstable_dependency/jitwatch/org_adoptopenjdk_jitwatch_model_assembly_arm.txt | E5: 22399 | F5: 0 | G5: =VLOOKUP(C5,gpt!$D$2:$E$101,2,0) -> 1 | H5: =VLOOKUP(C5,deepseek!$D$2:$E$101,2,0) -> 0 | I5: =VLOOKUP(C5,qwen!$D$2:$E$101,2,0) -> 0
A6: javaparser | B6: Unstable Dependency | C6: com.github.javaparser.symbolsolver.cache | D6: data/processed/prompts/unstable_dependency/javaparser/com_github_javaparser_symbolsolver_cache.txt | E6: 25085 | F6: 0 | G6: =VLOOKUP(C6,gpt!$D$2:$E$101,2,0) -> 0 | H6: =VLOOKUP(C6,deepseek!$D$2:$E$101,2,0) -> 0 | I6: =VLOOKUP(C6,qwen!$D$2:$E$101,2,0) -> 0
A7: jitwatch | B7: Unstable Dependency | C7: org.adoptopenjdk.jitwatch.ui.report.suggestion | D7: data/processed/prompts/unstable_dependency/jitwatch/org_adoptopenjdk_jitwatch_ui_report_suggestion.txt | E7: 4492 | F7: 0 | G7: =VLOOKUP(C7,gpt!$D$2:$E$101,2,0) -> 1 | H7: =VLOOKUP(C7,deepseek!$D$2:$E$101,2,0) -> 1 | I7: =VLOOKUP(C7,qwen!$D$2:$E$101,2,0) -> 0
A8: jitwatch | B8: Unstable Dependency | C8: org.adoptopenjdk.jitwatch.logger | D8: data/processed/prompts/unstable_dependency/jitwatch/org_adoptopenjdk_jitwatch_logger.txt | E8: 36109 | F8: 0 | G8: =VLOOKUP(C8,gpt!$D$2:$E$101,2,0) -> 0 | H8: =VLOOKUP(C8,deepseek!$D$2:$E$101,2,0) -> 0 | I8: =VLOOKUP(C8,qwen!$D$2:$E$101,2,0) -> 0
A9: javaparser | B9: Unstable Dependency | C9: javaparser | D9: data/processed/prompts/unstable_dependency/javaparser/javaparser.txt | E9: 1223 | F9: 0 | G9: =VLOOKUP(C9,gpt!$D$2:$E$101,2,0) -> 0 | H9: =VLOOKUP(C9,deepseek!$D$2:$E$101,2,0) -> 0 | I9: =VLOOKUP(C9,qwen!$D$2:$E$101,2,0) -> 0
A10: javaparser | B10: Unstable Dependency | C10: foo | D10: data/processed/prompts/unstable_dependency/javaparser/foo.txt | E10: 817 | F10: 0 | G10: =VLOOKUP(C10,gpt!$D$2:$E$101,2,0) -> 0 | H10: =VLOOKUP(C10,deepseek!$D$2:$E$101,2,0) -> 0 | I10: =VLOOKUP(C10,qwen!$D$2:$E$101,2,0) -> 0
A11: jitwatch | B11: Unstable Dependency | C11: org.adoptopenjdk.jitwatch.process.compiler | D11: data/processed/prompts/unstable_dependency/jitwatch/org_adoptopenjdk_jitwatch_process_compiler.txt | E11: 13175 | F11: 0 | G11: =VLOOKUP(C11,gpt!$D$2:$E$101,2,0) -> 0 | H11: =VLOOKUP(C11,deepseek!$D$2:$E$101,2,0) -> 0 | I11: =VLOOKUP(C11,qwen!$D$2:$E$101,2,0) -> 0
A12: jitwatch | B12: Unstable Dependency | C12: org.adoptopenjdk.jitwatch.inline | D12: data/processed/prompts/unstable_dependency/jitwatch/org_adoptopenjdk_jitwatch_inline.txt | E12: 38494 | F12: 0 | G12: =VLOOKUP(C12,gpt!$D$2:$E$101,2,0) -> 0 | H12: =VLOOKUP(C12,deepseek!$D$2:$E$101,2,0) -> 1 | I12: =VLOOKUP(C12,qwen!$D$2:$E$101,2,0) -> 0
A13: javaparser | B13: Unstable Dependency | C13: implements.duplicate | D13: data/processed/prompts/unstable_dependency/javaparser/implements_duplicate.txt | E13: 330 | F13: 0 | G13: =VLOOKUP(C13,gpt!$D$2:$E$101,2,0) -> 0 | H13: =VLOOKUP(C13,deepseek!$D$2:$E$101,2,0) -> 0 | I13: =VLOOKUP(C13,qwen!$D$2:$E$101,2,0) -> 0
... A101: zxing | B101: Unstable Dependency | C101: com.google.zxing.client.android.camera.open | D101: data/processed/prompts/unstable_dependency/zxing/com_google_zxing_client_android_camera_open.txt | E101: 12351 | F101: 0 | G101: =VLOOKUP(C101,gpt!$D$2:$E$101,2,0) -> 1 | H101: =VLOOKUP(C101,deepseek!$D$2:$E$101,2,0) -> 0 | I101: =VLOOKUP(C101,qwen!$D$2:$E$101,2,0) -> 0

Sheet gpt
A1: file_name | B1: smell | C1: entity_type | D1: entity | E1: detection | F1: justification
A2: (default package).txt | B2: Unstable Dependency | C2: package | D2: (default package) | E2: 0 | F2: The default package has outgoing dependencies to com.github.javaparser.quality (e.g. multiple classes import com.github.javaparser.quality.Preconditions/NotNull) and to com.packageName (e.g. InnerStaticClassFieldDotExpressions imports com.packageName.InnerStaticClassFieldContainer). Those target packages have incoming couplings (they are depended on) and no evident outgoing dependencies, making them more stable (low instability). The default package has essentially no incoming dependencies from other packages (afferent couplings = 0) and several efferent dependencies, so it is unstable but depends on more stable packages. Therefore the Stable Dependencies Principle is not violated (dependencies point from unstable → stable) and no Unstable Dependency smell is detected.
A3: a.txt | B3: Unstable Dependency | C3: package | D3: a | E3: 0 | F3: All referenced types (RefCycleClass, RefCycleEnum, RefCycleClassFailure, RefClass2) are within the same package 'a' and only use intra-package references (including static imports and field/method access). There are no outgoing dependencies from package 'a' to other packages nor incoming dependencies from other packages in the provided code, so the Stable Dependencies Principle is not violated.
A4: a_b_c.txt | B4: Unstable Dependency | C4: package | D4: a.b.c | E4: 1 | F4: Package a.b.c has an outgoing dependency to package d.e.f (ExampleClass contains 'import d.e.f.DataObjectFactory' and uses doFactory.getDataObject). In the provided code there are no incoming dependencies to a.b.c (no other packages depend on it), so its instability is high (instability = outgoing / (incoming + outgoing) = 1/(0+1) = 1.0). Because a.b.c (an unstable package) depends on another package, this violates the Stable Dependencies Principle and constitutes an Unstable Dependency smell.
A5: another.txt | B5: Unstable Dependency | C5: package | D5: another | E5: 0 | F5: Package 'another' contains only internal types (classes A, String, MyEnum, interface A) and no outgoing dependencies to other packages are present in the analyzed code. No incoming dependencies are recorded either. Because there are no outgoing dependencies to less-stable packages, the Unstable Dependency smell is not detected.
A6: bar.txt | B6: Unstable Dependency | C6: package | D6: bar | E6: 0 | F6: bar has an outgoing dependency to foo (bar.A extends foo.A). Dependency counts: bar Ca(incoming)=0, Ce(outgoing)=1 -> Instability I_bar = 1/(0+1) = 1. foo Ca(incoming)=1 (from bar), Ce(outgoing)=0 -> Instability I_foo = 0/(1+0) = 0. bar (more unstable) depends on foo (more stable), so the Stable Dependencies Principle is not violated; no Unstable Dependency smell detected.
A7: box.txt | B7: Unstable Dependency | C7: package | D7: box | E7: 0 | F7: Package 'box' has outgoing dependency on java.util.function.Function (a stable JDK package) and an internal dependency (Foo) within the same package. There are no incoming dependencies from other analyzed packages. The package does not depend on any less-stable packages, so the Unstable Dependency smell is not present.
A8: com_example.txt | B8: Unstable Dependency | C8: package | D8: com.example | E8: 0 | F8: No Unstable Dependency detected. com.example has outgoing dependencies on the well-established library package com.google.gson (examples: imports/usages of com.google.gson.Gson, GsonBuilder, TypeAdapter, TypeAdapterFactory, JsonAdapter, JsonReader, JsonWriter, TypeToken, SerializedName, JsonElement). There are no incoming dependencies from less-stable packages shown that com.example relies on. Because com.example depends on a stable external library (com.google.gson) rather than on less-stable packages, the Stable Dependencies Principle is not violated.
A9: com_foo_base.txt | B9: Unstable Dependency | C9: package | D9: com.foo.base | E9: 0 | F9: No outgoing dependencies: com.foo.base.Widget contains no imports or references to other packages. No incoming dependencies are present in the provided analysis. Because the package does not depend on any less-stable packages, the Unstable Dependency smell is not detected.
A10: com_github_javaparser_ast_nodeTypes_modifiers.txt | B10: Unstable Dependency | C10: package | D10: com.github.javaparser.ast.nodeTypes.modifiers | E10: 0 | F10: Outgoing dependencies observed: static import of com.github.javaparser.ast.Modifier.Keyword constants and regular imports of com.github.javaparser.ast.Node and com.github.javaparser.ast.nodeTypes.NodeWithModifiers (seen in NodeWithPublicModifier, NodeWithPrivateModifier, NodeWithProtectedModifier, NodeWithStaticModifier, NodeWithStrictfpModifier, NodeWithFinalModifier, NodeWithAbstractModifier, NodeWithAccessModifiers). No incoming dependencies are present in the provided code listing. All outgoing dependencies target core/parent AST packages (com.github.javaparser.ast and com.github.javaparser.ast.nodeTypes), which are expected to be as stable or more stable than this modifiers subpackage. There is no evidence of this package depending on less stable or more volatile components, nor of a cyclic dependency in the given files. Therefore an Unstable Dependency smell is not detected.
A11: com_github_javaparser_javasymbolsolver_javassist_symbols_included_jar.txt | B11: Unstable Dependency | C11: package | D11: com.github.javaparser.javasymbolsolver.javassist.symbols.included.jar | E11: 0 | F11: The package contains only SuperClassIncludedJar and InterfaceIncludedJar, each declaring only static String constants and not referencing other packages. There are no outgoing dependencies to other (less stable) packages in the provided code, and no incoming dependencies are listed. Therefore there is no violation of the Stable Dependencies Principle (no Unstable Dependency detected).
A12: com_github_javaparser_javasymbolsolver_javassist_symbols_main_jar.txt | B12: Unstable Dependency | C12: package | D12: com.github.javaparser.javasymbolsolver.javassist.symbols.main.jar | E12: 1 | F12: The package has multiple outgoing dependencies on external packages com.github.javaparser.javasymbolsolver.javassist_symbols.included_jar and com.github.javaparser.javasymbolsolver.javassist_symbols.excluded_jar while there are no incoming dependencies shown for these external packages in the provided data. Examples of outgoing dependencies: SubInterfaceIncludedJar extends InterfaceIncludedJar; SubClassIncludedJar extends SuperClassIncludedJar; InterfaceUserIncludedJar implements InterfaceIncludedJar; EnumInterfaceUserIncludedJar implements InterfaceIncludedJar (dependence on included_jar). InterfaceUserExcludedJar implements InterfaceExcludedJar; SubInterfaceExcludedJar extends InterfaceExcludedJar; SubClassExcludedJar extends SuperClassExcludedJar; EnumInterfaceUserExcludedJar implements InterfaceExcludedJar (dependence on excluded_jar). Because the main_jar package depends on these other packages (outgoing dependencies) and there are no corresponding incoming dependencies indicating those packages are more stable, this violates the Stable Dependencies Principle and constitutes an Unstable Dependency smell.
A13: com_github_javaparser_resolution_promotion.txt | B13: Unstable Dependency | C13: package | D13: com.github.javaparser.resolution.promotion | E13: 0 | F13: The package com.github.javaparser.resolution.promotion (ConditionalExprHandler) has an outgoing dependency on com.github.javaparser.resolution.types.ResolvedType (see ConditionalExprHandler import of ResolvedType). The target package com.github.javaparser.resolution.types contains many core type interfaces/classes (ResolvedType, ResolvedPrimitiveType, ResolvedReferenceType, ResolvedArrayType, ResolvedWildcard, etc.) which are widely used across the codebase. At the same time there are multiple incoming dependencies to com.github.javaparser.resolution.promotion from symbolsolver modules (e.g. TypeExtractor uses ConditionalExprHandler; symbolsolver.resolution.promotion.ReferenceConditionalExprHandler, NumericConditionalExprHandler and BooleanConditionalExprHandler implement/consume ConditionalExprHandler). Because the dependency direction is from the small promotion package toward a more central, heavily reused types package (i.e., depending on a more stable core package) and many other modules depend on the promotion package, the Stable Dependencies Principle is not violated. Therefore there is no Unstable Dependency smell.
... A101: package_b.txt | B101: Unstable Dependency | C101: package | D101: package.b | E101: 0 | F101: package_b has no outgoing dependencies (it does not depend on any other package) and no incoming dependencies recorded. Because it does not depend on less stable packages, the Unstable Dependency smell is not present.

Sheet deepseek
A1: file_name | B1: smell | C1: entity_type | D1: entity | E1: detection | F1: justification
A2: (default package).txt | B2: Unstable Dependency | C2: package | D2: (default package) | E2: 1 | F2: The default package depends on com.github.javaparser.quality (Preconditions) and com.packageName (ClassInPackage, InnerStaticClassFieldContainer). These external packages have no incoming dependencies from the default package, making them more stable (lower instability). The default package has high outgoing dependencies and low incoming dependencies, making it less stable. This violates the Stable Dependencies Principle as the less stable default package depends on more stable external packages.
A3: a.txt | B3: Unstable Dependency | C3: package | D3: a | E3: 1 | F3: Package 'a' contains a cyclic dependency between RefCycleClass and RefCycleEnum (RefCycleClass imports RefCycleEnum statically, RefCycleEnum imports RefCycleClass statically). This creates mutual instability where both components depend on each other, violating the Stable Dependencies Principle.
A4: a_b_c.txt | B4: Unstable Dependency | C4: package | D4: a.b.c | E4: 1 | F4: Package a.b.c has an outgoing dependency to d.e.f.DataObjectFactory (imported in ExampleClass), but d.e.f is not listed among the analyzed packages, making its stability unknown. Since a.b.c depends on an external package with potentially lower stability, this violates the Stable Dependencies Principle.
A5: another.txt | B5: Unstable Dependency | C5: package | D5: another | E5: 0 | F5: The package 'another' has no outgoing dependencies to other packages, and its incoming dependencies cannot be determined from the provided information. Therefore, there is insufficient evidence to detect an Unstable Dependency smell.
A6: bar.txt | B6: Unstable Dependency | C6: package | D6: bar | E6: 1 | F6: Package 'bar' depends on package 'foo' (via class A extends foo.A). Since 'foo' has no incoming dependencies shown and 'bar' has at least one outgoing dependency, 'foo' is more stable than 'bar'. This violates the Stable Dependencies Principle because 'bar' depends on a more stable component, making it an unstable dependency.
A7: box.txt | B7: Unstable Dependency | C7: package | D7: box | E7: 0 | F7: Package 'box' has no outgoing dependencies to other packages (only imports from java.util.function which is part of the stable Java standard library). It has no incoming dependencies from other packages in the provided context, making it maximally stable with no dependencies on less stable components.
A8: com_example.txt | B8: Unstable Dependency | C8: package | D8: com.example | E8: 1 | F8: The package 'com.example' depends on the less stable package 'com.google.gson' (which contains numerous classes like Gson, JsonElement, TypeAdapter, etc.). 'com.example' has high outgoing dependencies to 'com.google.gson' (many imports) and low incoming dependencies (likely only used by tests), making it less stable than 'com.google.gson'. This violates the Stable Dependencies Principle.
A9: com_foo_base.txt | B9: Unstable Dependency | C9: package | D9: com.foo.base | E9: 0 | F9: The package has no outgoing dependencies, and only one incoming dependency from the Widget class. With zero outgoing dependencies and one incoming dependency, the package is highly stable. There are no dependencies on less stable components.
A10: com_github_javaparser_ast_nodeTypes_modifiers.txt | B10: Unstable Dependency | C10: package | D10: com.github.javaparser.ast.nodeTypes.modifiers | E10: 0 | F10: All outgoing dependencies are to more stable packages: com.github.javaparser.ast (core AST) and com.github.javaparser.ast.nodeTypes (higher-level node types). No dependencies on less stable packages exist.
A11: com_github_javaparser_javasymbolsolver_javassist_symbols_included_jar.txt | B11: Unstable Dependency | C11: package | D11: com.github.javaparser.javasymbolsolver.javassist.symbols.included.jar | E11: 0 | F11: The package has no outgoing dependencies to other packages. It contains only two classes with no imports or references to external packages, making it maximally stable with zero afferent coupling (Ca=0) and zero efferent coupling (Ce=0).
A12: com_github_javaparser_javasymbolsolver_javassist_symbols_main_jar.txt | B12: Unstable Dependency | C12: package | D12: com.github.javaparser.javasymbolsolver.javassist.symbols.main.jar | E12: 0 | F12: The package has outgoing dependencies to packages 'com.github.javaparser.javasymbolsolver.javassist_symbols.included_jar' and 'com.github.javaparser.javasymbolsolver.javassist_symbols.excluded_jar', but no incoming dependencies from those packages are shown. Without data on the stability (incoming and outgoing dependencies) of the depended-upon packages, it cannot be determined if they are less stable than the current package. Therefore, an Unstable Dependency smell cannot be confirmed.
A13: com_github_javaparser_resolution_promotion.txt | B13: Unstable Dependency | C13: package | D13: com.github.javaparser.resolution.promotion | E13: 1 | F13: The package com.github.javaparser.resolution.promotion depends on com.github.javaparser.resolution.types.ResolvedType, which is part of a larger, more stable package (com.github.javaparser.resolution.types) with multiple incoming dependencies. The dependent package has 10 classes/interfaces (ResolvedType, ResolvedPrimitiveType, ResolvedLambdaConstraintType, ResolvedReferenceType, ResolvedUnionType, ResolvedWildcard, ResolvedIntersectionType, ResolvedVoidType, ResolvedTypeTransformer, ResolvedTypeVariable, ResolvedArrayType) and is imported by multiple other packages (including com.github.javaparser.symbolsolver.javaparsermodel and com.github.javaparser.symbolsolver.resolution.promotion), indicating higher stability. The analyzed package has only one class (ConditionalExprHandler) and depends on this more stable component, violating the Stable Dependencies Principle.
... A101: package_b.txt | B101: Unstable Dependency | C101: package | D101: package.b | E101: 0 | F101: Cannot assess stability without data on incoming and outgoing dependencies. Only one class definition is provided, insufficient to calculate afferent/efferent coupling or instability metric.

Sheet qwen
A1: file_name | B1: smell | C1: entity_type | D1: entity | E1: detection | F1: justification
A2: (default package).txt | C2: package | D2: (default package) | E2: 0 | F2: The default package does not exhibit Unstable Dependency. While it depends on com.github.javaparser.quality (Preconditions class), this dependency is stable as Preconditions is a final class with only static methods and no dependencies, making it highly stable. All other classes in the default package are self-contained or have minimal dependencies. There are no incoming dependencies from other packages, and the outgoing dependency to Preconditions does not violate stability principles since Preconditions is more stable than the default package components.
A3: a.txt | C3: package | D3: a | E3: 0 | F3: The package 'a' only contains internal dependencies between its own classes (RefCycleClass, RefCycleEnum, RefCycleClassFailure, RefClass2). There are no outgoing dependencies to other packages, so there cannot be unstable dependencies. All dependencies are self-contained within the package.
A4: a_b_c.txt | C4: package | D4: a.b.c | E4: 1 | F4: Package a.b.c has an unstable dependency on package d.e.f. The class ExampleClass in a.b.c imports d.e.f.DataObjectFactory, creating an outgoing dependency. Since a.b.c depends on d.e.f, according to the Stable Dependencies Principle, d.e.f should be more stable than a.b.c. However, there is no information indicating that d.e.f is more stable, and typically, importing external packages suggests a dependency on a less stable component, thus constituting an Unstable Dependency smell.
A5: another.txt | C5: package | D5: another | E5: 0 | F5: Package 'another' has no outgoing dependencies to other packages, therefore it does not violate the Stable Dependencies Principle. The package contains multiple classes and an enum but none of them depend on external packages.
A6: bar.txt | C6: package | D6: bar | E6: 1 | F6: Package 'bar' has an unstable dependency because class 'bar.A' extends 'foo.A', creating an outgoing dependency from bar to foo. Since bar is less stable (it depends on foo), but it's depending on a package that should be more stable, this violates the Stable Dependencies Principle. The dependency direction goes from the less stable package (bar) to the more stable one (foo), which is the correct direction, but the smell occurs because bar is inherently unstable due to this dependency on foo.
A7: box.txt | C7: package | D7: box | E7: 0 | F7: The package 'box' has no outgoing dependencies to other packages - it only imports java.util.function.Function which is part of the standard library. Since there are no inter-package dependencies, there cannot be unstable dependencies. The package is self-contained with only an interface and a record implementation.
A8: com_example.txt | C8: package | D8: com.example | E8: 0 | F8: The package 'com.example' does not exhibit the Unstable Dependency smell. All classes within this package either have no dependencies or depend only on stable external packages such as 'com.google.gson' and standard Java libraries. There are no dependencies on other less stable components within the analyzed code.
A9: com_foo_base.txt | C9: package | D9: com.foo.base | E9: 0 | F9: The package com.foo.base contains only a single empty class Widget with no outgoing dependencies to other packages, and no incoming dependencies from other packages are visible in the provided code. Since there are no inter-package dependencies to analyze, the Unstable Dependency smell cannot be detected.
A10: com_github_javaparser_ast_nodeTypes_modifiers.txt | C10: package | D10: com.github.javaparser.ast.nodeTypes.modifiers | E10: 0 | F10: The package 'com.github.javaparser.ast.nodeTypes.modifiers' contains only interface definitions that extend other interfaces within the same package or from the 'com.github.javaparser.ast.nodeTypes' package. All dependencies are internal or towards more stable packages (e.g., 'com.github.javaparser.ast'). There are no outgoing dependencies to less stable packages, and the structure adheres to the Stable Dependencies Principle.
A11: com_github_javaparser_javasymbolsolver_javassist_symbols_included_jar.txt | C11: package | D11: com.github.javaparser.javasymbolsolver.javassist.symbols.included.jar | E11: 0 | F11: The package contains only two simple classes (SuperClassIncludedJar and InterfaceIncludedJar) with no outgoing dependencies to other packages. Both classes only contain static final fields and no complex logic or external dependencies. Since there are no dependencies on less stable packages, there is no unstable dependency smell.
A12: com_github_javaparser_javasymbolsolver_javassist_symbols_main_jar.txt | C12: package | D12: com.github.javaparser.javasymbolsolver.javassist.symbols.main.jar | E12: 1 | F12: The package 'com.github.javaparser.javasymbolsolver.javassist_symbols.main_jar' has outgoing dependencies to 'com.github.javaparser.javasymbolsolver.javassist_symbols.included_jar' and 'com.github.javaparser.javasymbolsolver.javassist_symbols.excluded_jar'. If these dependent packages are less stable than the current package, it violates the Stable Dependencies Principle, resulting in an Unstable Dependency smell.
A13: com_github_javaparser_resolution_promotion.txt | C13: package | D13: com.github.javaparser.resolution.promotion | E13: 0 | F13: The package 'com.github.javaparser.resolution.promotion' defines the ConditionalExprHandler interface which is implemented by classes in the same package and used by other packages. The dependent packages like 'com.github.javaparser.symbolsolver.resolution.promotion' and 'com.github.javaparser.symbolsolver.javaparsermodel' depend on this package, but they are more stable or equally stable components. There is no evidence of this package depending on less stable packages, thus no unstable dependency is detected.
... A37: com_google_zxing_oned_rss.txt | C37: package | D37: com.google.zxing.oned.rss | E37: 0 | F37: The package com.google.zxing.oned.rss contains classes that are part of a cohesive module for reading RSS family barcodes. The classes within this package have high cohesion as they all relate to RSS barcode processing. The package depends on com.google.zxing.common and com.google.zxing.common.detector for shared utilities like BitArray, BitMatrix, MathUtils, and detector classes, which are stable foundational components. These dependencies are stable because they provide basic data structures and common utilities that are unlikely to change frequently. The package does not depend on less stable packages; instead, it depends on more stable ones. Therefore, it follows the Stable Dependencies Principle and does not exhibit the Unstable Dependency smell.
A38: com_google_zxing_pdf417_decoder_ec.txt | B38: unstable_dependency | C38: class | D38: com.google.zxing.pdf417.decoder.ec
A39: com_google_zxing_pdf417_detector.txt | C39: package | D39: com.google.zxing.pdf417.detector | E39: 0 | F39: The package com.google.zxing.pdf417.detector has dependencies on com.google.zxing and com.google.zxing.common packages. These dependencies are stable foundational packages of the ZXing library that provide core functionality like BinaryBitmap, ResultPoint, BitMatrix, NotFoundException, and DecodeHintType. The detector package itself is a specialized component for PDF417 barcode detection and follows the Stable Dependencies Principle by depending on more stable, core library components rather than less stable packages. Therefore, no unstable dependency smell is detected.
A40: com_google_zxing_web_generator_client.txt | C40: package | D40: com.google.zxing.web.generator.client | E40: 0 | F40: The package com.google.zxing.web.generator.client contains multiple classes that implement the GeneratorSource interface and depend on each other internally. All classes within this package are cohesive and work together to generate QR codes for various content types. The dependencies are stable because they are all part of the same functional module with no external unstable dependencies. Classes like WifiGenerator, GeoLocationGenerator, EmailGenerator, etc., all depend on shared internal classes like StylesDefs, GeneratorException, and Validators, which are stable within the package. There are no outgoing dependencies to less stable external packages that would violate the Stable Dependencies Principle.
A41: com_packageName.txt | C41: package | D41: com.packageName | E41: 0 | F41: The package com.packageName contains classes that are only depended upon by other classes (in the default package) but do not depend on any external packages themselves. Specifically, classes like ClassInPackage and InnerStaticClassFieldContainer are used by classes in the default package, but com.packageName does not have any outgoing dependencies to less stable packages. Therefore, it does not exhibit an Unstable Dependency smell.
A42: com_service_usage.txt | C42: package | D42: com.service.usage | E42: 0 | F42: The package com.service.usage has a stable dependency on com.service.definition. The ServiceImplementation class properly implements the ServiceDefinition interface, following the Stable Dependencies Principle where a less stable package (com.service.usage) depends on a more stable package (com.service.definition). There are no unstable dependencies detected.
A43: com_service_usage2.txt | C43: package | D43: com.service.usage2 | E43: 0 | F43: The package com.service.usage2 has an outgoing dependency to com.service.definition (importing ServiceDefinition). To determine if this is an unstable dependency, we need to consider the stability of both packages. However, with only one class shown in com.service.usage2 and its dependency on com.service.definition, and without information about incoming dependencies or the full structure of com.service.definition, we cannot definitively conclude that com.service.usage2 is less stable than its dependency. The package appears to be a simple implementation package depending on a definition/interface package, which is a typical stable dependency pattern where the implementation depends on the more stable interface/definition.
A44: demo.txt | C44: package | D44: demo | E44: 0 | F44: The 'demo' package does not exhibit the Unstable Dependency smell. It depends on the 'com.github.javaparser.utils' package, which is part of a stable, external library (JavaParser). The 'demo' package itself is stable (it's a main package with no outgoing dependencies other than the stable JavaParser library), and thus it does not depend on less stable components. The dependencies flow from a less stable package ('demo') to a more stable one ('com.github.javaparser.utils'), which aligns with the Stable Dependencies Principle.
A45: foo.txt | C45: package | D45: foo | E45: 0 | F45: The package 'foo' contains all classes and interfaces within itself, with no dependencies on external packages. All dependencies are internal to the package, so there are no unstable dependencies.
A46: foo_bar_differentpackage.txt | C46: package | D46: foo.bar.differentpackage | E46: 1 | F46: The package 'foo.bar.differentpackage' depends on 'foo.bar' through classes AClass importing AnInterface and BinaryExpr. The stability of 'foo.bar.differentpackage' is higher than 'foo.bar' because it has fewer incoming dependencies (0) compared to 'foo.bar' which has incoming dependencies from 'foo.bar.differentpackage'. According to the Stable Dependencies Principle, 'foo.bar.differentpackage' should not depend on a less stable package like 'foo.bar'.
A47: groovy_transform_builder.txt | C47: package | D47: groovy.transform.builder | E47: 0 | F47: The package groovy.transform.builder has a stable dependency architecture. It depends on org.codehaus.groovy.ast and org.codehaus.groovy.transform which are more stable packages as they are part of the core Groovy AST transformation infrastructure. The package does not depend on any less stable packages, and its dependencies follow the Stable Dependencies Principle.
A48: implements_duplicate.txt | C48: package | D48: implements.duplicate | E48: 0 | F48: The package implements_duplicate contains classes that form a cohesive unit with internal dependencies. Class A implements DuplicateTypeName interface and contains an inner class DuplicateTypeName that extends A, creating a stable internal structure. There are no outgoing dependencies to other packages, and the internal dependencies follow a logical hierarchy where the inner class extends the outer class, maintaining stability within the package boundaries.
A49: issue1945_interfaces.txt | C49: package | D49: issue1945.interfaces | E49: 0 | F49: The package issue1945.interfaces defines the core abstractions (HairType, HairyAnimal, HairTypeRenderer) and does not depend on any other packages. It is a stable interface layer with no outgoing dependencies, making it inherently stable and not violating the Stable Dependencies Principle.
A50: issue241.txt | C50: package | D50: issue241 | E50: 0 | F50: The package issue241 contains only one class TypeWithMemberType and its nested interface MemberInterface. There are no outgoing dependencies to other packages, and no incoming dependencies from other packages are shown. Since there are no inter-package dependencies, the Stable Dependencies Principle cannot be violated, and therefore no Unstable Dependency smell is detected.
... A62: org_adoptopenjdk_jitwatch_jarscan_allocationcount.txt | C62: package | D62: org.adoptopenjdk.jitwatch.jarscan.allocationcount | E62: 0 | F62: The package org.adoptopenjdk.jitwatch.jarscan.allocationcount depends only on the org.adoptopenjdk.jitwatch.model.bytecode package, which is more stable as it contains core model classes. The package does not have any outgoing dependencies to less stable packages, and its dependencies are directed towards more stable components, following the Stable Dependencies Principle.
A63: org_adoptopenjdk_jitwatch_jarscan_freqinlinesize.txt | B63: unstable_dependency | C63: class | D63: org.adoptopenjdk.jitwatch.jarscan.freqinlinesize
A64: org_adoptopenjdk_jitwatch_jarscan_invokecount.txt | C64: package | D64: org.adoptopenjdk.jitwatch.jarscan.invokecount | E64: 0 | F64: The package org.adoptopenjdk.jitwatch.jarscan.invokecount does not exhibit Unstable Dependency. It has a stable design with classes that are interdependent but maintain clear responsibilities. The classes InvokeMethodCountMap, MethodCountMap, and InvokeCountOperation work together cohesively, with InvokeCountOperation depending on the other two for functionality. All dependencies are within the same package, and there are no external dependencies on less stable components. The package structure follows the Stable Dependencies Principle as it does not depend on packages that are less stable than itself.
A65: org_adoptopenjdk_jitwatch_jarscan_methodsizehisto.txt | C65: package | D65: org.adoptopenjdk.jitwatch.jarscan.methodsizehisto | E65: 0 | F65: The package org.adoptopenjdk.jitwatch.jarscan.methodsizehisto has no incoming dependencies and only depends on packages that are more stable than itself. It depends on org.adoptopenjdk.jitwatch.core (which is part of the same project and likely more stable), org.adoptopenjdk.jitwatch.jarscan (its parent package), org.adoptopenjdk.jitwatch.model (a core model package), and org.adoptopenjdk.jitwatch.model.bytecode (a specialized model package). These dependencies follow the Stable Dependencies Principle as the dependent packages are foundational and less likely to change frequently compared to this specific operation implementation.
A66: org_adoptopenjdk_jitwatch_jarscan_nextinstruction.txt | C66: package | D66: org.adoptopenjdk.jitwatch.jarscan.nextinstruction | E66: 0 | F66: The package org.adoptopenjdk.jitwatch.jarscan.nextinstruction has outgoing dependencies on org.adoptopenjdk.jitwatch.model.bytecode and org.adoptopenjdk.jitwatch.jarscan.sequencecount. Both of these packages are more stable (have more incoming dependencies and are core model packages) than the nextinstruction package. The nextinstruction package itself has no incoming dependencies, making it unstable. Since it only depends on more stable packages, it does not violate the Stable Dependencies Principle. Therefore, there is no Unstable Dependency smell detected.
A67: org_adoptopenjdk_jitwatch_jarscan_sequencecount.txt | C67: package | D67: org.adoptopenjdk.jitwatch.jarscan.sequencecount | E67: 0 | F67: The package org.adoptopenjdk.jitwatch.jarscan.sequencecount has outgoing dependencies on org.adoptopenjdk.jitwatch.model.bytecode and org.adoptopenjdk.jitwatch.jarscan, and no incoming dependencies from other packages. Since it depends on more stable packages (like org.adoptopenjdk.jitwatch.model.bytecode which is likely to be more stable due to its foundational role) and does not have dependencies from less stable packages, it does not exhibit the Unstable Dependency smell.
A68: org_adoptopenjdk_jitwatch_jarscan_visualiser.txt | C68: package | D68: org.adoptopenjdk.jitwatch.jarscan.visualiser | E68: 0 | F68: The package org.adoptopenjdk.jitwatch.jarscan.visualiser has outgoing dependencies on javafx and java.awt packages, which are relatively stable platform packages. It also depends on org.adoptopenjdk.jitwatch.util.UserInterfaceUtil, which appears to be a utility class within the same project. The package does not exhibit unstable dependencies as it does not depend on packages that are less stable than itself. The dependencies are primarily on standard JavaFX libraries and internal utilities, indicating a stable dependency pattern.
A69: org_adoptopenjdk_jitwatch_logger.txt | C69: package | D69: org.adoptopenjdk.jitwatch.logger | E69: 0 | F69: The package org.adoptopenjdk.jitwatch.logger is stable as it only contains simple interface and implementation classes (ILogListener, StdLogListener, NullLogListener) with no external dependencies. It follows the Stable Dependencies Principle as it has low instability (I=0) - it doesn't depend on any other packages, and other packages depend on it. The package serves as a stable abstraction layer for logging functionality.
A70: org_adoptopenjdk_jitwatch_model_assembly.txt | C70: package | D70: org.adoptopenjdk.jitwatch.model.assembly | E70: 0 | F70: The package org.adoptopenjdk.jitwatch.model.assembly shows good stability characteristics. It has a clear dependency on org.adoptopenjdk.jitwatch.core for constants and org.adoptopenjdk.jitwatch.util for utilities, which are likely more stable foundational packages. The assembly package contains specialized parsers for different architectures (x86, ARM) and related classes that form a cohesive unit for assembly processing. Dependencies are primarily on standard Java libraries (java.util, java.io, java.lang) and well-established external libraries (com.chrisnewland.freelogj for logging, org.xml.sax for XML parsing). The package structure demonstrates good encapsulation with interfaces (IAssemblyParser) and abstract classes (AbstractAssemblyParser) providing stable contracts. There are no indications of unstable dependencies where less stable packages depend on more stable ones - the dependencies flow toward foundational, more stable packages.
A71: org_adoptopenjdk_jitwatch_model_assembly_arm.txt | C71: package | D71: org.adoptopenjdk.jitwatch.model.assembly.arm | E71: 0 | F71: The package org.adoptopenjdk.jitwatch.model.assembly.arm contains classes that are all related to ARM assembly parsing and do not depend on less stable packages. The classes within this package are cohesive and focused on ARM-specific assembly handling. There are no dependencies on packages that are less stable than this package, thus adhering to the Stable Dependencies Principle.
A72: org_adoptopenjdk_jitwatch_model_assembly_x86.txt | C72: package | D72: org.adoptopenjdk.jitwatch.model.assembly.x86 | E72: 0 | F72: The package org.adoptopenjdk.jitwatch.model.assembly.x86 depends on org.adoptopenjdk.jitwatch.model.assembly, which is a more stable and abstract package containing core assembly model classes and interfaces. The x86 package implements specific parsers and types for x86 architecture, following the Stable Dependencies Principle by depending on more stable components. There are no dependencies on less stable packages, and the architecture flows from abstract (assembly) to concrete (x86), maintaining stability direction.
A73: org_adoptopenjdk_jitwatch_parser_zing.txt | C73: package | D73: org.adoptopenjdk.jitwatch.parser.zing | E73: 0 | F73: The package org.adoptopenjdk.jitwatch.parser.zing has incoming dependencies (used by other packages) but no outgoing dependencies to other packages within the provided code. It only depends on standard Java libraries (java.io, java.util, java.util.regex) and its own internal packages (org.adoptopenjdk.jitwatch.core, org.adoptopenjdk.jitwatch.model, org.adoptopenjdk.jitwatch.parser, org.adoptopenjdk.jitwatch.util). Since it doesn't depend on any less stable packages and is itself a leaf package in terms of inter-package dependencies, it does not exhibit the Unstable Dependency smell.
A74: org_adoptopenjdk_jitwatch_process_compiler.txt | C74: package | D74: org.adoptopenjdk.jitwatch.process.compiler | E74: 0 | F74: The package org.adoptopenjdk.jitwatch.process.compiler has outgoing dependencies to org.adoptopenjdk.jitwatch.logger and org.adoptopenjdk.jitwatch.process, but no incoming dependencies from other packages are shown. Since it depends on more stable packages (logger and process) and there are no dependencies from less stable packages, it does not exhibit the Unstable Dependency smell.
...
