Workbook

Sheet samples
A1: project | B1: smell | C1: package | D1: class | E1: fqn | F1: prompt_file | G1: context_size | H1: designite | I1: codex
A2: byte-buddy | B2: Hub-like Modularization | C2: net.bytebuddy.agent.builder | D2: AgentBuilder | E2: net.bytebuddy.agent.builder.AgentBuilder | G2: 16845 | H2: 1 | I2: =VLOOKUP(E2,codex!$A$1:$B$358,2,0) -> 1 | K2: TP | L2: =COUNTIFS(H2:H361,1,I2:I361,1) -> 10
A3: byte-buddy | B3: Hub-like Modularization | C3: net.bytebuddy.matcher | D3: ElementMatchers | E3: net.bytebuddy.matcher.ElementMatchers | G3: 10914 | H3: 1 | I3: =VLOOKUP(E3,codex!$A$1:$B$358,2,0) -> 1 | K3: TN | L3: =COUNTIFS(H2:H361,0,I2:I361,0) -> 337
A4: byte-buddy | B4: Hub-like Modularization | C4: net.bytebuddy.asm | D4: Advice | E4: net.bytebuddy.asm.Advice | G4: 16814 | H4: 1 | I4: =VLOOKUP(E4,codex!$A$1:$B$358,2,0) -> 1 | K4: FP | L4: =COUNTIFS(H2:H361,0,I2:I361,1) -> 13
A5: byte-buddy | B5: Hub-like Modularization | C5: net.bytebuddy.asm | D5: MemberSubstitution | E5: net.bytebuddy.asm.MemberSubstitution | G5: 12594 | H5: 1 | I5: =VLOOKUP(E5,codex!$A$1:$B$358,2,0) -> 1 | K5: FN | L5: =COUNTIFS(H2:H361,1,I2:I361,0) -> 0
A6: byte-buddy | B6: Hub-like Modularization | C6: net.bytebuddy | D6: ByteBuddy | E6: net.bytebuddy.ByteBuddy | G6: 13466 | H6: 1 | I6: =VLOOKUP(E6,codex!$A$1:$B$358,2,0) -> 1
A7: jsoup | B7: Hub-like Modularization | C7: org.jsoup.nodes | D7: Element | E7: org.jsoup.nodes.Element | G7: 4742 | H7: 1 | I7: =VLOOKUP(E7,codex!$A$1:$B$358,2,0) -> 1 | K7: Pr | L7: =IFERROR(L2/(L2+L4),0) -> 0.43478261
A8: gson | B8: Hub-like Modularization | C8: com.google.gson | D8: Gson | E8: com.google.gson.Gson | G8: 5856 | H8: 1 | I8: =VLOOKUP(E8,codex!$A$1:$B$358,2,0) -> 1 | K8: Rc | L8: =IFERROR(L2/(L2+L5),0) -> 1
A9: javaparser | B9: Hub-like Modularization | C9: com.github.javaparser.symbolsolver | D9: JavaSymbolSolver | E9: com.github.javaparser.symbolsolver.JavaSymbolSolver | G9: 6074 | H9: 1 | I9: =VLOOKUP(E9,codex!$A$1:$B$358,2,0) -> 1 | K9: F1 | L9: =IFERROR(2*L7*L8/(L7+L8),0) -> 0.60606061
A10: javaparser | B10: Hub-like Modularization | C10: com.github.javaparser.symbolsolver.javaparsermodel | D10: JavaParserFacade | E10: com.github.javaparser.symbolsolver.javaparsermodel.JavaParserFacade | G10: 20287 | H10: 1 | I10: =VLOOKUP(E10,codex!$A$1:$B$358,2,0) -> 1 | K10: MCC | L10: =IFERROR(((L2*L3)-(L4*L5))/SQRT((L2+L4)*(L2+L5)*(L3+L4)*(L3+L5)),0) -> 0.64701896
A11: javaparser | B11: Hub-like Modularization | C11: com.github.javaparser.ast | D11: CompilationUnit | E11: com.github.javaparser.ast.CompilationUnit | G11: 44654 | H11: 1 | I11: =VLOOKUP(E11,codex!$A$1:$B$358,2,0) -> 1
A12: zxing | B12: Hub-like Modularization | C12: com.google.zxing.oned.Code128Writer | D12: Latch | E12: =C12&"."&D12 -> com.google.zxing.oned.Code128Writer.Latch | F12: data/processed/prompts/hublike_modularization/zxing/com_google_zxing_oned_Code128Writer_Latch.txt | G12: 358 | H12: 0 | I12: =VLOOKUP(E12,codex!$A$1:$B$358,2,0) -> 0
A13: zxing | B13: Hub-like Modularization | C13: com.google.zxing.client.result | D13: WifiParsedResult | E13: =C13&"."&D13 -> com.google.zxing.client.result.WifiParsedResult | F13: data/processed/prompts/hublike_modularization/zxing/com_google_zxing_client_result_WifiParsedResult.txt | G13: 480 | H13: 0 | I13: =VLOOKUP(E13,codex!$A$1:$B$358,2,0) -> 0
A14: commons-lang | B14: Hub-like Modularization | C14: org.apache.commons.lang3.function | D14: FailableBiPredicate | E14: =C14&"."&D14 -> org.apache.commons.lang3.function.FailableBiPredicate | F14: data/processed/prompts/hublike_modularization/commons-lang/org_apache_commons_lang3_function_FailableBiPredicate.txt | G14: 511 | H14: 0 | I14: =VLOOKUP(E14,codex!$A$1:$B$358,2,0) -> 0
A15: byte-buddy | B15: Hub-like Modularization | C15: net.bytebuddy.utility.JavaConstant | D15: OfClassDesc | E15: =C15&"."&D15 -> net.bytebuddy.utility.JavaConstant.OfClassDesc | F15: data/processed/prompts/hublike_modularization/byte-buddy/net_bytebuddy_utility_JavaConstant_OfClassDesc.txt | G15: 810 | H15: 0 | I15: =VLOOKUP(E15,codex!$A$1:$B$358,2,0) -> 0
A16: byte-buddy | B16: Hub-like Modularization | C16: net.bytebuddy.build.Plugin | D16: ForJarOutputStream | E16: =C16&"."&D16 -> net.bytebuddy.build.Plugin.ForJarOutputStream | F16: data/processed/prompts/hublike_modularization/byte-buddy/net_bytebuddy_build_Plugin_ForJarOutputStream.txt | G16: 509 | H16: 0 | I16: =VLOOKUP(E16,codex!$A$1:$B$358,2,0) -> 0
A17: commons-io | B17: Hub-like Modularization | C17: org.apache.commons.io | D17: CopyUtils | E17: =C17&"."&D17 -> org.apache.commons.io.CopyUtils | F17: data/processed/prompts/hublike_modularization/commons-io/org_apache_commons_io_CopyUtils.txt | G17: 474 | H17: 0 | I17: =VLOOKUP(E17,codex!$A$1:$B$358,2,0) -> 0
A18: byte-buddy | B18: Hub-like Modularization | C18: net.bytebuddy.benchmark.jmh.generated.ClassByImplementationBenchmark.benchmarkJdkProxy | D18: jmhTest | E18: =C18&"."&D18 -> net.bytebuddy.benchmark.jmh.generated.ClassByImplementationBenchmark.benchmarkJdkProxy.jmhTest | F18: data/processed/prompts/hublike_modularization/byte-buddy/net_bytebuddy_benchmark_jmh_generated_ClassByImplementationBenchmark_benchmarkJdkProxy_jmhTest.txt | G18: 4425 | H18: 0 | I18: 0
A19: commons-lang | B19: Hub-like Modularization | C19: org.apache.commons.lang3.concurrent | D19: UncheckedExecutionException | E19: =C19&"."&D19 -> org.apache.commons.lang3.concurrent.UncheckedExecutionException | F19: data/processed/prompts/hublike_modularization/commons-lang/org_apache_commons_lang3_concurrent_UncheckedExecutionException.txt | G19: 248 | H19: 0 | I19: =VLOOKUP(E19,codex!$A$1:$B$358,2,0) -> 0
A20: byte-buddy | B20: Hub-like Modularization | C20: net.bytebuddy.description.type.TypeDescription | D20: OfAnnotatedElement | E20: =C20&"."&D20 -> net.bytebuddy.description.type.TypeDescription.OfAnnotatedElement | F20: data/processed/prompts/hublike_modularization/byte-buddy/net_bytebuddy_description_type_TypeDescription_OfAnnotatedElement.txt | G20: 249 | H20: 0 | I20: =VLOOKUP(E20,codex!$A$1:$B$358,2,0) -> 0
A21: byte-buddy | B21: Hub-like Modularization | C21: net.bytebuddy.dynamic.TypeResolutionStrategy | D21: Passive | E21: =C21&"."&D21 -> net.bytebuddy.dynamic.TypeResolutionStrategy.Passive | F21: data/processed/prompts/hublike_modularization/byte-buddy/net_bytebuddy_dynamic_TypeResolutionStrategy_Passive.txt | G21: 248 | H21: 0 | I21: =VLOOKUP(E21,codex!$A$1:$B$358,2,0) -> 0
A22: byte-buddy | B22: Hub-like Modularization | C22: net.bytebuddy.implementation.attribute.AnnotationAppender | D22: OnField | E22: =C22&"."&D22 -> net.bytebuddy.implementation.attribute.AnnotationAppender.OnField | F22: data/processed/prompts/hublike_modularization/byte-buddy/net_bytebuddy_implementation_attribute_AnnotationAppender_OnField.txt | G22: 263 | H22: 0 | I22: =VLOOKUP(E22,codex!$A$1:$B$358,2,0) -> 0
A23: byte-buddy | B23: Hub-like Modularization | C23: com.service.definition | D23: ServiceDefinition | E23: =C23&"."&D23 -> com.service.definition.ServiceDefinition | F23: data/processed/prompts/hublike_modularization/byte-buddy/com_service_definition_ServiceDefinition.txt | G23: 244 | H23: 0 | I23: =VLOOKUP(E23,codex!$A$1:$B$358,2,0) -> 0
A24: zxing | B24: Hub-like Modularization | C24: com.google.zxing.datamatrix.encoder | D24: DataMatrixSymbolInfo144 | E24: =C24&"."&D24 -> com.google.zxing.datamatrix.encoder.DataMatrixSymbolInfo144 | F24: data/processed/prompts/hublike_modularization/zxing/com_google_zxing_datamatrix_encoder_DataMatrixSymbolInfo144.txt | G24: 252 | H24: 0 | I24: =VLOOKUP(E24,codex!$A$1:$B$358,2,0) -> 0
A25: jsoup | B25: Hub-like Modularization | C25: org.jsoup.helper.HttpConnection | D25: Response | E25: =C25&"."&D25 -> org.jsoup.helper.HttpConnection.Response | F25: data/processed/prompts/hublike_modularization/jsoup/org_jsoup_helper_HttpConnection_Response.txt | G25: 892 | H25: 0 | I25: =VLOOKUP(E25,codex!$A$1:$B$358,2,0) -> 0
A26: javaparser | B26: Hub-like Modularization | C26: (default package).InnerClassContainer | D26: InnerClass | E26: =C26&"."&D26 -> (default package).InnerClassContainer.InnerClass | F26: data/processed/prompts/hublike_modularization/javaparser/(default package)_InnerClassContainer_InnerClass.txt | G26: 246 | H26: 0 | I26: =VLOOKUP(E26,codex!$A$1:$B$358,2,0) -> 0
A27: javaparser | B27: Hub-like Modularization | C27: com.packageName | D27: InnerStaticClassFieldContainer | E27: =C27&"."&D27 -> com.packageName.InnerStaticClassFieldContainer | F27: data/processed/prompts/hublike_modularization/javaparser/com_packageName_InnerStaticClassFieldContainer.txt | G27: 291 | H27: 0 | I27: =VLOOKUP(E27,codex!$A$1:$B$358,2,0) -> 0
A28: byte-buddy | B28: Hub-like Modularization | C28: net.bytebuddy.implementation.attribute.FieldAttributeAppender | D28: Compound | E28: =C28&"."&D28 -> net.bytebuddy.implementation.attribute.FieldAttributeAppender.Compound | F28: data/processed/prompts/hublike_modularization/byte-buddy/net_bytebuddy_implementation_attribute_FieldAttributeAppender_Compound.txt | G28: 355 | H28: 0 | I28: =VLOOKUP(E28,codex!$A$1:$B$358,2,0) -> 0
A29: zxing | B29: Hub-like Modularization | C29: com.google.zxing.common | D29: DetectorResult | E29: =C29&"."&D29 -> com.google.zxing.common.DetectorResult | F29: data/processed/prompts/hublike_modularization/zxing/com_google_zxing_common_DetectorResult.txt | G29: 854 | H29: 0 | I29: =VLOOKUP(E29,codex!$A$1:$B$358,2,0) -> 0
A30: commons-io | B30: Hub-like Modularization | C30: org.apache.commons.io.input | D30: UncheckedFilterReader | E30: =C30&"."&D30 -> org.apache.commons.io.input.UncheckedFilterReader | F30: data/processed/prompts/hublike_modularization/commons-io/org_apache_commons_io_input_UncheckedFilterReader.txt | G30: 498 | H30: 0 | I30: =VLOOKUP(E30,codex!$A$1:$B$358,2,0) -> 0
... A54: google-java-format | B54: Hub-like Modularization | C54: com.google.googlejavaformat.java.JavaInputAstVisitor | D54: Kind | E54: =C54&"."&D54 -> com.google.googlejavaformat.java.JavaInputAstVisitor.Kind | F54: data/processed/prompts/hublike_modularization/google-java-format/com_google_googlejavaformat_java_JavaInputAstVisitor_Kind.txt | G54: 570 | H54: 0 | I54: =VLOOKUP(E54,codex!$A$1:$B$358,2,0) -> 0
A55: byte-buddy | B55: Hub-like Modularization | C55: net.bytebuddy.benchmark.jmh.generated.ClassByExtensionBenchmark.benchmarkByteBuddyWithAccessor | D55: jmhTest | E55: =C55&"."&D55 -> net.bytebuddy.benchmark.jmh.generated.ClassByExtensionBenchmark.benchmarkByteBuddyWithAccessor.jmhTest | F55: data/processed/prompts/hublike_modularization/byte-buddy/net_bytebuddy_benchmark_jmh_generated_ClassByExtensionBenchmark_benchmarkByteBuddyWithAccessor_jmhTest.txt | G55: 4453 | H55: 0 | I55: 0
A56: byte-buddy | B56: Hub-like Modularization | C56: net.bytebuddy.asm.AsmVisitorWrapper | D56: Entry | E56: =C56&"."&D56 -> net.bytebuddy.asm.AsmVisitorWrapper.Entry | F56: data/processed/prompts/hublike_modularization/byte-buddy/net_bytebuddy_asm_AsmVisitorWrapper_Entry.txt | G56: 866 | H56: 0 | I56: =VLOOKUP(E56,codex!$A$1:$B$358,2,0) -> 0
A57: byte-buddy | B57: Hub-like Modularization | C57: net.bytebuddy.dynamic.scaffold.MethodGraph | D57: ForJVMMethod | E57: =C57&"."&D57 -> net.bytebuddy.dynamic.scaffold.MethodGraph.ForJVMMethod | F57: data/processed/prompts/hublike_modularization/byte-buddy/net_bytebuddy_dynamic_scaffold_MethodGraph_ForJVMMethod.txt | G57: 877 | H57: 0 | I57: =VLOOKUP(E57,codex!$A$1:$B$358,2,0) -> 0
A58: commons-lang | B58: Hub-like Modularization | C58: org.apache.commons.lang3.time.FastDateParser | D58: StrategyParser | E58: =C58&"."&D58 -> org.apache.commons.lang3.time.FastDateParser.StrategyParser | F58: data/processed/prompts/hublike_modularization/commons-lang/org_apache_commons_lang3_time_FastDateParser_StrategyParser.txt | G58: 370 | H58: 0 | I58: =VLOOKUP(E58,codex!$A$1:$B$358,2,0) -> 0
A59: byte-buddy | B59: Hub-like Modularization | C59: net.bytebuddy.asm.TypeReferenceAdjustment | D59: TypeReferenceMethodVisitor | E59: =C59&"."&D59 -> net.bytebuddy.asm.TypeReferenceAdjustment.TypeReferenceMethodVisitor | F59: data/processed/prompts/hublike_modularization/byte-buddy/net_bytebuddy_asm_TypeReferenceAdjustment_TypeReferenceMethodVisitor.txt | G59: 325 | H59: 0 | I59: =VLOOKUP(E59,codex!$A$1:$B$358,2,0) -> 0
A60: byte-buddy | B60: Hub-like Modularization | C60: net.bytebuddy.matcher | D60: CollectionErasureMatcher | E60: =C60&"."&D60 -> net.bytebuddy.matcher.CollectionErasureMatcher | F60: data/processed/prompts/hublike_modularization/byte-buddy/net_bytebuddy_matcher_CollectionErasureMatcher.txt | G60: 324 | H60: 0 | I60: =VLOOKUP(E60,codex!$A$1:$B$358,2,0) -> 0
A61: javaparser | B61: Hub-like Modularization | C61: com.github.javaparser.metamodel | D61: CompilationUnitMetaModel | E61: =C61&"."&D61 -> com.github.javaparser.metamodel.CompilationUnitMetaModel | F61: data/processed/prompts/hublike_modularization/javaparser/com_github_javaparser_metamodel_CompilationUnitMetaModel.txt | G61: 2401 | H61: 0 | I61: =VLOOKUP(E61,codex!$A$1:$B$358,2,0) -> 0
A62: jimfs | B62: Hub-like Modularization | C62: com.google.common.jimfs.FileFactory | D62: DirectorySupplier | E62: =C62&"."&D62 -> com.google.common.jimfs.FileFactory.DirectorySupplier | F62: data/processed/prompts/hublike_modularization/jimfs/com_google_common_jimfs_FileFactory_DirectorySupplier.txt | G62: 249 | H62: 0 | I62: =VLOOKUP(E62,codex!$A$1:$B$358,2,0) -> 0
A63: byte-buddy | B63: Hub-like Modularization | C63: net.bytebuddy.build.gradle.android.ByteBuddyAndroidPlugin | D63: VariantAction | E63: =C63&"."&D63 -> net.bytebuddy.build.gradle.android.ByteBuddyAndroidPlugin.VariantAction | F63: data/processed/prompts/hublike_modularization/byte-buddy/net_bytebuddy_build_gradle_android_ByteBuddyAndroidPlugin_VariantAction.txt | G63: 442 | H63: 0 | I63: =VLOOKUP(E63,codex!$A$1:$B$358,2,0) -> 0
...

Sheet codex
A1: net.bytebuddy.agent.builder.AgentBuilder | B1: 1
A2: net.bytebuddy.matcher.ElementMatchers | B2: 1
A3: net.bytebuddy.asm.Advice | B3: 1
A4: net.bytebuddy.asm.MemberSubstitution | B4: 1
A5: net.bytebuddy.ByteBuddy | B5: 1
A6: org.jsoup.nodes.Element | B6: 1
A7: com.google.gson.Gson | B7: 1
A8: com.github.javaparser.symbolsolver.JavaSymbolSolver | B8: 1
A9: com.github.javaparser.symbolsolver.javaparsermodel.JavaParserFacade | B9: 1
A10: com.github.javaparser.ast.CompilationUnit | B10: 1
A11: com.google.zxing.oned.Code128Writer.Latch | B11: 0
A12: com.google.zxing.client.result.WifiParsedResult | B12: 0
... A358: net.bytebuddy.description.modifier.MethodStrictness | B358: 0
